Workbook
Name AA: #REF!
Name AA: #REF!
Name aaa: '[3]100022'!$A$1:$AV$90
Name aaaaa: '[4]عوامل در مراکز '!$A$1:$AV$87
Name acttype: #REF!
Name acttype: #REF!
Name ali: #REF!
Name ali: #REF!
Name Ard: "آرد قراردادي"
Name BTitle: #REF!
Name BTitle: #REF!
Name Contracual_Driver: [5]Parametr!$C$3
Name cr_kim_sheet1: [6]SHEET1!#REF!
Name cr_kim_sheet1: [6]SHEET1!#REF!
Name Cا152: [1]BudgetDB!#REF!
Name Daramad_Serkati_GF: 125%
Name Daramad_Tejari_GF: 125%
Name fd: #REF!
Name fd: #REF!
Name fm: #REF!
Name fm: #REF!
Name fpath: #REF!
Name fpath: #REF!
Name ftype: #REF!
Name ftype: #REF!
Name fulltablist: #REF!
Name fulltablist: #REF!
Name fy: #REF!
Name fy: #REF!
Name fymd: #REF!
Name fymd: #REF!
Name Gandom: "گندم قراردادي"
Name Hazineh_Sherkati_GF: 130%
Name Hazineh_Tejari_GF: 130%
Name LastCell: #REF!
Name LastCell: #REF!
Name Light_Ratio: [5]Parametr!$C$7
Name Ostani: "گندم قراردادي"
Name Sarasari: "سراسري"
Name StartCell: #REF!
Name StartCell: #REF!
Name tabfile: #REF!
Name tabfile: #REF!
Name tabref: #REF!
Name tabref: #REF!
Name tabtitles: #REF!
Name tabtitles: #REF!
Name Tashim_From_Cost_to_Official: #REF!
Name Tashim_From_Cost_to_Official: #REF!
Name Tashim_From_Cost_to_Official_12_month_92_Forcast: #REF!
Name Tashim_From_Cost_to_Official_12_month_92_Forcast: #REF!
Name Tashim_From_Cost_to_Official_6_month_92: #REF!
Name Tashim_From_Cost_to_Official_6_month_92: #REF!
Name Tashim_From_Cost_to_Opratinal_12_month_92_Forcast: #REF!
Name Tashim_From_Cost_to_Opratinal_12_month_92_Forcast: #REF!
Name vco: #REF!
Name vco: #REF!
Name vconame: #REF!
Name vconame: #REF!
Name ا: #REF!

Sheet جدول فروش خدمات
A1: =[1]صادرات!A1 -> انبارهای عمومی و خدمات گمرکی ایران | U1: =AF2 -> شهید کاوه | W1: =U1 -> شهید کاوه | Z1: =W1 -> شهید کاوه | AK1: =AV2 -> مطهری | AM1: =AK1 -> مطهری | AP1: =AM1 -> مطهری | BA1: =BL2 -> سرخس | BC1: =BA1 -> سرخس | BF1: =BC1 -> سرخس | BQ1: =CB2 -> لطف آباد | BS1: =BQ1 -> لطف آباد | BV1: =BS1 -> لطف آباد | CG1: =CR2 -> نیشابور | CI1: =CG1 -> نیشابور | CL1: =CI1 -> نیشابور | CW1: =DH2 -> ماهیرود | CY1: =CW1 -> ماهیرود | DB1: =CY1 -> ماهیرود | DM1: =DX2 -> دوغارون | DO1: =DM1 -> دوغارون | DR1: =DO1 -> دوغارون | EC1: =EN2 -> بجنورد | EE1: =EC1 -> بجنورد | EH1: =EE1 -> بجنورد | ES1: =FD2 -> بیرجند | EU1: =ES1 -> بیرجند | EX1: =EU1 -> بیرجند | FI1: =FT2 -> باجگیران | FK1: =FI1 -> باجگیران | FN1: =FK1 -> باجگیران
A2: ="جدول فروش خدمات در دوره " & [1]روکش!$F$9 & " سال " & [1]روکش!$D$9&"- مجتمع خراسان" -> جدول فروش خدمات در دوره شش ماهه سال 1405- مجتمع خراسان | Q2: ="جدول فروش خدمات در دوره " & [1]روکش!$F$9 & " سال " & [1]روکش!$D$9&"- مجتمع خراسان/ شعبه "&AF$2 -> جدول فروش خدمات در دوره شش ماهه سال 1405- مجتمع خراسان/ شعبه شهید کاوه | AF2: =[1]واردات!$AA$42 -> شهید کاوه | AG2: ="جدول فروش خدمات در دوره " & [1]روکش!$F$9 & " سال " & [1]روکش!$D$9&"- مجتمع خراسان/ شعبه "&AV$2 -> جدول فروش خدمات در دوره شش ماهه سال 1405- مجتمع خراسان/ شعبه مطهری | AV2: =[1]واردات!$AA$43 -> مطهری | AW2: ="جدول فروش خدمات در دوره " & [1]روکش!$F$9 & " سال " & [1]روکش!$D$9&"- مجتمع خراسان/ شعبه "&BL$2 -> جدول فروش خدمات در دوره شش ماهه سال 1405- مجتمع خراسان/ شعبه سرخس | BL2: =[1]واردات!$AA$44 -> سرخس | BM2: ="جدول فروش خدمات در دوره " & [1]روکش!$F$9 & " سال " & [1]روکش!$D$9&"- مجتمع خراسان/ شعبه "&CB$2 -> جدول فروش خدمات در دوره شش ماهه سال 1405- مجتمع خراسان/ شعبه لطف آباد | CB2: =[1]واردات!$AA$45 -> لطف آباد | CC2: ="جدول فروش خدمات در دوره " & [1]روکش!$F$9 & " سال " & [1]روکش!$D$9&"- مجتمع خراسان/ شعبه "&CR$2 -> جدول فروش خدمات در دوره شش ماهه سال 1405- مجتمع خراسان/ شعبه نیشابور | CR2: =[1]واردات!$AA$46 -> نیشابور | CS2: ="جدول فروش خدمات در دوره " & [1]روکش!$F$9 & " سال " & [1]روکش!$D$9&"- مجتمع خراسان/ شعبه "&DH$2 -> جدول فروش خدمات در دوره شش ماهه سال 1405- مجتمع خراسان/ شعبه ماهیرود | DH2: =[1]واردات!$AA$47 -> ماهیرود | DI2: ="جدول فروش خدمات در دوره " & [1]روکش!$F$9 & " سال " & [1]روکش!$D$9&"- مجتمع خراسان/ شعبه "&DX$2 -> جدول فروش خدمات در دوره شش ماهه سال 1405- مجتمع خراسان/ شعبه دوغارون | DX2: =[1]واردات!$AA$48 -> دوغارون | DY2: ="جدول فروش خدمات در دوره " & [1]روکش!$F$9 & " سال " & [1]روکش!$D$9&"- مجتمع خراسان/ شعبه "&EN$2 -> جدول فروش خدمات در دوره شش ماهه سال 1405- مجتمع خراسان/ شعبه بجنورد | EN2: =[1]واردات!$AA$49 -> بجنورد | EO2: ="جدول فروش خدمات در دوره " & [1]روکش!$F$9 & " سال " & [1]روکش!$D$9&"- مجتمع خراسان/ شعبه "&FD$2 -> جدول فروش خدمات در دوره شش ماهه سال 1405- مجتمع خراسان/ شعبه بیرجند | FD2: =[1]واردات!$AA$50 -> بیرجند | FE2: ="جدول فروش خدمات در دوره " & [1]روکش!$F$9 & " سال " & [1]روکش!$D$9&"- مجتمع خراسان/ شعبه "&FT$2 -> جدول فروش خدمات در دوره شش ماهه سال 1405- مجتمع خراسان/ شعبه باجگیران | FT2: =[1]واردات!$AA$51 -> باجگیران
A3: بخش | B3: شرح خدمات | C3: واحد سنجش | D3: عملکرد سال قبل | F3: بودجه دوره رسیدگی سال جاری | H3: عملکرد دوره رسیدگی سال جاری | L3: تغییرات مقداری سال جاری و سال قبل | N3: تغییرات درصدی سال جاری و سال قبل | Q3: =$A$3 -> بخش | R3: =$B$3 -> شرح خدمات | S3: =$C$3 -> واحد سنجش | T3: =$D$3 -> عملکرد سال قبل | V3: =$F$3 -> بودجه دوره رسیدگی سال جاری | X3: =$H$3 -> عملکرد دوره رسیدگی سال جاری | AB3: =$L$3 -> تغییرات مقداری سال جاری و سال قبل | AD3: =$N$3 -> تغییرات درصدی سال جاری و سال قبل | AG3: =$A$3 -> بخش | AH3: =$B$3 -> شرح خدمات | AI3: =$C$3 -> واحد سنجش | AJ3: =$D$3 -> عملکرد سال قبل | AL3: =$F$3 -> بودجه دوره رسیدگی سال جاری | AN3: =$H$3 -> عملکرد دوره رسیدگی سال جاری | AR3: =$L$3 -> تغییرات مقداری سال جاری و سال قبل | AT3: =$N$3 -> تغییرات درصدی سال جاری و سال قبل | AW3: =$A$3 -> بخش | AX3: =$B$3 -> شرح خدمات | AY3: =$C$3 -> واحد سنجش | AZ3: =$D$3 -> عملکرد سال قبل | BB3: =$F$3 -> بودجه دوره رسیدگی سال جاری | BD3: =$H$3 -> عملکرد دوره رسیدگی سال جاری | BH3: =$L$3 -> تغییرات مقداری سال جاری و سال قبل | BJ3: =$N$3 -> تغییرات درصدی سال جاری و سال قبل | BM3: =$A$3 -> بخش | BN3: =$B$3 -> شرح خدمات | BO3: =$C$3 -> واحد سنجش | BP3: =$D$3 -> عملکرد سال قبل | BR3: =$F$3 -> بودجه دوره رسیدگی سال جاری | BT3: =$H$3 -> عملکرد دوره رسیدگی سال جاری | BX3: =$L$3 -> تغییرات مقداری سال جاری و سال قبل | BZ3: =$N$3 -> تغییرات درصدی سال جاری و سال قبل | CC3: =$A$3 -> بخش | CD3: =$B$3 -> شرح خدمات | CE3: =$C$3 -> واحد سنجش | CF3: =$D$3 -> عملکرد سال قبل | CH3: =$F$3 -> بودجه دوره رسیدگی سال جاری | CJ3: =$H$3 -> عملکرد دوره رسیدگی سال جاری | CN3: =$L$3 -> تغییرات مقداری سال جاری و سال قبل | CP3: =$N$3 -> تغییرات درصدی سال جاری و سال قبل | CS3: =$A$3 -> بخش | CT3: =$B$3 -> شرح خدمات | CU3: =$C$3 -> واحد سنجش | CV3: =$D$3 -> عملکرد سال قبل | CX3: =$F$3 -> بودجه دوره رسیدگی سال جاری | CZ3: =$H$3 -> عملکرد دوره رسیدگی سال جاری | DD3: =$L$3 -> تغییرات مقداری سال جاری و سال قبل | DF3: =$N$3 -> تغییرات درصدی سال جاری و سال قبل | DI3: =$A$3 -> بخش | DJ3: =$B$3 -> شرح خدمات | DK3: =$C$3 -> واحد سنجش | DL3: =$D$3 -> عملکرد سال قبل | DN3: =$F$3 -> بودجه دوره رسیدگی سال جاری | DP3: =$H$3 -> عملکرد دوره رسیدگی سال جاری | DT3: =$L$3 -> تغییرات مقداری سال جاری و سال قبل | DV3: =$N$3 -> تغییرات درصدی سال جاری و سال قبل | DY3: =$A$3 -> بخش | DZ3: =$B$3 -> شرح خدمات | EA3: =$C$3 -> واحد سنجش | EB3: =$D$3 -> عملکرد سال قبل | ED3: =$F$3 -> بودجه دوره رسیدگی سال جاری | EF3: =$H$3 -> عملکرد دوره رسیدگی سال جاری | EJ3: =$L$3 -> تغییرات مقداری سال جاری و سال قبل | EL3: =$N$3 -> تغییرات درصدی سال جاری و سال قبل | EO3: =$A$3 -> بخش | EP3: =$B$3 -> شرح خدمات | EQ3: =$C$3 -> واحد سنجش | ER3: =$D$3 -> عملکرد سال قبل | ET3: =$F$3 -> بودجه دوره رسیدگی سال جاری | EV3: =$H$3 -> عملکرد دوره رسیدگی سال جاری | EZ3: =$L$3 -> تغییرات مقداری سال جاری و سال قبل | FB3: =$N$3 -> تغییرات درصدی سال جاری و سال قبل | FE3: =$A$3 -> بخش | FF3: =$B$3 -> شرح خدمات | FG3: =$C$3 -> واحد سنجش | FH3: =$D$3 -> عملکرد سال قبل | FJ3: =$F$3 -> بودجه دوره رسیدگی سال جاری | FL3: =$H$3 -> عملکرد دوره رسیدگی سال جاری | FP3: =$L$3 -> تغییرات مقداری سال جاری و سال قبل | FR3: =$N$3 -> تغییرات درصدی سال جاری و سال قبل
D4: عملکرد عملیاتی | E4: ارزش ریالی ارائه خدمات (میلیون ریال) | F4: بودجه عملیاتی | G4: ارزش ریالی ارائه خدمات (میلیون ریال) | H4: عملکرد عملیاتی | I4: درصد تحقق بودجه (عملیاتی) | J4: ارزش ریالی ارائه خدمات (میلیون ریال) | K4: درصد تحقق بودجه (ریالی) | L4: عملکرد عملیاتی | M4: ارزش ریالی ارائه خدمات (میلیون ریال) | N4: عملکرد عملیاتی | O4: ارزش ریالی ارائه خدمات (میلیون ریال) | T4: =$D$4 -> عملکرد عملیاتی | U4: =$E$4 -> ارزش ریالی ارائه خدمات (میلیون ریال) | V4: =$F$4 -> بودجه عملیاتی | W4: =$G$4 -> ارزش ریالی ارائه خدمات (میلیون ریال) | X4: =$H$4 -> عملکرد عملیاتی | Y4: =$I$4 -> درصد تحقق بودجه (عملیاتی) | Z4: =$J$4 -> ارزش ریالی ارائه خدمات (میلیون ریال) | AA4: =$K$4 -> درصد تحقق بودجه (ریالی) | AB4: =$L$4 -> عملکرد عملیاتی | AC4: =$M$4 -> ارزش ریالی ارائه خدمات (میلیون ریال) | AD4: =$N$4 -> عملکرد عملیاتی | AE4: =$O$4 -> ارزش ریالی ارائه خدمات (میلیون ریال) | AJ4: =$D$4 -> عملکرد عملیاتی | AK4: =$E$4 -> ارزش ریالی ارائه خدمات (میلیون ریال) | AL4: =$F$4 -> بودجه عملیاتی | AM4: =$G$4 -> ارزش ریالی ارائه خدمات (میلیون ریال) | AN4: =$H$4 -> عملکرد عملیاتی | AO4: =$I$4 -> درصد تحقق بودجه (عملیاتی) | AP4: =$J$4 -> ارزش ریالی ارائه خدمات (میلیون ریال) | AQ4: =$K$4 -> درصد تحقق بودجه (ریالی) | AR4: =$L$4 -> عملکرد عملیاتی | AS4: =$M$4 -> ارزش ریالی ارائه خدمات (میلیون ریال) | AT4: =$N$4 -> عملکرد عملیاتی | AU4: =$O$4 -> ارزش ریالی ارائه خدمات (میلیون ریال) | AZ4: =$D$4 -> عملکرد عملیاتی | BA4: =$E$4 -> ارزش ریالی ارائه خدمات (میلیون ریال) | BB4: =$F$4 -> بودجه عملیاتی | BC4: =$G$4 -> ارزش ریالی ارائه خدمات (میلیون ریال) | BD4: =$H$4 -> عملکرد عملیاتی | BE4: =$I$4 -> درصد تحقق بودجه (عملیاتی) | BF4: =$J$4 -> ارزش ریالی ارائه خدمات (میلیون ریال) | BG4: =$K$4 -> درصد تحقق بودجه (ریالی) | BH4: =$L$4 -> عملکرد عملیاتی | BI4: =$M$4 -> ارزش ریالی ارائه خدمات (میلیون ریال) | BJ4: =$N$4 -> عملکرد عملیاتی | BK4: =$O$4 -> ارزش ریالی ارائه خدمات (میلیون ریال) | BP4: =$D$4 -> عملکرد عملیاتی | BQ4: =$E$4 -> ارزش ریالی ارائه خدمات (میلیون ریال) | BR4: =$F$4 -> بودجه عملیاتی | BS4: =$G$4 -> ارزش ریالی ارائه خدمات (میلیون ریال) | BT4: =$H$4 -> عملکرد عملیاتی | BU4: =$I$4 -> درصد تحقق بودجه (عملیاتی) | BV4: =$J$4 -> ارزش ریالی ارائه خدمات (میلیون ریال) | BW4: =$K$4 -> درصد تحقق بودجه (ریالی) | BX4: =$L$4 -> عملکرد عملیاتی | BY4: =$M$4 -> ارزش ریالی ارائه خدمات (میلیون ریال) | BZ4: =$N$4 -> عملکرد عملیاتی | CA4: =$O$4 -> ارزش ریالی ارائه خدمات (میلیون ریال) | CF4: =$D$4 -> عملکرد عملیاتی | CG4: =$E$4 -> ارزش ریالی ارائه خدمات (میلیون ریال) | CH4: =$F$4 -> بودجه عملیاتی | CI4: =$G$4 -> ارزش ریالی ارائه خدمات (میلیون ریال) | CJ4: =$H$4 -> عملکرد عملیاتی | CK4: =$I$4 -> درصد تحقق بودجه (عملیاتی) | CL4: =$J$4 -> ارزش ریالی ارائه خدمات (میلیون ریال) | CM4: =$K$4 -> درصد تحقق بودجه (ریالی) | CN4: =$L$4 -> عملکرد عملیاتی | CO4: =$M$4 -> ارزش ریالی ارائه خدمات (میلیون ریال) | CP4: =$N$4 -> عملکرد عملیاتی | CQ4: =$O$4 -> ارزش ریالی ارائه خدمات (میلیون ریال) | CV4: =$D$4 -> عملکرد عملیاتی | CW4: =$E$4 -> ارزش ریالی ارائه خدمات (میلیون ریال) | CX4: =$F$4 -> بودجه عملیاتی | CY4: =$G$4 -> ارزش ریالی ارائه خدمات (میلیون ریال) | CZ4: =$H$4 -> عملکرد عملیاتی | DA4: =$I$4 -> درصد تحقق بودجه (عملیاتی) | DB4: =$J$4 -> ارزش ریالی ارائه خدمات (میلیون ریال) | DC4: =$K$4 -> درصد تحقق بودجه (ریالی) | DD4: =$L$4 -> عملکرد عملیاتی | DE4: =$M$4 -> ارزش ریالی ارائه خدمات (میلیون ریال) | DF4: =$N$4 -> عملکرد عملیاتی | DG4: =$O$4 -> ارزش ریالی ارائه خدمات (میلیون ریال) | DL4: =$D$4 -> عملکرد عملیاتی | DM4: =$E$4 -> ارزش ریالی ارائه خدمات (میلیون ریال) | DN4: =$F$4 -> بودجه عملیاتی | DO4: =$G$4 -> ارزش ریالی ارائه خدمات (میلیون ریال) | DP4: =$H$4 -> عملکرد عملیاتی | DQ4: =$I$4 -> درصد تحقق بودجه (عملیاتی) | DR4: =$J$4 -> ارزش ریالی ارائه خدمات (میلیون ریال) | DS4: =$K$4 -> درصد تحقق بودجه (ریالی) | DT4: =$L$4 -> عملکرد عملیاتی | DU4: =$M$4 -> ارزش ریالی ارائه خدمات (میلیون ریال) | DV4: =$N$4 -> عملکرد عملیاتی | DW4: =$O$4 -> ارزش ریالی ارائه خدمات (میلیون ریال) | EB4: =$D$4 -> عملکرد عملیاتی | EC4: =$E$4 -> ارزش ریالی ارائه خدمات (میلیون ریال) | ED4: =$F$4 -> بودجه عملیاتی | EE4: =$G$4 -> ارزش ریالی ارائه خدمات (میلیون ریال) | EF4: =$H$4 -> عملکرد عملیاتی | EG4: =$I$4 -> درصد تحقق بودجه (عملیاتی) | EH4: =$J$4 -> ارزش ریالی ارائه خدمات (میلیون ریال) | EI4: =$K$4 -> درصد تحقق بودجه (ریالی) | EJ4: =$L$4 -> عملکرد عملیاتی | EK4: =$M$4 -> ارزش ریالی ارائه خدمات (میلیون ریال) | EL4: =$N$4 -> عملکرد عملیاتی | EM4: =$O$4 -> ارزش ریالی ارائه خدمات (میلیون ریال) | ER4: =$D$4 -> عملکرد عملیاتی | ES4: =$E$4 -> ارزش ریالی ارائه خدمات (میلیون ریال) | ET4: =$F$4 -> بودجه عملیاتی | EU4: =$G$4 -> ارزش ریالی ارائه خدمات (میلیون ریال) | EV4: =$H$4 -> عملکرد عملیاتی | EW4: =$I$4 -> درصد تحقق بودجه (عملیاتی) | EX4: =$J$4 -> ارزش ریالی ارائه خدمات (میلیون ریال) | EY4: =$K$4 -> درصد تحقق بودجه (ریالی) | EZ4: =$L$4 -> عملکرد عملیاتی | FA4: =$M$4 -> ارزش ریالی ارائه خدمات (میلیون ریال) | FB4: =$N$4 -> عملکرد عملیاتی | FC4: =$O$4 -> ارزش ریالی ارائه خدمات (میلیون ریال) | FH4: =$D$4 -> عملکرد عملیاتی | FI4: =$E$4 -> ارزش ریالی ارائه خدمات (میلیون ریال) | FJ4: =$F$4 -> بودجه عملیاتی | FK4: =$G$4 -> ارزش ریالی ارائه خدمات (میلیون ریال) | FL4: =$H$4 -> عملکرد عملیاتی | FM4: =$I$4 -> درصد تحقق بودجه (عملیاتی) | FN4: =$J$4 -> ارزش ریالی ارائه خدمات (میلیون ریال) | FO4: =$K$4 -> درصد تحقق بودجه (ریالی) | FP4: =$L$4 -> عملکرد عملیاتی | FQ4: =$M$4 -> ارزش ریالی ارائه خدمات (میلیون ریال) | FR4: =$N$4 -> عملکرد عملیاتی | FS4: =$O$4 -> ارزش ریالی ارائه خدمات (میلیون ریال)
A5: واردات | B5: انبارداری | C5: تن | D5: =SUM(T5,AJ5,AZ5,BP5,CF5,CV5,DL5,EB5,ER5,FH5) -> 113724 | E5: =SUM(U5,AK5,BA5,BQ5,CG5,CW5,DM5,EC5,ES5,FI5) -> 331775 | F5: =SUM(V5,AL5,BB5,BR5,CH5,CX5,DN5,ED5,ET5,FJ5) -> 152262.28 | G5: =SUM(W5,AM5,BC5,BS5,CI5,CY5,DO5,EE5,EU5,FK5) -> 615444 | H5: =SUM(X5,AN5,BD5,BT5,CJ5,CZ5,DP5,EF5,EV5,FL5) -> 145726 | I5: =IFERROR(H5*100/F5,"") -> 95.707226 | J5: =SUM(Z5,AP5,BF5,BV5,CL5,DB5,DR5,EH5,EX5,FN5) -> 528593 | K5: =IFERROR(J5*100/G5,"") -> 85.888074 | L5: =IFERROR(H5-D5,"") -> 32002 | M5: =IFERROR(J5-E5,"") -> 196818 | N5: =IFERROR((H5-D5)*100/D5,"") -> 28.140058 | O5: =IFERROR((J5-E5)*100/E5,"") -> 59.322734 | P5: 1 | Q5: =$A$5 -> واردات | R5: =$B5 -> انبارداری | S5: =$C5 -> تن | T5: =SUMIFS([1]واردات!$D$42:$D$51,[1]واردات!$AA$42:$AA$51,AF2) -> 11125 | U5: =65097-10422 -> 54675 | V5: =SUMIFS([1]واردات!$H$42:$H$51,[1]واردات!$AA$42:$AA$51,AF2) -> 38497.266 | W5: 210259 | X5: =SUMIFS([1]واردات!$L$42:$L$51,[1]واردات!$AA$42:$AA$51,AF2) -> 2891 | Y5: =IFERROR(X5*100/V5,"") -> 7.5096243 | Z5: 33548 | AA5: =IFERROR(Z5*100/W5,"") -> 15.95556 | AB5: =X5-T5 -> -8234 | AC5: =Z5-U5 -> -21127 | AD5: =IFERROR((X5-T5)*100/T5,"") -> -74.013483 | AE5: =IFERROR((Z5-U5)*100/U5,"") -> -38.641061 | AG5: =$A$5 -> واردات | AH5: =$B5 -> انبارداری | AI5: =$C5 -> تن | AJ5: =SUMIFS([1]واردات!$D$42:$D$51,[1]واردات!$AA$42:$AA$51,AV2) -> 9899 | AK5: =37012-5940 -> 31072 | AL5: =SUMIFS([1]واردات!$H$42:$H$51,[1]واردات!$AA$42:$AA$51,AV2) -> 16320.389 | AM5: 58398 | AN5: =SUMIFS([1]واردات!$L$42:$L$51,[1]واردات!$AA$42:$AA$51,AV2) -> 6309 | AO5: =IFERROR(AN5*100/AL5,"") -> 38.657166 | AP5: 39017 | AQ5: =IFERROR(AP5*100/AM5,"") -> 66.81222 | AR5: =AN5-AJ5 -> -3590 | AS5: =AP5-AK5 -> 7945 | AT5: =IFERROR((AN5-AJ5)*100/AJ5,"") -> -36.26629 | AU5: =IFERROR((AP5-AK5)*100/AK5,"") -> 25.569645 | AW5: =$A$5 -> واردات | AX5: =$B5 -> انبارداری | AY5: =$C5 -> تن | AZ5: =SUMIFS([1]واردات!$D$42:$D$51,[1]واردات!$AA$42:$AA$51,BL2) -> 7882 | BA5: =28179-2256 -> 25923 | BB5: =SUMIFS([1]واردات!$H$42:$H$51,[1]واردات!$AA$42:$AA$51,BL2) -> 9271.6114 | BC5: 45500 | BD5: =SUMIFS([1]واردات!$L$42:$L$51,[1]واردات!$AA$42:$AA$51,BL2) -> 6778 | BE5: =IFERROR(BD5*100/BB5,"") -> 73.104876 | BF5: 26869 | BG5: =IFERROR(BF5*100/BC5,"") -> 59.052747 | BH5: =BD5-AZ5 -> -1104 | BI5: =BF5-BA5 -> 946 | BJ5: =IFERROR((BD5-AZ5)*100/AZ5,"") -> -14.006597 | BK5: =IFERROR((BF5-BA5)*100/BA5,"") -> 3.649269 | BM5: =$A$5 -> واردات | BN5: =$B5 -> انبارداری | BO5: =$C5 -> تن | BP5: =SUMIFS([1]واردات!$D$42:$D$51,[1]واردات!$AA$42:$AA$51,CB2) -> 40280 | BQ5: =39079-6826 -> 32253 | BR5: =SUMIFS([1]واردات!$H$42:$H$51,[1]واردات!$AA$42:$AA$51,CB2) -> 37960.715 | BS5: 57420 | BT5: =SUMIFS([1]واردات!$L$42:$L$51,[1]واردات!$AA$42:$AA$51,CB2) -> 62858 | BU5: =IFERROR(BT5*100/BR5,"") -> 165.58698 | BV5: 115432 | BW5: =IFERROR(BV5*100/BS5,"") -> 201.031 | BX5: =BT5-BP5 -> 22578 | BY5: =BV5-BQ5 -> 83179 | BZ5: =IFERROR((BT5-BP5)*100/BP5,"") -> 56.052632 | CA5: =IFERROR((BV5-BQ5)*100/BQ5,"") -> 257.89539 | CC5: =$A$5 -> واردات | CD5: =$B5 -> انبارداری | CE5: =$C5 -> تن | CF5: =SUMIFS([1]واردات!$D$42:$D$51,[1]واردات!$AA$42:$AA$51,CR2) -> 10826 | CG5: =100918-10695 -> 90223 | CH5: =SUMIFS([1]واردات!$H$42:$H$51,[1]واردات!$AA$42:$AA$51,CR2) -> 5774.4347 | CI5: 78185 | CJ5: =SUMIFS([1]واردات!$L$42:$L$51,[1]واردات!$AA$42:$AA$51,CR2) -> 6401 | CK5: =IFERROR(CJ5*100/CH5,"") -> 110.85068 | CL5: 147424 | CM5: =IFERROR(CL5*100/CI5,"") -> 188.55791 | CN5: =CJ5-CF5 -> -4425 | CO5: =CL5-CG5 -> 57201 | CP5: =IFERROR((CJ5-CF5)*100/CF5,"") -> -40.873822 | CQ5: =IFERROR((CL5-CG5)*100/CG5,"") -> 63.399577 | CS5: =$A$5 -> واردات | CT5: =$B5 -> انبارداری | CU5: =$C5 -> تن | CV5: =SUMIFS([1]واردات!$D$42:$D$51,[1]واردات!$AA$42:$AA$51,DH2) -> 20 | CW5: =398-89 -> 309 | CX5: =SUMIFS([1]واردات!$H$42:$H$51,[1]واردات!$AA$42:$AA$51,DH2) -> 33.470578 | CY5: 465 | CZ5: =SUMIFS([1]واردات!$L$42:$L$51,[1]واردات!$AA$42:$AA$51,DH2) -> 1952 | DA5: =IFERROR(CZ5*100/CX5,"") -> 5831.9878 | DB5: 19113 | DC5: =IFERROR(DB5*100/CY5,"") -> 4110.3226 | DD5: =CZ5-CV5 -> 1932 | DE5: =DB5-CW5 -> 18804 | DF5: =IFERROR((CZ5-CV5)*100/CV5,"") -> 9660 | DG5: =IFERROR((DB5-CW5)*100/CW5,"") -> 6085.4369 | DI5: =$A$5 -> واردات | DJ5: =$B5 -> انبارداری | DK5: =$C5 -> تن | DL5: =SUMIFS([1]واردات!$D$42:$D$51,[1]واردات!$AA$42:$AA$51,DX2) -> 32693 | DM5: =104022-14133 -> 89889 | DN5: =SUMIFS([1]واردات!$H$42:$H$51,[1]واردات!$AA$42:$AA$51,DX2) -> 37898.877 | DO5: 128943 | DP5: =SUMIFS([1]واردات!$L$42:$L$51,[1]واردات!$AA$42:$AA$51,DX2) -> 51694 | DQ5: =IFERROR(DP5*100/DN5,"") -> 136.39982 | DR5: 131601 | DS5: =IFERROR(DR5*100/DO5,"") -> 102.06138 | DT5: =DP5-DL5 -> 19001 | DU5: =DR5-DM5 -> 41712 | DV5: =IFERROR((DP5-DL5)*100/DL5,"") -> 58.119475 | DW5: =IFERROR((DR5-DM5)*100/DM5,"") -> 46.403898 | DY5: =$A$5 -> واردات | DZ5: =$B5 -> انبارداری | EA5: =$C5 -> تن | EB5: =SUMIFS([1]واردات!$D$42:$D$51,[1]واردات!$AA$42:$AA$51,EN2) -> 373 | EC5: 5089 | ED5: =SUMIFS([1]واردات!$H$42:$H$51,[1]واردات!$AA$42:$AA$51,EN2) -> 3069.1126 | EE5: 26217 | EF5: =SUMIFS([1]واردات!$L$42:$L$51,[1]واردات!$AA$42:$AA$51,EN2) -> 96 | EG5: =IFERROR(EF5*100/ED5,"") -> 3.12794 | EH5: 195 | EI5: =IFERROR(EH5*100/EE5,"") -> 0.7437922 | EJ5: =EF5-EB5 -> -277 | EK5: =EH5-EC5 -> -4894 | EL5: =IFERROR((EF5-EB5)*100/EB5,"") -> -74.262735 | EM5: =IFERROR((EH5-EC5)*100/EC5,"") -> -96.168206 | EO5: =$A$5 -> واردات | EP5: =$B5 -> انبارداری | EQ5: =$C5 -> تن | ER5: =SUMIFS([1]واردات!$D$42:$D$51,[1]واردات!$AA$42:$AA$51,FD2) -> 626 | ES5: 2342 | ET5: =SUMIFS([1]واردات!$H$42:$H$51,[1]واردات!$AA$42:$AA$51,FD2) -> 3436.4 | EU5: 10057 | EV5: =SUMIFS([1]واردات!$L$42:$L$51,[1]واردات!$AA$42:$AA$51,FD2) -> 6747 | EW5: =IFERROR(EV5*100/ET5,"") -> 196.33919 | EX5: 15394 | EY5: =IFERROR(EX5*100/EU5,"") -> 153.06752 | EZ5: =EV5-ER5 -> 6121 | FA5: =EX5-ES5 -> 13052 | FB5: =IFERROR((EV5-ER5)*100/ER5,"") -> 977.79553 | FC5: =IFERROR((EX5-ES5)*100/ES5,"") -> 557.30145 | FE5: =$A$5 -> واردات | FF5: =$B5 -> انبارداری | FG5: =$C5 -> تن | FH5: =SUMIFS([1]واردات!$D$42:$D$51,[1]واردات!$AA$42:$AA$51,FT2) -> 0 | FJ5: =SUMIFS([1]واردات!$H$42:$H$51,[1]واردات!$AA$42:$AA$51,FT2) -> 0 | FL5: =SUMIFS([1]واردات!$L$42:$L$51,[1]واردات!$AA$42:$AA$51,FT2) -> 0 | FM5: =IFERROR(FL5*100/FJ5,"") | FO5: =IFERROR(FN5*100/FK5,"") | FP5: =FL5-FH5 -> 0 | FQ5: =FN5-FI5 -> 0 | FR5: =IFERROR((FL5-FH5)*100/FH5,"") | FS5: =IFERROR((FN5-FI5)*100/FI5,"")
B6: میانگین مدت ماندگاری کالا | C6: روز | D6: =IFERROR(D7/D5,"") -> 29.692211 | F6: =IFERROR(F7/F5,"") -> 52.017423 | H6: =IFERROR(H7/H5,"") -> 25.251259 | I6: =IFERROR(H6*100/F6,"") -> 48.543849 | L6: =IFERROR(H6-D6,"") -> -4.4409518 | N6: =IFERROR((H6-D6)*100/D6,"") -> -14.956622 | O6: =IFERROR((J6-E6)*100/E6,"-") -> - | P6: 1 | R6: =$B6 -> میانگین مدت ماندگاری کالا | S6: =$C6 -> روز | T6: 60 | V6: 60 | X6: 78 | Y6: =IFERROR(X6*100/V6,"") -> 130 | AB6: =X6-T6 -> 18 | AD6: =IFERROR((X6-T6)*100/T6,"") -> 30 | AE6: =IFERROR((Z6-U6)*100/U6,"-") -> - | AH6: =$B6 -> میانگین مدت ماندگاری کالا | AI6: =$C6 -> روز | AJ6: 50 | AL6: 50 | AN6: 52 | AO6: =IFERROR(AN6*100/AL6,"") -> 104 | AR6: =AN6-AJ6 -> 2 | AT6: =IFERROR((AN6-AJ6)*100/AJ6,"") -> 4 | AU6: =IFERROR((AP6-AK6)*100/AK6,"-") -> - | AX6: =$B6 -> میانگین مدت ماندگاری کالا | AY6: =$C6 -> روز | AZ6: 25 | BB6: 25 | BD6: 42 | BE6: =IFERROR(BD6*100/BB6,"") -> 168 | BH6: =BD6-AZ6 -> 17 | BJ6: =IFERROR((BD6-AZ6)*100/AZ6,"") -> 68 | BK6: =IFERROR((BF6-BA6)*100/BA6,"-") -> - | BN6: =$B6 -> میانگین مدت ماندگاری کالا | BO6: =$C6 -> روز | BP6: 8 | BR6: 9 | BT6: 14 | BU6: =IFERROR(BT6*100/BR6,"") -> 155.55556 | BX6: =BT6-BP6 -> 6 | BZ6: =IFERROR((BT6-BP6)*100/BP6,"") -> 75 | CA6: =IFERROR((BV6-BQ6)*100/BQ6,"-") -> - | CD6: =$B6 -> میانگین مدت ماندگاری کالا | CE6: =$C6 -> روز | CF6: 62 | CH6: 63 | CJ6: 96 | CK6: =IFERROR(CJ6*100/CH6,"") -> 152.38095 | CN6: =CJ6-CF6 -> 34 | CP6: =IFERROR((CJ6-CF6)*100/CF6,"") -> 54.83871 | CQ6: =IFERROR((CL6-CG6)*100/CG6,"-") -> - | CT6: =$B6 -> میانگین مدت ماندگاری کالا | CU6: =$C6 -> روز | CV6: 55 | CX6: 51 | CZ6: 59 | DA6: =IFERROR(CZ6*100/CX6,"") -> 115.68627 | DD6: =CZ6-CV6 -> 4 | DF6: =IFERROR((CZ6-CV6)*100/CV6,"") -> 7.2727273 | DG6: =IFERROR((DB6-CW6)*100/CW6,"-") -> - | DJ6: =$B6 -> میانگین مدت ماندگاری کالا | DK6: =$C6 -> روز | DL6: 29 | DN6: 90 | DP6: 20 | DQ6: =IFERROR(DP6*100/DN6,"") -> 22.222222 | DT6: =DP6-DL6 -> -9 | DV6: =IFERROR((DP6-DL6)*100/DL6,"") -> -31.034483 | DW6: =IFERROR((DR6-DM6)*100/DM6,"-") -> - | DZ6: =$B6 -> میانگین مدت ماندگاری کالا | EA6: =$C6 -> روز | EB6: 116 | ED6: 90 | EF6: 24 | EG6: =IFERROR(EF6*100/ED6,"") -> 26.666667 | EJ6: =EF6-EB6 -> -92 | EL6: =IFERROR((EF6-EB6)*100/EB6,"") -> -79.310345 | EM6: =IFERROR((EH6-EC6)*100/EC6,"-") -> - | EP6: =$B6 -> میانگین مدت ماندگاری کالا | EQ6: =$C6 -> روز | ER6: 50 | ET6: 49 | EV6: 29 | EW6: =IFERROR(EV6*100/ET6,"") -> 59.183673 | EZ6: =EV6-ER6 -> -21 | FB6: =IFERROR((EV6-ER6)*100/ER6,"") -> -42 | FC6: =IFERROR((EX6-ES6)*100/ES6,"-") -> - | FF6: =$B6 -> میانگین مدت ماندگاری کالا | FG6: =$C6 -> روز | FM6: =IFERROR(FL6*100/FJ6,"") | FP6: =FL6-FH6 -> 0 | FR6: =IFERROR((FL6-FH6)*100/FH6,"") | FS6: =IFERROR((FN6-FI6)*100/FI6,"-") -> -
B7: انبارداری | C7: تن روز | D7: =SUM(T7,AJ7,AZ7,BP7,CF7,CV7,DL7,EB7,ER7,FH7) -> 3376717 | F7: =SUM(V7,AL7,BB7,BR7,CH7,CX7,DN7,ED7,ET7,FJ7) -> 7920291.2 | H7: =SUM(X7,AN7,BD7,BT7,CJ7,CZ7,DP7,EF7,EV7,FL7) -> 3679765 | I7: =IFERROR(H7*100/F7,"") -> 46.459971 | L7: =IFERROR(H7-D7,"") -> 303048 | N7: =IFERROR((H7-D7)*100/D7,"") -> 8.9746342 | O7: =IFERROR((J7-E7)*100/E7,"-") -> - | P7: 1 | R7: =$B7 -> انبارداری | S7: =$C7 -> تن روز | T7: =IFERROR(T5*T6,"") -> 667500 | V7: =IFERROR(V5*V6,"") -> 2309835.9 | X7: =IFERROR(X5*X6,"") -> 225498 | Y7: =IFERROR(X7*100/V7,"") -> 9.7625115 | AB7: =X7-T7 -> -442002 | AD7: =IFERROR((X7-T7)*100/T7,"") -> -66.217528 | AE7: =IFERROR((Z7-U7)*100/U7,"-") -> - | AH7: =$B7 -> انبارداری | AI7: =$C7 -> تن روز | AJ7: =IFERROR(AJ5*AJ6,"") -> 494950 | AL7: =IFERROR(AL5*AL6,"") -> 816019.46 | AN7: =IFERROR(AN5*AN6,"") -> 328068 | AO7: =IFERROR(AN7*100/AL7,"") -> 40.203453 | AR7: =AN7-AJ7 -> -166882 | AT7: =IFERROR((AN7-AJ7)*100/AJ7,"") -> -33.716941 | AU7: =IFERROR((AP7-AK7)*100/AK7,"-") -> - | AX7: =$B7 -> انبارداری | AY7: =$C7 -> تن روز | AZ7: =IFERROR(AZ5*AZ6,"") -> 197050 | BB7: =IFERROR(BB5*BB6,"") -> 231790.28 | BD7: =IFERROR(BD5*BD6,"") -> 284676 | BE7: =IFERROR(BD7*100/BB7,"") -> 122.81619 | BH7: =BD7-AZ7 -> 87626 | BJ7: =IFERROR((BD7-AZ7)*100/AZ7,"") -> 44.468917 | BK7: =IFERROR((BF7-BA7)*100/BA7,"-") -> - | BN7: =$B7 -> انبارداری | BO7: =$C7 -> تن روز | BP7: =IFERROR(BP5*BP6,"") -> 322240 | BR7: =IFERROR(BR5*BR6,"") -> 341646.43 | BT7: =IFERROR(BT5*BT6,"") -> 880012 | BU7: =IFERROR(BT7*100/BR7,"") -> 257.57974 | BX7: =BT7-BP7 -> 557772 | BZ7: =IFERROR((BT7-BP7)*100/BP7,"") -> 173.09211 | CA7: =IFERROR((BV7-BQ7)*100/BQ7,"-") -> - | CD7: =$B7 -> انبارداری | CE7: =$C7 -> تن روز | CF7: =IFERROR(CF5*CF6,"") -> 671212 | CH7: =IFERROR(CH5*CH6,"") -> 363789.39 | CJ7: =IFERROR(CJ5*CJ6,"") -> 614496 | CK7: =IFERROR(CJ7*100/CH7,"") -> 168.91532 | CN7: =CJ7-CF7 -> -56716 | CP7: =IFERROR((CJ7-CF7)*100/CF7,"") -> -8.4497893 | CQ7: =IFERROR((CL7-CG7)*100/CG7,"-") -> - | CT7: =$B7 -> انبارداری | CU7: =$C7 -> تن روز | CV7: =IFERROR(CV5*CV6,"") -> 1100 | CX7: =IFERROR(CX5*CX6,"") -> 1706.9995 | CZ7: =IFERROR(CZ5*CZ6,"") -> 115168 | DA7: =IFERROR(CZ7*100/CX7,"") -> 6746.8094 | DD7: =CZ7-CV7 -> 114068 | DF7: =IFERROR((CZ7-CV7)*100/CV7,"") -> 10369.818 | DG7: =IFERROR((DB7-CW7)*100/CW7,"-") -> - | DJ7: =$B7 -> انبارداری | DK7: =$C7 -> تن روز | DL7: =IFERROR(DL5*DL6,"") -> 948097 | DN7: =IFERROR(DN5*DN6,"") -> 3410898.9 | DP7: =IFERROR(DP5*DP6,"") -> 1033880 | DQ7: =IFERROR(DP7*100/DN7,"") -> 30.311071 | DT7: =DP7-DL7 -> 85783 | DV7: =IFERROR((DP7-DL7)*100/DL7,"") -> 9.0479139 | DW7: =IFERROR((DR7-DM7)*100/DM7,"-") -> - | DZ7: =$B7 -> انبارداری | EA7: =$C7 -> تن روز | EB7: =IFERROR(EB5*EB6,"") -> 43268 | ED7: =IFERROR(ED5*ED6,"") -> 276220.13 | EF7: =IFERROR(EF5*EF6,"") -> 2304 | EG7: =IFERROR(EF7*100/ED7,"") -> 0.83411733 | EJ7: =EF7-EB7 -> -40964 | EL7: =IFERROR((EF7-EB7)*100/EB7,"") -> -94.675049 | EM7: =IFERROR((EH7-EC7)*100/EC7,"-") -> - | EP7: =$B7 -> انبارداری | EQ7: =$C7 -> تن روز | ER7: =IFERROR(ER5*ER6,"") -> 31300 | ET7: =IFERROR(ET5*ET6,"") -> 168383.6 | EV7: =IFERROR(EV5*EV6,"") -> 195663 | EW7: =IFERROR(EV7*100/ET7,"") -> 116.20075 | EZ7: =EV7-ER7 -> 164363 | FB7: =IFERROR((EV7-ER7)*100/ER7,"") -> 525.12141 | FC7: =IFERROR((EX7-ES7)*100/ES7,"-") -> - | FF7: =$B7 -> انبارداری | FG7: =$C7 -> تن روز | FH7: =IFERROR(FH5*FH6,"") -> 0 | FJ7: =IFERROR(FJ5*FJ6,"") -> 0 | FL7: =IFERROR(FL5*FL6,"") -> 0 | FM7: =IFERROR(FL7*100/FJ7,"") | FP7: =FL7-FH7 -> 0 | FR7: =IFERROR((FL7-FH7)*100/FH7,"") | FS7: =IFERROR((FN7-FI7)*100/FI7,"-") -> -
B8: باربری | C8: تن | D8: =SUM(T8,AJ8,AZ8,BP8,CF8,CV8,DL8,EB8,ER8,FH8) -> 227448 | E8: =SUM(U8,AK8,BA8,BQ8,CG8,CW8,DM8,EC8,ES8,FI8) -> 465998 | F8: =SUM(V8,AL8,BB8,BR8,CH8,CX8,DN8,ED8,ET8,FJ8) -> 304524.55 | G8: =SUM(W8,AM8,BC8,BS8,CI8,CY8,DO8,EE8,EU8,FK8) -> 690927 | H8: =SUM(X8,AN8,BD8,BT8,CJ8,CZ8,DP8,EF8,EV8,FL8) -> 291452 | I8: =IFERROR(H8*100/F8,"") -> 95.707226 | J8: =SUM(Z8,AP8,BF8,BV8,CL8,DB8,DR8,EH8,EX8,FN8) -> 808273 | K8: =IFERROR(J8*100/G8,"") -> 116.98385 | L8: =IFERROR(H8-D8,"") -> 64004 | M8: =IFERROR(J8-E8,"") -> 342275 | N8: =IFERROR((H8-D8)*100/D8,"") -> 28.140058 | O8: =IFERROR((J8-E8)*100/E8,"") -> 73.449886 | P8: 1 | R8: =$B8 -> باربری | S8: =$C8 -> تن | T8: =IFERROR(2*T5,"") -> 22250 | U8: 40772 | V8: =IFERROR(2*V5,"") -> 76994.531 | W8: 138874 | X8: =IFERROR(2*X5,"") -> 5782 | Y8: =IFERROR(X8*100/V8,"") -> 7.5096243 | Z8: 14688 | AA8: =IFERROR(Z8*100/W8,"") -> 10.576494 | AB8: =X8-T8 -> -16468 | AC8: =Z8-U8 -> -26084 | AD8: =IFERROR((X8-T8)*100/T8,"") -> -74.013483 | AE8: =IFERROR((Z8-U8)*100/U8,"") -> -63.975277 | AH8: =$B8 -> باربری | AI8: =$C8 -> تن | AJ8: =IFERROR(2*AJ5,"") -> 19798 | AK8: 9720 | AL8: =IFERROR(2*AL5,"") -> 32640.779 | AM8: 16351 | AN8: =IFERROR(2*AN5,"") -> 12618 | AO8: =IFERROR(AN8*100/AL8,"") -> 38.657166 | AP8: 25516 | AQ8: =IFERROR(AP8*100/AM8,"") -> 156.05162 | AR8: =AN8-AJ8 -> -7180 | AS8: =AP8-AK8 -> 15796 | AT8: =IFERROR((AN8-AJ8)*100/AJ8,"") -> -36.26629 | AU8: =IFERROR((AP8-AK8)*100/AK8,"") -> 162.51029 | AX8: =$B8 -> باربری | AY8: =$C8 -> تن | AZ8: =IFERROR(2*AZ5,"") -> 15764 | BA8: 32643 | BB8: =IFERROR(2*BB5,"") -> 18543.223 | BC8: 57439 | BD8: =IFERROR(2*BD5,"") -> 13556 | BE8: =IFERROR(BD8*100/BB8,"") -> 73.104876 | BF8: 43718 | BG8: =IFERROR(BF8*100/BC8,"") -> 76.112049 | BH8: =BD8-AZ8 -> -2208 | BI8: =BF8-BA8 -> 11075 | BJ8: =IFERROR((BD8-AZ8)*100/AZ8,"") -> -14.006597 | BK8: =IFERROR((BF8-BA8)*100/BA8,"") -> 33.927641 | BN8: =$B8 -> باربری | BO8: =$C8 -> تن | BP8: =IFERROR(2*BP5,"") -> 80560 | BQ8: 311287 | BR8: =IFERROR(2*BR5,"") -> 75921.43 | BS8: 385608 | BT8: =IFERROR(2*BT5,"") -> 125716 | BU8: =IFERROR(BT8*100/BR8,"") -> 165.58698 | BV8: 515378 | BW8: =IFERROR(BV8*100/BS8,"") -> 133.65335 | BX8: =BT8-BP8 -> 45156 | BY8: =BV8-BQ8 -> 204091 | BZ8: =IFERROR((BT8-BP8)*100/BP8,"") -> 56.052632 | CA8: =IFERROR((BV8-BQ8)*100/BQ8,"") -> 65.563612 | CD8: =$B8 -> باربری | CE8: =$C8 -> تن | CF8: =IFERROR(2*CF5,"") -> 21652 | CG8: 24587 | CH8: =IFERROR(2*CH5,"") -> 11548.869 | CI8: 18793 | CJ8: =IFERROR(2*CJ5,"") -> 12802 | CK8: =IFERROR(CJ8*100/CH8,"") -> 110.85068 | CL8: 21518 | CM8: =IFERROR(CL8*100/CI8,"") -> 114.50008 | CN8: =CJ8-CF8 -> -8850 | CO8: =CL8-CG8 -> -3069 | CP8: =IFERROR((CJ8-CF8)*100/CF8,"") -> -40.873822 | CQ8: =IFERROR((CL8-CG8)*100/CG8,"") -> -12.482206 | CT8: =$B8 -> باربری | CU8: =$C8 -> تن | CV8: =IFERROR(2*CV5,"") -> 40 | CW8: 53 | CX8: =IFERROR(2*CX5,"") -> 66.941156 | CY8: 60 | CZ8: =IFERROR(2*CZ5,"") -> 3904 | DA8: =IFERROR(CZ8*100/CX8,"") -> 5831.9878 | DB8: 2362 | DC8: =IFERROR(DB8*100/CY8,"") -> 3936.6667 | DD8: =CZ8-CV8 -> 3864 | DE8: =DB8-CW8 -> 2309 | DF8: =IFERROR((CZ8-CV8)*100/CV8,"") -> 9660 | DG8: =IFERROR((DB8-CW8)*100/CW8,"") -> 4356.6038 | DJ8: =$B8 -> باربری | DK8: =$C8 -> تن | DL8: =IFERROR(2*DL5,"") -> 65386 | DM8: 46190 | DN8: =IFERROR(2*DN5,"") -> 75797.754 | DO8: 69943 | DP8: =IFERROR(2*DP5,"") -> 103388 | DQ8: =IFERROR(DP8*100/DN8,"") -> 136.39982 | DR8: 163436 | DS8: =IFERROR(DR8*100/DO8,"") -> 233.67027 | DT8: =DP8-DL8 -> 38002 | DU8: =DR8-DM8 -> 117246 | DV8: =IFERROR((DP8-DL8)*100/DL8,"") -> 58.119475 | DW8: =IFERROR((DR8-DM8)*100/DM8,"") -> 253.83416 | DZ8: =$B8 -> باربری | EA8: =$C8 -> تن | EB8: =IFERROR(2*EB5,"") -> 746 | EC8: 215 | ED8: =IFERROR(2*ED5,"") -> 6138.2252 | EE8: 1417 | EF8: =IFERROR(2*EF5,"") -> 192 | EG8: =IFERROR(EF8*100/ED8,"") -> 3.12794 | EH8: 259 | EI8: =IFERROR(EH8*100/EE8,"") -> 18.278052 | EJ8: =EF8-EB8 -> -554 | EK8: =EH8-EC8 -> 44 | EL8: =IFERROR((EF8-EB8)*100/EB8,"") -> -74.262735 | EM8: =IFERROR((EH8-EC8)*100/EC8,"") -> 20.465116 | EP8: =$B8 -> باربری | EQ8: =$C8 -> تن | ER8: =IFERROR(2*ER5,"") -> 1252 | ES8: 531 | ET8: =IFERROR(2*ET5,"") -> 6872.8 | EU8: 2442 | EV8: =IFERROR(2*EV5,"") -> 13494 | EW8: =IFERROR(EV8*100/ET8,"") -> 196.33919 | EX8: 21398 | EY8: =IFERROR(EX8*100/EU8,"") -> 876.24898 | EZ8: =EV8-ER8 -> 12242 | FA8: =EX8-ES8 -> 20867 | FB8: =IFERROR((EV8-ER8)*100/ER8,"") -> 977.79553 | FC8: =IFERROR((EX8-ES8)*100/ES8,"") -> 3929.7552 | FF8: =$B8 -> باربری | FG8: =$C8 -> تن | FH8: =IFERROR(2*FH5,"") -> 0 | FJ8: =IFERROR(2*FJ5,"") -> 0 | FL8: =IFERROR(2*FL5,"") -> 0 | FM8: =IFERROR(FL8*100/FJ8,"") | FO8: =IFERROR(FN8*100/FK8,"") | FP8: =FL8-FH8 -> 0 | FQ8: =FN8-FI8 -> 0 | FR8: =IFERROR((FL8-FH8)*100/FH8,"") | FS8: =IFERROR((FN8-FI8)*100/FI8,"")
B9: حمل یکسره | C9: تن | D9: =SUM(T9,AJ9,AZ9,BP9,CF9,CV9,DL9,EB9,ER9,FH9) -> 3902 | E9: =SUM(U9,AK9,BA9,BQ9,CG9,CW9,DM9,EC9,ES9,FI9) -> 151 | F9: =SUM(V9,AL9,BB9,BR9,CH9,CX9,DN9,ED9,ET9,FJ9) -> 9774.4185 | G9: =SUM(W9,AM9,BC9,BS9,CI9,CY9,DO9,EE9,EU9,FK9) -> 67 | H9: =SUM(X9,AN9,BD9,BT9,CJ9,CZ9,DP9,EF9,EV9,FL9) -> 657 | I9: =IFERROR(H9*100/F9,"") -> 6.7216275 | J9: =SUM(Z9,AP9,BF9,BV9,CL9,DB9,DR9,EH9,EX9,FN9) -> 479 | K9: =IFERROR(J9*100/G9,"") -> 714.92537 | L9: =IFERROR(H9-D9,"") -> -3245 | M9: =IFERROR(J9-E9,"") -> 328 | N9: =IFERROR((H9-D9)*100/D9,"") -> -83.162481 | O9: =IFERROR((J9-E9)*100/E9,"") -> 217.21854 | P9: 1 | R9: =$B9 -> حمل یکسره | S9: =$C9 -> تن | T9: =SUMIFS([1]واردات!$C$42:$C$51,[1]واردات!$AA$42:$AA$51,AF2) -> 3822 | U9: 26 | V9: =SUMIFS([1]واردات!$G$42:$G$51,[1]واردات!$AA$42:$AA$51,AF2) -> 9716.2736 | W9: 67 | X9: =SUMIFS([1]واردات!$K$42:$K$51,[1]واردات!$AA$42:$AA$51,AF2) -> 40 | Y9: =IFERROR(X9*100/V9,"") -> 0.41168046 | Z9: 26 | AA9: =IFERROR(Z9*100/W9,"") -> 38.80597 | AB9: =X9-T9 -> -3782 | AC9: =Z9-U9 -> 0 | AD9: =IFERROR((X9-T9)*100/T9,"") -> -98.953428 | AE9: =IFERROR((Z9-U9)*100/U9,"") -> 0 | AH9: =$B9 -> حمل یکسره | AI9: =$C9 -> تن | AJ9: =SUMIFS([1]واردات!$C$42:$C$51,[1]واردات!$AA$42:$AA$51,AV2) -> 0 | AL9: =SUMIFS([1]واردات!$G$42:$G$51,[1]واردات!$AA$42:$AA$51,AV2) -> 0 | AN9: =SUMIFS([1]واردات!$K$42:$K$51,[1]واردات!$AA$42:$AA$51,AV2) -> 493 | AO9: =IFERROR(AN9*100/AL9,"") | AP9: 292 | AQ9: =IFERROR(AP9*100/AM9,"") | AR9: =AN9-AJ9 -> 493 | AS9: =AP9-AK9 -> 292 | AT9: =IFERROR((AN9-AJ9)*100/AJ9,"") | AU9: =IFERROR((AP9-AK9)*100/AK9,"") | AX9: =$B9 -> حمل یکسره | AY9: =$C9 -> تن | AZ9: =SUMIFS([1]واردات!$C$42:$C$51,[1]واردات!$AA$42:$AA$51,BL2) -> 0 | BB9: =SUMIFS([1]واردات!$G$42:$G$51,[1]واردات!$AA$42:$AA$51,BL2) -> 0 | BD9: =SUMIFS([1]واردات!$K$42:$K$51,[1]واردات!$AA$42:$AA$51,BL2) -> 0 | BE9: =IFERROR(BD9*100/BB9,"") | BG9: =IFERROR(BF9*100/BC9,"") | BH9: =BD9-AZ9 -> 0 | BI9: =BF9-BA9 -> 0 | BJ9: =IFERROR((BD9-AZ9)*100/AZ9,"") | BK9: =IFERROR((BF9-BA9)*100/BA9,"") | BN9: =$B9 -> حمل یکسره | BO9: =$C9 -> تن | BP9: =SUMIFS([1]واردات!$C$42:$C$51,[1]واردات!$AA$42:$AA$51,CB2) -> 0 | BR9: =SUMIFS([1]واردات!$G$42:$G$51,[1]واردات!$AA$42:$AA$51,CB2) -> 0 | BT9: =SUMIFS([1]واردات!$K$42:$K$51,[1]واردات!$AA$42:$AA$51,CB2) -> 0 | BU9: =IFERROR(BT9*100/BR9,"") | BW9: =IFERROR(BV9*100/BS9,"") | BX9: =BT9-BP9 -> 0 | BY9: =BV9-BQ9 -> 0 | BZ9: =IFERROR((BT9-BP9)*100/BP9,"") | CA9: =IFERROR((BV9-BQ9)*100/BQ9,"") | CD9: =$B9 -> حمل یکسره | CE9: =$C9 -> تن | CF9: =SUMIFS([1]واردات!$C$42:$C$51,[1]واردات!$AA$42:$AA$51,CR2) -> 1 | CH9: =SUMIFS([1]واردات!$G$42:$G$51,[1]واردات!$AA$42:$AA$51,CR2) -> 0 | CJ9: =SUMIFS([1]واردات!$K$42:$K$51,[1]واردات!$AA$42:$AA$51,CR2) -> 0 | CK9: =IFERROR(CJ9*100/CH9,"") | CM9: =IFERROR(CL9*100/CI9,"") | CN9: =CJ9-CF9 -> -1 | CO9: =CL9-CG9 -> 0 | CP9: =IFERROR((CJ9-CF9)*100/CF9,"") -> -100 | CQ9: =IFERROR((CL9-CG9)*100/CG9,"") | CT9: =$B9 -> حمل یکسره | CU9: =$C9 -> تن | CV9: =SUMIFS([1]واردات!$C$42:$C$51,[1]واردات!$AA$42:$AA$51,DH2) -> 0 | CX9: =SUMIFS([1]واردات!$G$42:$G$51,[1]واردات!$AA$42:$AA$51,DH2) -> 0 | CZ9: =SUMIFS([1]واردات!$K$42:$K$51,[1]واردات!$AA$42:$AA$51,DH2) -> 0 | DA9: =IFERROR(CZ9*100/CX9,"") | DC9: =IFERROR(DB9*100/CY9,"") | DD9: =CZ9-CV9 -> 0 | DE9: =DB9-CW9 -> 0 | DF9: =IFERROR((CZ9-CV9)*100/CV9,"") | DG9: =IFERROR((DB9-CW9)*100/CW9,"") | DJ9: =$B9 -> حمل یکسره | DK9: =$C9 -> تن | DL9: =SUMIFS([1]واردات!$C$42:$C$51,[1]واردات!$AA$42:$AA$51,DX2) -> 50 | DM9: 125 | DN9: =SUMIFS([1]واردات!$G$42:$G$51,[1]واردات!$AA$42:$AA$51,DX2) -> 0 | DP9: =SUMIFS([1]واردات!$K$42:$K$51,[1]واردات!$AA$42:$AA$51,DX2) -> 86 | DQ9: =IFERROR(DP9*100/DN9,"") | DR9: 128 | DS9: =IFERROR(DR9*100/DO9,"") | DT9: =DP9-DL9 -> 36 | DU9: =DR9-DM9 -> 3 | DV9: =IFERROR((DP9-DL9)*100/DL9,"") -> 72 | DW9: =IFERROR((DR9-DM9)*100/DM9,"") -> 2.4 | DZ9: =$B9 -> حمل یکسره | EA9: =$C9 -> تن | EB9: =SUMIFS([1]واردات!$C$42:$C$51,[1]واردات!$AA$42:$AA$51,EN2) -> 29 | ED9: =SUMIFS([1]واردات!$G$42:$G$51,[1]واردات!$AA$42:$AA$51,EN2) -> 58.144819 | EF9: =SUMIFS([1]واردات!$K$42:$K$51,[1]واردات!$AA$42:$AA$51,EN2) -> 38 | EG9: =IFERROR(EF9*100/ED9,"") -> 65.35406 | EH9: 33 | EI9: =IFERROR(EH9*100/EE9,"") | EJ9: =EF9-EB9 -> 9 | EK9: =EH9-EC9 -> 33 | EL9: =IFERROR((EF9-EB9)*100/EB9,"") -> 31.034483 | EM9: =IFERROR((EH9-EC9)*100/EC9,"") | EP9: =$B9 -> حمل یکسره | EQ9: =$C9 -> تن | ER9: =SUMIFS([1]واردات!$C$42:$C$51,[1]واردات!$AA$42:$AA$51,FD2) -> 0 | ET9: =SUMIFS([1]واردات!$G$42:$G$51,[1]واردات!$AA$42:$AA$51,FD2) -> 0 | EV9: =SUMIFS([1]واردات!$K$42:$K$51,[1]واردات!$AA$42:$AA$51,FD2) -> 0 | EW9: =IFERROR(EV9*100/ET9,"") | EY9: =IFERROR(EX9*100/EU9,"") | EZ9: =EV9-ER9 -> 0 | FA9: =EX9-ES9 -> 0 | FB9: =IFERROR((EV9-ER9)*100/ER9,"") | FC9: =IFERROR((EX9-ES9)*100/ES9,"") | FF9: =$B9 -> حمل یکسره | FG9: =$C9 -> تن | FH9: =SUMIFS([1]واردات!$C$42:$C$51,[1]واردات!$AA$42:$AA$51,FT2) -> 0 | FJ9: =SUMIFS([1]واردات!$G$42:$G$51,[1]واردات!$AA$42:$AA$51,FT2) -> 0 | FL9: =SUMIFS([1]واردات!$K$42:$K$51,[1]واردات!$AA$42:$AA$51,FT2) -> 0 | FM9: =IFERROR(FL9*100/FJ9,"") | FO9: =IFERROR(FN9*100/FK9,"") | FP9: =FL9-FH9 -> 0 | FQ9: =FN9-FI9 -> 0 | FR9: =IFERROR((FL9-FH9)*100/FH9,"") | FS9: =IFERROR((FN9-FI9)*100/FI9,"")
B10: ترانشیپ | C10: تن | D10: =SUM(T10,AJ10,AZ10,BP10,CF10,CV10,DL10,EB10,ER10,FH10) -> 498346 | E10: =SUM(U10,AK10,BA10,BQ10,CG10,CW10,DM10,EC10,ES10,FI10) -> 95843 | F10: =SUM(V10,AL10,BB10,BR10,CH10,CX10,DN10,ED10,ET10,FJ10) -> 509431.77 | G10: =SUM(W10,AM10,BC10,BS10,CI10,CY10,DO10,EE10,EU10,FK10) -> 146941 | H10: =SUM(X10,AN10,BD10,BT10,CJ10,CZ10,DP10,EF10,EV10,FL10) -> 641162 | I10: =IFERROR(H10*100/F10,"") -> 125.85827 | J10: =SUM(Z10,AP10,BF10,BV10,CL10,DB10,DR10,EH10,EX10,FN10) -> 164419 | K10: =IFERROR(J10*100/G10,"") -> 111.89457 | L10: =IFERROR(H10-D10,"") -> 142816 | M10: =IFERROR(J10-E10,"") -> 68576 | N10: =IFERROR((H10-D10)*100/D10,"") -> 28.658001 | O10: =IFERROR((J10-E10)*100/E10,"") -> 71.550348 | P10: 1 | R10: =$B10 -> ترانشیپ | S10: =$C10 -> تن | T10: =SUMIFS([1]واردات!$E$42:$E$51,[1]واردات!$AA$42:$AA$51,AF2) -> 0 | V10: =SUMIFS([1]واردات!$I$42:$I$51,[1]واردات!$AA$42:$AA$51,AF2) -> 0 | X10: =SUMIFS([1]واردات!$M$42:$M$51,[1]واردات!$AA$42:$AA$51,AF2) -> 0 | Y10: =IFERROR(X10*100/V10,"") | AA10: =IFERROR(Z10*100/W10,"") | AB10: =X10-T10 -> 0 | AC10: =Z10-U10 -> 0 | AD10: =IFERROR((X10-T10)*100/T10,"") | AE10: =IFERROR((Z10-U10)*100/U10,"") | AH10: =$B10 -> ترانشیپ | AI10: =$C10 -> تن | AJ10: =SUMIFS([1]واردات!$E$42:$E$51,[1]واردات!$AA$42:$AA$51,AV2) -> 0 | AL10: =SUMIFS([1]واردات!$I$42:$I$51,[1]واردات!$AA$42:$AA$51,AV2) -> 0 | AN10: =SUMIFS([1]واردات!$M$42:$M$51,[1]واردات!$AA$42:$AA$51,AV2) -> 2207 | AO10: =IFERROR(AN10*100/AL10,"") | AP10: 1557 | AQ10: =IFERROR(AP10*100/AM10,"") | AR10: =AN10-AJ10 -> 2207 | AS10: =AP10-AK10 -> 1557 | AT10: =IFERROR((AN10-AJ10)*100/AJ10,"") | AU10: =IFERROR((AP10-AK10)*100/AK10,"") | AX10: =$B10 -> ترانشیپ | AY10: =$C10 -> تن | AZ10: =SUMIFS([1]واردات!$E$42:$E$51,[1]واردات!$AA$42:$AA$51,BL2) -> 29637 | BA10: 8883 | BB10: =SUMIFS([1]واردات!$I$42:$I$51,[1]واردات!$AA$42:$AA$51,BL2) -> 35361.703 | BC10: 14281 | BD10: =SUMIFS([1]واردات!$M$42:$M$51,[1]واردات!$AA$42:$AA$51,BL2) -> 24810 | BE10: =IFERROR(BD10*100/BB10,"") -> 70.160647 | BF10: 7949 | BG10: =IFERROR(BF10*100/BC10,"") -> 55.661368 | BH10: =BD10-AZ10 -> -4827 | BI10: =BF10-BA10 -> -934 | BJ10: =IFERROR((BD10-AZ10)*100/AZ10,"") -> -16.287074 | BK10: =IFERROR((BF10-BA10)*100/BA10,"") -> -10.514466 | BN10: =$B10 -> ترانشیپ | BO10: =$C10 -> تن | BP10: =SUMIFS([1]واردات!$E$42:$E$51,[1]واردات!$AA$42:$AA$51,CB2) -> 418170 | BQ10: 75305 | BR10: =SUMIFS([1]واردات!$I$42:$I$51,[1]واردات!$AA$42:$AA$51,CB2) -> 401431.4 | BS10: 107863 | BT10: =SUMIFS([1]واردات!$M$42:$M$51,[1]واردات!$AA$42:$AA$51,CB2) -> 489014 | BU10: =IFERROR(BT10*100/BR10,"") -> 121.81758 | BV10: 130124 | BW10: =IFERROR(BV10*100/BS10,"") -> 120.63822 | BX10: =BT10-BP10 -> 70844 | BY10: =BV10-BQ10 -> 54819 | BZ10: =IFERROR((BT10-BP10)*100/BP10,"") -> 16.941435 | CA10: =IFERROR((BV10-BQ10)*100/BQ10,"") -> 72.795963 | CD10: =$B10 -> ترانشیپ | CE10: =$C10 -> تن | CF10: =SUMIFS([1]واردات!$E$42:$E$51,[1]واردات!$AA$42:$AA$51,CR2) -> 0 | CH10: =SUMIFS([1]واردات!$I$42:$I$51,[1]واردات!$AA$42:$AA$51,CR2) -> 0 | CJ10: =SUMIFS([1]واردات!$M$42:$M$51,[1]واردات!$AA$42:$AA$51,CR2) -> 0 | CK10: =IFERROR(CJ10*100/CH10,"") | CM10: =IFERROR(CL10*100/CI10,"") | CN10: =CJ10-CF10 -> 0 | CO10: =CL10-CG10 -> 0 | CP10: =IFERROR((CJ10-CF10)*100/CF10,"") | CQ10: =IFERROR((CL10-CG10)*100/CG10,"") | CT10: =$B10 -> ترانشیپ | CU10: =$C10 -> تن | CV10: =SUMIFS([1]واردات!$E$42:$E$51,[1]واردات!$AA$42:$AA$51,DH2) -> 0 | CX10: =SUMIFS([1]واردات!$I$42:$I$51,[1]واردات!$AA$42:$AA$51,DH2) -> 0 | CZ10: =SUMIFS([1]واردات!$M$42:$M$51,[1]واردات!$AA$42:$AA$51,DH2) -> 0 | DA10: =IFERROR(CZ10*100/CX10,"") | DC10: =IFERROR(DB10*100/CY10,"") | DD10: =CZ10-CV10 -> 0 | DE10: =DB10-CW10 -> 0 | DF10: =IFERROR((CZ10-CV10)*100/CV10,"") | DG10: =IFERROR((DB10-CW10)*100/CW10,"") | DJ10: =$B10 -> ترانشیپ | DK10: =$C10 -> تن | DL10: =SUMIFS([1]واردات!$E$42:$E$51,[1]واردات!$AA$42:$AA$51,DX2) -> 50539 | DM10: 11655 | DN10: =SUMIFS([1]واردات!$I$42:$I$51,[1]واردات!$AA$42:$AA$51,DX2) -> 72638.662 | DO10: 24797 | DP10: =SUMIFS([1]واردات!$M$42:$M$51,[1]واردات!$AA$42:$AA$51,DX2) -> 125131 | DQ10: =IFERROR(DP10*100/DN10,"") -> 172.26501 | DR10: 24789 | DS10: =IFERROR(DR10*100/DO10,"") -> 99.967738 | DT10: =DP10-DL10 -> 74592 | DU10: =DR10-DM10 -> 13134 | DV10: =IFERROR((DP10-DL10)*100/DL10,"") -> 147.59295 | DW10: =IFERROR((DR10-DM10)*100/DM10,"") -> 112.68983 | DZ10: =$B10 -> ترانشیپ | EA10: =$C10 -> تن | EB10: =SUMIFS([1]واردات!$E$42:$E$51,[1]واردات!$AA$42:$AA$51,EN2) -> 0 | ED10: =SUMIFS([1]واردات!$I$42:$I$51,[1]واردات!$AA$42:$AA$51,EN2) -> 0 | EF10: =SUMIFS([1]واردات!$M$42:$M$51,[1]واردات!$AA$42:$AA$51,EN2) -> 0 | EG10: =IFERROR(EF10*100/ED10,"") | EI10: =IFERROR(EH10*100/EE10,"") | EJ10: =EF10-EB10 -> 0 | EK10: =EH10-EC10 -> 0 | EL10: =IFERROR((EF10-EB10)*100/EB10,"") | EM10: =IFERROR((EH10-EC10)*100/EC10,"") | EP10: =$B10 -> ترانشیپ | EQ10: =$C10 -> تن | ER10: =SUMIFS([1]واردات!$E$42:$E$51,[1]واردات!$AA$42:$AA$51,FD2) -> 0 | ET10: =SUMIFS([1]واردات!$I$42:$I$51,[1]واردات!$AA$42:$AA$51,FD2) -> 0 | EV10: =SUMIFS([1]واردات!$M$42:$M$51,[1]واردات!$AA$42:$AA$51,FD2) -> 0 | EW10: =IFERROR(EV10*100/ET10,"") | EY10: =IFERROR(EX10*100/EU10,"") | EZ10: =EV10-ER10 -> 0 | FA10: =EX10-ES10 -> 0 | FB10: =IFERROR((EV10-ER10)*100/ER10,"") | FC10: =IFERROR((EX10-ES10)*100/ES10,"") | FF10: =$B10 -> ترانشیپ | FG10: =$C10 -> تن | FH10: =SUMIFS([1]واردات!$E$42:$E$51,[1]واردات!$AA$42:$AA$51,FT2) -> 0 | FJ10: =SUMIFS([1]واردات!$I$42:$I$51,[1]واردات!$AA$42:$AA$51,FT2) -> 0 | FL10: =SUMIFS([1]واردات!$M$42:$M$51,[1]واردات!$AA$42:$AA$51,FT2) -> 0 | FM10: =IFERROR(FL10*100/FJ10,"") | FO10: =IFERROR(FN10*100/FK10,"") | FP10: =FL10-FH10 -> 0 | FQ10: =FN10-FI10 -> 0 | FR10: =IFERROR((FL10-FH10)*100/FH10,"") | FS10: =IFERROR((FN10-FI10)*100/FI10,"")
B11: خدمات باربری | C11: میلیون ریال | E11: =SUM(U11,AK11,BA11,BQ11,CG11,CW11,DM11,EC11,ES11,FI11) -> 73454 | G11: =SUM(W11,AM11,BC11,BS11,CI11,CY11,DO11,EE11,EU11,FK11) -> 132255 | J11: =SUM(Z11,AP11,BF11,BV11,CL11,DB11,DR11,EH11,EX11,FN11) -> 118106 | K11: =IFERROR(J11*100/G11,"") -> 89.301728 | M11: =IFERROR(J11-E11,"") -> 44652 | O11: =IFERROR((J11-E11)*100/E11,"") -> 60.789065 | P11: 1 | R11: =$B11 -> خدمات باربری | S11: =$C11 -> میلیون ریال | U11: 12286 | W11: 38822 | Z11: 3602 | AA11: =IFERROR(Z11*100/W11,"") -> 9.2782443 | AC11: =Z11-U11 -> -8684 | AE11: =IFERROR((Z11-U11)*100/U11,"") -> -70.682077 | AH11: =$B11 -> خدمات باربری | AI11: =$C11 -> میلیون ریال | AK11: 2818 | AM11: 3883 | AP11: 1448 | AQ11: =IFERROR(AP11*100/AM11,"") -> 37.290755 | AS11: =AP11-AK11 -> -1370 | AU11: =IFERROR((AP11-AK11)*100/AK11,"") -> -48.61604 | AX11: =$B11 -> خدمات باربری | AY11: =$C11 -> میلیون ریال | BA11: 6742 | BC11: 13533 | BF11: 6290 | BG11: =IFERROR(BF11*100/BC11,"") -> 46.478977 | BI11: =BF11-BA11 -> -452 | BK11: =IFERROR((BF11-BA11)*100/BA11,"") -> -6.7042421 | BN11: =$B11 -> خدمات باربری | BO11: =$C11 -> میلیون ریال | BQ11: 40661 | BS11: 56411 | BV11: 59733 | BW11: =IFERROR(BV11*100/BS11,"") -> 105.88892 | BY11: =BV11-BQ11 -> 19072 | CA11: =IFERROR((BV11-BQ11)*100/BQ11,"") -> 46.904897 | CD11: =$B11 -> خدمات باربری | CE11: =$C11 -> میلیون ریال | CG11: 1149 | CI11: 1254 | CL11: 1948 | CM11: =IFERROR(CL11*100/CI11,"") -> 155.3429 | CO11: =CL11-CG11 -> 799 | CQ11: =IFERROR((CL11-CG11)*100/CG11,"") -> 69.538729 | CT11: =$B11 -> خدمات باربری | CU11: =$C11 -> میلیون ریال | CW11: 5 | CY11: 4 | DB11: 61 | DC11: =IFERROR(DB11*100/CY11,"") -> 1525 | DE11: =DB11-CW11 -> 56 | DG11: =IFERROR((DB11-CW11)*100/CW11,"") -> 1120 | DJ11: =$B11 -> خدمات باربری | DK11: =$C11 -> میلیون ریال | DM11: 9573 | DO11: 16803 | DR11: 43786 | DS11: =IFERROR(DR11*100/DO11,"") -> 260.58442 | DU11: =DR11-DM11 -> 34213 | DW11: =IFERROR((DR11-DM11)*100/DM11,"") -> 357.39058 | DZ11: =$B11 -> خدمات باربری | EA11: =$C11 -> میلیون ریال | EC11: 168 | EE11: 1334 | EH11: 325 | EI11: =IFERROR(EH11*100/EE11,"") -> 24.362819 | EK11: =EH11-EC11 -> 157 | EM11: =IFERROR((EH11-EC11)*100/EC11,"") -> 93.452381 | EP11: =$B11 -> خدمات باربری | EQ11: =$C11 -> میلیون ریال | ES11: 52 | EU11: 211 | EX11: 913 | EY11: =IFERROR(EX11*100/EU11,"") -> 432.70142 | FA11: =EX11-ES11 -> 861 | FC11: =IFERROR((EX11-ES11)*100/ES11,"") -> 1655.7692 | FF11: =$B11 -> خدمات باربری | FG11: =$C11 -> میلیون ریال | FO11: =IFERROR(FN11*100/FK11,"") | FQ11: =FN11-FI11 -> 0 | FS11: =IFERROR((FN11-FI11)*100/FI11,"")
B12: بیمه | C12: میلیون ریال | E12: =SUM(U12,AK12,BA12,BQ12,CG12,CW12,DM12,EC12,ES12,FI12) -> 74605 | G12: =SUM(W12,AM12,BC12,BS12,CI12,CY12,DO12,EE12,EU12,FK12) -> 158140 | J12: =SUM(Z12,AP12,BF12,BV12,CL12,DB12,DR12,EH12,EX12,FN12) -> 150422 | K12: =IFERROR(J12*100/G12,"") -> 95.119514 | M12: =IFERROR(J12-E12,"") -> 75817 | O12: =IFERROR((J12-E12)*100/E12,"") -> 101.62456 | P12: 0 | R12: =$B12 -> بیمه | S12: =$C12 -> میلیون ریال | U12: 23994 | W12: 57455 | Z12: 17962 | AA12: =IFERROR(Z12*100/W12,"") -> 31.262727 | AC12: =Z12-U12 -> -6032 | AE12: =IFERROR((Z12-U12)*100/U12,"") -> -25.139618 | AH12: =$B12 -> بیمه | AI12: =$C12 -> میلیون ریال | AK12: 2402 | AM12: 4269 | AP12: 6902 | AQ12: =IFERROR(AP12*100/AM12,"") -> 161.67721 | AS12: =AP12-AK12 -> 4500 | AU12: =IFERROR((AP12-AK12)*100/AK12,"") -> 187.34388 | AX12: =$B12 -> بیمه | AY12: =$C12 -> میلیون ریال | BA12: 7033 | BC12: 17991 | BF12: 13170 | BG12: =IFERROR(BF12*100/BC12,"") -> 73.203268 | BI12: =BF12-BA12 -> 6137 | BK12: =IFERROR((BF12-BA12)*100/BA12,"") -> 87.26006 | BN12: =$B12 -> بیمه | BO12: =$C12 -> میلیون ریال | BQ12: 17704 | BS12: 31685 | BV12: 31514 | BW12: =IFERROR(BV12*100/BS12,"") -> 99.460312 | BY12: =BV12-BQ12 -> 13810 | CA12: =IFERROR((BV12-BQ12)*100/BQ12,"") -> 78.004971 | CD12: =$B12 -> بیمه | CE12: =$C12 -> میلیون ریال | CG12: 6556 | CI12: 9762 | CL12: 24779 | CM12: =IFERROR(CL12*100/CI12,"") -> 253.83118 | CO12: =CL12-CG12 -> 18223 | CQ12: =IFERROR((CL12-CG12)*100/CG12,"") -> 277.95912 | CT12: =$B12 -> بیمه | CU12: =$C12 -> میلیون ریال | CW12: 129 | CY12: 163 | DB12: 4113 | DC12: =IFERROR(DB12*100/CY12,"") -> 2523.3129 | DE12: =DB12-CW12 -> 3984 | DG12: =IFERROR((DB12-CW12)*100/CW12,"") -> 3088.3721 | DJ12: =$B12 -> بیمه | DK12: =$C12 -> میلیون ریال | DM12: 15546 | DO12: 34765 | DR12: 46034 | DS12: =IFERROR(DR12*100/DO12,"") -> 132.41478 | DU12: =DR12-DM12 -> 30488 | DW12: =IFERROR((DR12-DM12)*100/DM12,"") -> 196.11476 | DZ12: =$B12 -> بیمه | EA12: =$C12 -> میلیون ریال | EC12: 939 | EE12: 1635 | EH12: 121 | EI12: =IFERROR(EH12*100/EE12,"") -> 7.4006116 | EK12: =EH12-EC12 -> -818 | EM12: =IFERROR((EH12-EC12)*100/EC12,"") -> -87.113951 | EP12: =$B12 -> بیمه | EQ12: =$C12 -> میلیون ریال | ES12: 302 | EU12: 415 | EX12: 5827 | EY12: =IFERROR(EX12*100/EU12,"") -> 1404.0964 | FA12: =EX12-ES12 -> 5525 | FC12: =IFERROR((EX12-ES12)*100/ES12,"") -> 1829.4702 | FF12: =$B12 -> بیمه | FG12: =$C12 -> میلیون ریال | FO12: =IFERROR(FN12*100/FK12,"") | FQ12: =FN12-FI12 -> 0 | FS12: =IFERROR((FN12-FI12)*100/FI12,"")
A13: صادرات | B13: انبارداری | C13: تن | D13: =SUM(T13,AJ13,AZ13,BP13,CF13,CV13,DL13,EB13,ER13,FH13) -> 26356 | E13: =SUM(U13,AK13,BA13,BQ13,CG13,CW13,DM13,EC13,ES13,FI13) -> 29875 | F13: =SUM(V13,AL13,BB13,BR13,CH13,CX13,DN13,ED13,ET13,FJ13) -> 36653.374 | G13: =SUM(W13,AM13,BC13,BS13,CI13,CY13,DO13,EE13,EU13,FK13) -> 46391 | H13: =SUM(X13,AN13,BD13,BT13,CJ13,CZ13,DP13,EF13,EV13,FL13) -> 43469 | I13: =IFERROR(H13*100/F13,"") -> 118.59481 | J13: =SUM(Z13,AP13,BF13,BV13,CL13,DB13,DR13,EH13,EX13,FN13) -> 50631 | K13: =IFERROR(J13*100/G13,"") -> 109.1397 | L13: =IFERROR(H13-D13,"") -> 17113 | M13: =IFERROR(J13-E13,"") -> 20756 | N13: =IFERROR((H13-D13)*100/D13,"") -> 64.930187 | O13: =IFERROR((J13-E13)*100/E13,"") -> 69.476151 | P13: 1 | Q13: =$A$13 -> صادرات | R13: =$B13 -> انبارداری | S13: =$C13 -> تن | T13: =SUMIFS([1]صادرات!$D$42:$D$51,[1]صادرات!$AA$42:$AA$51,AF2) -> 19 | U13: 62 | V13: =SUMIFS([1]صادرات!$H$42:$H$51,[1]صادرات!$AA$42:$AA$51,AF2) -> 112.61889 | W13: 553 | X13: =SUMIFS([1]صادرات!$L$42:$L$51,[1]صادرات!$AA$42:$AA$51,AF2) -> 1 | Y13: =IFERROR(X13*100/V13,"") -> 0.88795054 | Z13: 227 | AA13: =IFERROR(Z13*100/W13,"") -> 41.048825 | AB13: =X13-T13 -> -18 | AC13: =Z13-U13 -> 165 | AD13: =IFERROR((X13-T13)*100/T13,"") -> -94.736842 | AE13: =IFERROR((Z13-U13)*100/U13,"") -> 266.12903 | AG13: =$A$13 -> صادرات | AH13: =$B13 -> انبارداری | AI13: =$C13 -> تن | AJ13: =SUMIFS([1]صادرات!$D$42:$D$51,[1]صادرات!$AA$42:$AA$51,AV2) -> 17690 | AK13: 16279 | AL13: =SUMIFS([1]صادرات!$H$42:$H$51,[1]صادرات!$AA$42:$AA$51,AV2) -> 30771.372 | AM13: 35062 | AN13: =SUMIFS([1]صادرات!$L$42:$L$51,[1]صادرات!$AA$42:$AA$51,AV2) -> 29701 | AO13: =IFERROR(AN13*100/AL13,"") -> 96.521534 | AP13: 28471 | AQ13: =IFERROR(AP13*100/AM13,"") -> 81.201871 | AR13: =AN13-AJ13 -> 12011 | AS13: =AP13-AK13 -> 12192 | AT13: =IFERROR((AN13-AJ13)*100/AJ13,"") -> 67.897117 | AU13: =IFERROR((AP13-AK13)*100/AK13,"") -> 74.894035 | AW13: =$A$13 -> صادرات | AX13: =$B13 -> انبارداری | AY13: =$C13 -> تن | AZ13: =SUMIFS([1]صادرات!$D$42:$D$51,[1]صادرات!$AA$42:$AA$51,BL2) -> 5146 | BA13: 1985 | BB13: =SUMIFS([1]صادرات!$H$42:$H$51,[1]صادرات!$AA$42:$AA$51,BL2) -> 2959.1333 | BC13: 1882 | BD13: =SUMIFS([1]صادرات!$L$42:$L$51,[1]صادرات!$AA$42:$AA$51,BL2) -> 7010 | BE13: =IFERROR(BD13*100/BB13,"") -> 236.89369 | BF13: 6252 | BG13: =IFERROR(BF13*100/BC13,"") -> 332.19979 | BH13: =BD13-AZ13 -> 1864 | BI13: =BF13-BA13 -> 4267 | BJ13: =IFERROR((BD13-AZ13)*100/AZ13,"") -> 36.222309 | BK13: =IFERROR((BF13-BA13)*100/BA13,"") -> 214.96222 | BM13: =$A$13 -> صادرات | BN13: =$B13 -> انبارداری | BO13: =$C13 -> تن | BP13: =SUMIFS([1]صادرات!$D$42:$D$51,[1]صادرات!$AA$42:$AA$51,CB2) -> 996 | BQ13: 2301 | BR13: =SUMIFS([1]صادرات!$H$42:$H$51,[1]صادرات!$AA$42:$AA$51,CB2) -> 1708.8143 | BS13: 3739 | BT13: =SUMIFS([1]صادرات!$L$42:$L$51,[1]صادرات!$AA$42:$AA$51,CB2) -> 4561 | BU13: =IFERROR(BT13*100/BR13,"") -> 266.91022 | BV13: 8632 | BW13: =IFERROR(BV13*100/BS13,"") -> 230.86387 | BX13: =BT13-BP13 -> 3565 | BY13: =BV13-BQ13 -> 6331 | BZ13: =IFERROR((BT13-BP13)*100/BP13,"") -> 357.93173 | CA13: =IFERROR((BV13-BQ13)*100/BQ13,"") -> 275.14124 | CC13: =$A$13 -> صادرات | CD13: =$B13 -> انبارداری | CE13: =$C13 -> تن | CF13: =SUMIFS([1]صادرات!$D$42:$D$51,[1]صادرات!$AA$42:$AA$51,CR2) -> 0 | CH13: =SUMIFS([1]صادرات!$H$42:$H$51,[1]صادرات!$AA$42:$AA$51,CR2) -> 0 | CJ13: =SUMIFS([1]صادرات!$L$42:$L$51,[1]صادرات!$AA$42:$AA$51,CR2) -> 0 | CK13: =IFERROR(CJ13*100/CH13,"") | CM13: =IFERROR(CL13*100/CI13,"") | CN13: =CJ13-CF13 -> 0 | CO13: =CL13-CG13 -> 0 | CP13: =IFERROR((CJ13-CF13)*100/CF13,"") | CQ13: =IFERROR((CL13-CG13)*100/CG13,"") | CS13: =$A$13 -> صادرات | CT13: =$B13 -> انبارداری | CU13: =$C13 -> تن | CV13: =SUMIFS([1]صادرات!$D$42:$D$51,[1]صادرات!$AA$42:$AA$51,DH2) -> 2086 | CW13: 7671 | CX13: =SUMIFS([1]صادرات!$H$42:$H$51,[1]صادرات!$AA$42:$AA$51,DH2) -> 895.96023 | CY13: 4090 | CZ13: =SUMIFS([1]صادرات!$L$42:$L$51,[1]صادرات!$AA$42:$AA$51,DH2) -> 924 | DA13: =IFERROR(CZ13*100/CX13,"") -> 103.12958 | DB13: 3539 | DC13: =IFERROR(DB13*100/CY13,"") -> 86.528117 | DD13: =CZ13-CV13 -> -1162 | DE13: =DB13-CW13 -> -4132 | DF13: =IFERROR((CZ13-CV13)*100/CV13,"") -> -55.704698 | DG13: =IFERROR((DB13-CW13)*100/CW13,"") -> -53.865207 | DI13: =$A$13 -> صادرات | DJ13: =$B13 -> انبارداری | DK13: =$C13 -> تن | DL13: =SUMIFS([1]صادرات!$D$42:$D$51,[1]صادرات!$AA$42:$AA$51,DX2) -> 419 | DM13: 1577 | DN13: =SUMIFS([1]صادرات!$H$42:$H$51,[1]صادرات!$AA$42:$AA$51,DX2) -> 205.47551 | DO13: 1065 | DP13: =SUMIFS([1]صادرات!$L$42:$L$51,[1]صادرات!$AA$42:$AA$51,DX2) -> 311 | DQ13: =IFERROR(DP13*100/DN13,"") -> 151.35623 | DR13: 1514 | DS13: =IFERROR(DR13*100/DO13,"") -> 142.15962 | DT13: =DP13-DL13 -> -108 | DU13: =DR13-DM13 -> -63 | DV13: =IFERROR((DP13-DL13)*100/DL13,"") -> -25.775656 | DW13: =IFERROR((DR13-DM13)*100/DM13,"") -> -3.9949271 | DY13: =$A$13 -> صادرات | DZ13: =$B13 -> انبارداری | EA13: =$C13 -> تن | EB13: =SUMIFS([1]صادرات!$D$42:$D$51,[1]صادرات!$AA$42:$AA$51,EN2) -> 0 | ED13: =SUMIFS([1]صادرات!$H$42:$H$51,[1]صادرات!$AA$42:$AA$51,EN2) -> 0 | EF13: =SUMIFS([1]صادرات!$L$42:$L$51,[1]صادرات!$AA$42:$AA$51,EN2) -> 0 | EG13: =IFERROR(EF13*100/ED13,"") | EI13: =IFERROR(EH13*100/EE13,"") | EJ13: =EF13-EB13 -> 0 | EK13: =EH13-EC13 -> 0 | EL13: =IFERROR((EF13-EB13)*100/EB13,"") | EM13: =IFERROR((EH13-EC13)*100/EC13,"") | EO13: =$A$13 -> صادرات | EP13: =$B13 -> انبارداری | EQ13: =$C13 -> تن | ER13: =SUMIFS([1]صادرات!$D$42:$D$51,[1]صادرات!$AA$42:$AA$51,FD2) -> 0 | ET13: =SUMIFS([1]صادرات!$H$42:$H$51,[1]صادرات!$AA$42:$AA$51,FD2) -> 0 | EV13: =SUMIFS([1]صادرات!$L$42:$L$51,[1]صادرات!$AA$42:$AA$51,FD2) -> 8 | EW13: =IFERROR(EV13*100/ET13,"") | EX13: 132 | EY13: =IFERROR(EX13*100/EU13,"") | EZ13: =EV13-ER13 -> 8 | FA13: =EX13-ES13 -> 132 | FB13: =IFERROR((EV13-ER13)*100/ER13,"") | FC13: =IFERROR((EX13-ES13)*100/ES13,"") | FE13: =$A$13 -> صادرات | FF13: =$B13 -> انبارداری | FG13: =$C13 -> تن | FH13: =SUMIFS([1]صادرات!$D$42:$D$51,[1]صادرات!$AA$42:$AA$51,FT2) -> 0 | FJ13: =SUMIFS([1]صادرات!$H$42:$H$51,[1]صادرات!$AA$42:$AA$51,FT2) -> 0 | FL13: =SUMIFS([1]صادرات!$L$42:$L$51,[1]صادرات!$AA$42:$AA$51,FT2) -> 953 | FM13: =IFERROR(FL13*100/FJ13,"") | FN13: 1864 | FO13: =IFERROR(FN13*100/FK13,"") | FP13: =FL13-FH13 -> 953 | FQ13: =FN13-FI13 -> 1864 | FR13: =IFERROR((FL13-FH13)*100/FH13,"") | FS13: =IFERROR((FN13-FI13)*100/FI13,"")
B14: میانگین مدت ماندگاری کالا | C14: روز | D14: =IFERROR(D15/D13,"") -> 24.691304 | F14: =IFERROR(F15/F13,"") -> 25.040062 | H14: =IFERROR(H15/H13,"") -> 29.219191 | I14: =IFERROR(H14*100/F14,"") -> 116.68977 | L14: =IFERROR(H14-D14,"") -> 4.527887 | N14: =IFERROR((H14-D14)*100/D14,"") -> 18.337983 | O14: =IFERROR((J14-E14)*100/E14,"-") -> - | P14: 1 | R14: =$B14 -> میانگین مدت ماندگاری کالا | S14: =$C14 -> روز | T14: 20 | V14: 28 | X14: 90 | Y14: =IFERROR(X14*100/V14,"") -> 321.42857 | AB14: =X14-T14 -> 70 | AC14: =Z14-U14 -> 0 | AD14: =IFERROR((X14-T14)*100/T14,"") -> 350 | AE14: =IFERROR((Z14-U14)*100/U14,"-") -> - | AH14: =$B14 -> میانگین مدت ماندگاری کالا | AI14: =$C14 -> روز | AJ14: 25 | AL14: 26 | AN14: 28 | AO14: =IFERROR(AN14*100/AL14,"") -> 107.69231 | AR14: =AN14-AJ14 -> 3 | AS14: =AP14-AK14 -> 0 | AT14: =IFERROR((AN14-AJ14)*100/AJ14,"") -> 12 | AU14: =IFERROR((AP14-AK14)*100/AK14,"-") -> - | AX14: =$B14 -> میانگین مدت ماندگاری کالا | AY14: =$C14 -> روز | AZ14: 13 | BB14: 8 | BD14: 19 | BE14: =IFERROR(BD14*100/BB14,"") -> 237.5 | BH14: =BD14-AZ14 -> 6 | BI14: =BF14-BA14 -> 0 | BJ14: =IFERROR((BD14-AZ14)*100/AZ14,"") -> 46.153846 | BK14: =IFERROR((BF14-BA14)*100/BA14,"-") -> - | BN14: =$B14 -> میانگین مدت ماندگاری کالا | BO14: =$C14 -> روز | BP14: 32 | BR14: 25 | BT14: 22 | BU14: =IFERROR(BT14*100/BR14,"") -> 88 | BX14: =BT14-BP14 -> -10 | BY14: =BV14-BQ14 -> 0 | BZ14: =IFERROR((BT14-BP14)*100/BP14,"") -> -31.25 | CA14: =IFERROR((BV14-BQ14)*100/BQ14,"-") -> - | CD14: =$B14 -> میانگین مدت ماندگاری کالا | CE14: =$C14 -> روز | CK14: =IFERROR(CJ14*100/CH14,"") | CN14: =CJ14-CF14 -> 0 | CO14: =CL14-CG14 -> 0 | CP14: =IFERROR((CJ14-CF14)*100/CF14,"") | CQ14: =IFERROR((CL14-CG14)*100/CG14,"-") -> - | CT14: =$B14 -> میانگین مدت ماندگاری کالا | CU14: =$C14 -> روز | CV14: 46 | CX14: 46 | CZ14: 182 | DA14: =IFERROR(CZ14*100/CX14,"") -> 395.65217 | DD14: =CZ14-CV14 -> 136 | DE14: =DB14-CW14 -> 0 | DF14: =IFERROR((CZ14-CV14)*100/CV14,"") -> 295.65217 | DG14: =IFERROR((DB14-CW14)*100/CW14,"-") -> - | DJ14: =$B14 -> میانگین مدت ماندگاری کالا | DK14: =$C14 -> روز | DL14: 32 | DN14: 34 | DP14: 41 | DQ14: =IFERROR(DP14*100/DN14,"") -> 120.58824 | DT14: =DP14-DL14 -> 9 | DU14: =DR14-DM14 -> 0 | DV14: =IFERROR((DP14-DL14)*100/DL14,"") -> 28.125 | DW14: =IFERROR((DR14-DM14)*100/DM14,"-") -> - | DZ14: =$B14 -> میانگین مدت ماندگاری کالا | EA14: =$C14 -> روز | EG14: =IFERROR(EF14*100/ED14,"") | EJ14: =EF14-EB14 -> 0 | EK14: =EH14-EC14 -> 0 | EL14: =IFERROR((EF14-EB14)*100/EB14,"") | EM14: =IFERROR((EH14-EC14)*100/EC14,"-") -> - | EP14: =$B14 -> میانگین مدت ماندگاری کالا | EQ14: =$C14 -> روز | ER14: 0 | EV14: 136 | EW14: =IFERROR(EV14*100/ET14,"") | EZ14: =EV14-ER14 -> 136 | FA14: =EX14-ES14 -> 0 | FB14: =IFERROR((EV14-ER14)*100/ER14,"") | FC14: =IFERROR((EX14-ES14)*100/ES14,"-") -> - | FF14: =$B14 -> میانگین مدت ماندگاری کالا | FG14: =$C14 -> روز | FL14: 24 | FM14: =IFERROR(FL14*100/FJ14,"") | FP14: =FL14-FH14 -> 24 | FQ14: =FN14-FI14 -> 0 | FR14: =IFERROR((FL14-FH14)*100/FH14,"") | FS14: =IFERROR((FN14-FI14)*100/FI14,"-") -> -
B15: انبارداری | C15: تن روز | D15: =SUM(T15,AJ15,AZ15,BP15,CF15,CV15,DL15,EB15,ER15,FH15) -> 650764 | F15: =SUM(V15,AL15,BB15,BR15,CH15,CX15,DN15,ED15,ET15,FJ15) -> 917802.75 | H15: =SUM(X15,AN15,BD15,BT15,CJ15,CZ15,DP15,EF15,EV15,FL15) -> 1270129 | I15: =IFERROR(H15*100/F15,"") -> 138.38801 | L15: =IFERROR(H15-D15,"") -> 619365 | N15: =IFERROR((H15-D15)*100/D15,"") -> 95.175056 | O15: =IFERROR((J15-E15)*100/E15,"-") -> - | P15: 1 | R15: =$B15 -> انبارداری | S15: =$C15 -> تن روز | T15: =IFERROR(T13*T14,"") -> 380 | V15: =IFERROR(V13*V14,"") -> 3153.3288 | X15: =IFERROR(X13*X14,"") -> 90 | Y15: =IFERROR(X15*100/V15,"") -> 2.8541267 | AB15: =X15-T15 -> -290 | AC15: =Z15-U15 -> 0 | AD15: =IFERROR((X15-T15)*100/T15,"") -> -76.315789 | AE15: =IFERROR((Z15-U15)*100/U15,"-") -> - | AH15: =$B15 -> انبارداری | AI15: =$C15 -> تن روز | AJ15: =IFERROR(AJ13*AJ14,"") -> 442250 | AL15: =IFERROR(AL13*AL14,"") -> 800055.66 | AN15: =IFERROR(AN13*AN14,"") -> 831628 | AO15: =IFERROR(AN15*100/AL15,"") -> 103.94627 | AR15: =AN15-AJ15 -> 389378 | AS15: =AP15-AK15 -> 0 | AT15: =IFERROR((AN15-AJ15)*100/AJ15,"") -> 88.044771 | AU15: =IFERROR((AP15-AK15)*100/AK15,"-") -> - | AX15: =$B15 -> انبارداری | AY15: =$C15 -> تن روز | AZ15: =IFERROR(AZ13*AZ14,"") -> 66898 | BB15: =IFERROR(BB13*BB14,"") -> 23673.067 | BD15: =IFERROR(BD13*BD14,"") -> 133190 | BE15: =IFERROR(BD15*100/BB15,"") -> 562.6225 | BH15: =BD15-AZ15 -> 66292 | BI15: =BF15-BA15 -> 0 | BJ15: =IFERROR((BD15-AZ15)*100/AZ15,"") -> 99.094143 | BK15: =IFERROR((BF15-BA15)*100/BA15,"-") -> - | BN15: =$B15 -> انبارداری | BO15: =$C15 -> تن روز | BP15: =IFERROR(BP13*BP14,"") -> 31872 | BR15: =IFERROR(BR13*BR14,"") -> 42720.358 | BT15: =IFERROR(BT13*BT14,"") -> 100342 | BU15: =IFERROR(BT15*100/BR15,"") -> 234.88099 | BX15: =BT15-BP15 -> 68470 | BY15: =BV15-BQ15 -> 0 | BZ15: =IFERROR((BT15-BP15)*100/BP15,"") -> 214.82806 | CA15: =IFERROR((BV15-BQ15)*100/BQ15,"-") -> - | CD15: =$B15 -> انبارداری | CE15: =$C15 -> تن روز | CF15: =IFERROR(CF13*CF14,"") -> 0 | CH15: =IFERROR(CH13*CH14,"") -> 0 | CJ15: =IFERROR(CJ13*CJ14,"") -> 0 | CK15: =IFERROR(CJ15*100/CH15,"") | CN15: =CJ15-CF15 -> 0 | CO15: =CL15-CG15 -> 0 | CP15: =IFERROR((CJ15-CF15)*100/CF15,"") | CQ15: =IFERROR((CL15-CG15)*100/CG15,"-") -> - | CT15: =$B15 -> انبارداری | CU15: =$C15 -> تن روز | CV15: =IFERROR(CV13*CV14,"") -> 95956 | CX15: =IFERROR(CX13*CX14,"") -> 41214.171 | CZ15: =IFERROR(CZ13*CZ14,"") -> 168168 | DA15: =IFERROR(CZ15*100/CX15,"") -> 408.03441 | DD15: =CZ15-CV15 -> 72212 | DE15: =DB15-CW15 -> 0 | DF15: =IFERROR((CZ15-CV15)*100/CV15,"") -> 75.255325 | DG15: =IFERROR((DB15-CW15)*100/CW15,"-") -> - | DJ15: =$B15 -> انبارداری | DK15: =$C15 -> تن روز | DL15: =IFERROR(DL13*DL14,"") -> 13408 | DN15: =IFERROR(DN13*DN14,"") -> 6986.1675 | DP15: =IFERROR(DP13*DP14,"") -> 12751 | DQ15: =IFERROR(DP15*100/DN15,"") -> 182.51781 | DT15: =DP15-DL15 -> -657 | DU15: =DR15-DM15 -> 0 | DV15: =IFERROR((DP15-DL15)*100/DL15,"") -> -4.9000597 | DW15: =IFERROR((DR15-DM15)*100/DM15,"-") -> - | DZ15: =$B15 -> انبارداری | EA15: =$C15 -> تن روز | EB15: =IFERROR(EB13*EB14,"") -> 0 | ED15: =IFERROR(ED13*ED14,"") -> 0 | EF15: =IFERROR(EF13*EF14,"") -> 0 | EG15: =IFERROR(EF15*100/ED15,"") | EJ15: =EF15-EB15 -> 0 | EK15: =EH15-EC15 -> 0 | EL15: =IFERROR((EF15-EB15)*100/EB15,"") | EM15: =IFERROR((EH15-EC15)*100/EC15,"-") -> - | EP15: =$B15 -> انبارداری | EQ15: =$C15 -> تن روز | ER15: =IFERROR(ER13*ER14,"") -> 0 | ET15: =IFERROR(ET13*ET14,"") -> 0 | EV15: =IFERROR(EV13*EV14,"") -> 1088 | EW15: =IFERROR(EV15*100/ET15,"") | EZ15: =EV15-ER15 -> 1088 | FA15: =EX15-ES15 -> 0 | FB15: =IFERROR((EV15-ER15)*100/ER15,"") | FC15: =IFERROR((EX15-ES15)*100/ES15,"-") -> - | FF15: =$B15 -> انبارداری | FG15: =$C15 -> تن روز | FH15: =IFERROR(FH13*FH14,"") -> 0 | FJ15: =IFERROR(FJ13*FJ14,"") -> 0 | FL15: =IFERROR(FL13*FL14,"") -> 22872 | FM15: =IFERROR(FL15*100/FJ15,"") | FP15: =FL15-FH15 -> 22872 | FQ15: =FN15-FI15 -> 0 | FR15: =IFERROR((FL15-FH15)*100/FH15,"") | FS15: =IFERROR((FN15-FI15)*100/FI15,"-") -> -
