Workbook
Name AA: #REF!
Name aaa: '[1]100022'!$A$1:$AV$90
Name aaaaa: '[2]عوامل در مراکز '!$A$1:$AV$87
Name acttype: #REF!
Name ali: #REF!
Name Ard: "آرد قراردادي"
Name BTitle: #REF!
Name Contracual_Driver: [3]Parametr!$C$3
Name cr_kim_sheet1: [4]SHEET1!#REF!
Name Daramad_Serkati_GF: 125%
Name Daramad_Tejari_GF: 125%
Name fd: #REF!
Name fm: #REF!
Name fpath: #REF!
Name ftype: #REF!
Name fulltablist: #REF!
Name fy: #REF!
Name fymd: #REF!
Name Gandom: "گندم قراردادي"
Name Hazineh_Sherkati_GF: 130%
Name Hazineh_Tejari_GF: 130%
Name LastCell: #REF!
Name Light_Ratio: [3]Parametr!$C$7
Name Ostani: "گندم قراردادي"
Name Sarasari: "سراسري"
Name StartCell: #REF!
Name tabfile: #REF!
Name tabref: #REF!
Name tabtitles: #REF!
Name Tashim_From_Cost_to_Official: #REF!
Name Tashim_From_Cost_to_Official_12_month_92_Forcast: #REF!
Name Tashim_From_Cost_to_Official_6_month_92: #REF!
Name Tashim_From_Cost_to_Opratinal_12_month_92_Forcast: #REF!
Name vco: #REF!
Name vconame: #REF!
Name ا: #REF!
Name آوینی: #REF!
Name تلاتال: '[5]عوامل در مراکز '!$A$1:$AV$87
Name مم: [4]SHEET1!#REF!
Name مواد: #REF!
Name ناهغ: [4]SHEET1!#REF!
Name یییی: [6]SHEET1!#REF!
Name ئم10: [7]BudgetDB!#REF!

Sheet مجتمع خراسان
B1: شرکت انبارهای عمومی و خدمات گمرکی ایران / شعبه مجتمع خراسان
B3: آمار مقایسه ای عملیاتی - 6 ماهه اول | J3: آمار مقایسه ای عملیاتی - 6 ماهه اول
B4: واردات | C4: عملیات (تن) | D4: تناژ | G4: درصد تحقق | H4: درصد تغییرات به عملکرد | J4: صادرات | K4: عملیات (تن) | L4: تناژ | O4: درصد تحقق | P4: درصد تغییرات به عملکرد
D5: عملکرد 1404 | E5: بودجه 1405 | F5: عملکرد 1405 | G5: بودجه | L5: عملکرد 1404 | M5: بودجه 1405 | N5: عملکرد 1405 | O5: بودجه
C6: تخلیه | D6: 102609 | E6: 142772 | F6: 139434 | G6: =F6/E6*100 -> 97.662007 | H6: =IFERROR((F6-D6)*100/D6,"") -> 35.888665 | K6: تخلیه | L6: 24961 | M6: 33653 | N6: 43957 | O6: =N6/M6*100 -> 130.61837 | P6: =IFERROR((N6-L6)*100/L6,"") -> 76.10272
C7: بارگیری | D7: 113724 | E7: 152262 | F7: 145727 | G7: =F7/E7*100 -> 95.708056 | H7: =IFERROR((F7-D7)*100/D7,"") -> 28.140938 | K7: بارگیری | L7: 26356 | M7: 36653 | N7: 43469 | O7: =N7/M7*100 -> 118.59602 | P7: =IFERROR((N7-L7)*100/L7,"") -> 64.930187
C8: حمل یکسره | D8: 3902 | E8: 9774 | F8: 657 | G8: =F8/E8*100 -> 6.7219153 | H8: =IFERROR((F8-D8)*100/D8,"") -> -83.162481 | K8: حمل یکسره | L8: 18 | M8: 26 | O8: =N8/M8*100 -> 0 | P8: =IFERROR((N8-L8)*100/L8,"") -> -100
C9: ترانشیپ | D9: 498346 | E9: 509432 | F9: 641162 | G9: =F9/E9*100 -> 125.85821 | H9: =IFERROR((F9-D9)*100/D9,"") -> 28.658001 | K9: ترانشیپ | L9: 378750 | M9: 513151 | N9: 467550 | O9: =N9/M9*100 -> 91.113532 | P9: =IFERROR((N9-L9)*100/L9,"") -> 23.445545
B12: آمار مقایسه ای درآمد واردات - 6 ماهه اول | J12: آمار مقایسه ای درآمد صادرات - 6 ماهه اول
B13: درآمد واردات (میلیون ریال) | D13: عملکرد 1404 | E13: بودجه 1405 | F13: عملکرد 1405 | G13: درصد تحقق بودجه | H13: درصد تغییرات به عملکرد | J13: درآمد صادرات (میلیون ریال) | L13: عملکرد 1404 | M13: بودجه 1405 | N13: عملکرد 1405 | O13: درصد تحقق بودجه | P13: درصد تغییرات به عملکرد
B14: انبارداری | D14: 331775 | E14: 615444 | F14: 528593 | G14: =-IFERROR(F14*100/E14,"") -> -85.888074 | H14: =IFERROR((F14-D14)*100/D14,"") -> 59.322734 | J14: انبارداری | L14: 29875 | M14: 46391 | N14: 50631 | O14: =IFERROR(N14*100/M14,"") -> 109.1397 | P14: =IFERROR((N14-L14)*100/L14,"") -> 69.476151
B15: باربری | D15: 465998 | E15: 690927 | F15: 808273 | G15: =IFERROR(F15*100/E15,"") -> 116.98385 | H15: =IFERROR((F15-D15)*100/D15,"") -> 73.449886 | J15: باربری | L15: 33448 | M15: 56912 | N15: 44261 | O15: =-IFERROR(N15*100/M15,"") -> -77.770945 | P15: =IFERROR((N15-L15)*100/L15,"") -> 32.327792
B16: حمل یکسره | D16: 151 | E16: 67 | F16: 479 | G16: =IFERROR(F16*100/E16,"") -> 714.92537 | H16: =IFERROR((F16-D16)*100/D16,"") -> 217.21854 | J16: حمل یکسره | P16: =IFERROR((N16-L16)*100/L16,"")
B17: ترانشیپ | D17: 95843 | E17: 146941 | F17: 164419 | G17: =IFERROR(F17*100/E17,"") -> 111.89457 | H17: =IFERROR((F17-D17)*100/D17,"") -> 71.550348 | J17: ترانشیپ | L17: 5622 | M17: 8953 | N17: 949122 | O17: =IFERROR(N17*100/M17,"") -> 10601.162 | P17: =IFERROR((N17-L17)*100/L17,"") -> 16782.284
B18: سایر خدمات باربری | D18: 73454 | E18: 132255 | F18: 118206 | G18: =-IFERROR(F18*100/E18,"") -> -89.377339 | H18: =IFERROR((F18-D18)*100/D18,"") -> 60.925205 | J18: سایر خدمات باربری | L18: 55252 | M18: 55246 | N18: 34526 | O18: =-IFERROR(N18*100/M18,"") -> -62.495022 | P18: =IFERROR((N18-L18)*100/L18,"") -> -37.511764
B19: بیمه | D19: 74605 | E19: 158140 | F19: 150422 | G19: =IFERROR(F19*100/E19,"") -> 95.119514 | H19: =IFERROR((F19-D19)*100/D19,"") -> 101.62456 | J19: بیمه | L19: 2515 | M19: 4653 | N19: 10575 | O19: =IFERROR(N19*100/M19,"") -> 227.27273 | P19: =IFERROR((N19-L19)*100/L19,"") -> 320.47714
B21: سود و زیان مقایسه ای - 6 ماهه اول
B22: شرح (میلیون ریال) | D22: عملکرد 1404 | F22: بودجه 1405 | H22: عملکرد 1405 | J22: درصد تحقق بودجه | K22: درصد تغییرات به عملکرد
B23: درآمد حاصل از ارائه خدمات | D23: 1091418 | F23: 1753136 | H23: 2698410 | J23: =IFERROR(H23*100/F23,"") -> 153.91903 | K23: =IFERROR((H23-D23)*100/ABS(D23),"") -> 147.23891
B24: بهای تمام شده ارائه خدمات | D24: -1271898 | F24: -2007348 | H24: -2950579 | J24: =IFERROR(H24*100/F24,"") -> 146.98891 | K24: =IFERROR((H24-D24)*100/ABS(D24),"") -> -131.98236
B25: سود (زیان) ناخالص | D25: -180480 | F25: -254212 | H25: -252169 | J25: =IFERROR(H25*100/F25,"") -> 99.19634 | K25: =IFERROR((H25-D25)*100/ABS(D25),"") -> -39.721299
B26: هزینه های اداری و عمومی | D26: -158356 | F26: -241263 | H26: -264469 | J26: =IFERROR(H26*100/F26,"") -> 109.61855 | K26: =IFERROR((H26-D26)*100/ABS(D26),"") -> -67.009144
B27: سایر درآمدهای عملیاتی | D27: 692240 | F27: 922004 | H27: 1042459 | J27: =IFERROR(H27*100/F27,"") -> 113.06448 | K27: =IFERROR((H27-D27)*100/ABS(D27),"") -> 50.592136
B28: سایر هزینه های عملیاتی | J28: =IFERROR(H28*100/F28,"") | K28: =IFERROR((H28-D28)*100/ABS(D28),"")
B29: سود ( زیان ) عملیاتی | D29: 353404 | F29: 426529 | H29: 525821 | J29: =IFERROR(H29*100/F29,"") -> 123.27907 | K29: =IFERROR((H29-D29)*100/ABS(D29),"") -> 48.787507
B30: هزینه های مالی | J30: =IFERROR(H30*100/F30,"") | K30: =IFERROR((H30-D30)*100/ABS(D30),"")
B31: سایر درآمد (هزینه) غیر عملیاتی | D31: 4 | F31: 3 | H31: 100 | J31: =IFERROR(H31*100/F31,"") -> 3333.3333 | K31: =IFERROR((H31-D31)*100/ABS(D31),"") -> 2400
B32: سود (زیان) خالص (قبل از مالیات) | D32: 353408 | F32: 426532 | H32: 525921 | J32: =IFERROR(H32*100/F32,"") -> 123.30165 | K32: =IFERROR((H32-D32)*100/ABS(D32),"") -> 48.814119
B34: آمار مقایسه ای منابع انسانی - 6 ماهه اول
B35: نیروی انسانی | D35: عملکرد 1404 | H35: بودجه 1405 | L35: عملکرد 1405 | P35: تحقق بودجه (نفر) | Q35: تغییرات به عملکرد (نفر)
D36: رسمی | E36: قراردادی | F36: پیمانی | G36: جمع | H36: رسمی | I36: قراردادی | J36: پیمانی | K36: جمع | L36: رسمی | M36: قراردادی | N36: پیمانی | O36: جمع | P36: جمع | Q36: جمع
B37: ارائه خدمات | D37: =SUM(کاوه!D37+مطهری!D37+سرخس!D37+'لطف آباد'!D37+نیشابور!D37+ماهیرود!D37+دوغارون!D37+بجنورد!D37+بیرجند!D37+باجگیران!D37) -> 0 | E37: =SUM(کاوه!E37+مطهری!E37+سرخس!E37+'لطف آباد'!E37+نیشابور!E37+ماهیرود!E37+دوغارون!E37+بجنورد!E37+بیرجند!E37+باجگیران!E37) -> 166 | F37: =SUM(کاوه!F37+مطهری!F37+سرخس!F37+'لطف آباد'!F37+نیشابور!F37+ماهیرود!F37+دوغارون!F37+بجنورد!F37+بیرجند!F37+باجگیران!F37) -> 23 | G37: =SUM(کاوه!G37+مطهری!G37+سرخس!G37+'لطف آباد'!G37+نیشابور!G37+ماهیرود!G37+دوغارون!G37+بجنورد!G37+بیرجند!G37+باجگیران!G37) -> 189 | H37: =SUM(کاوه!H37+مطهری!H37+سرخس!H37+'لطف آباد'!H37+نیشابور!H37+ماهیرود!H37+دوغارون!H37+بجنورد!H37+بیرجند!H37+باجگیران!H37) -> 0 | I37: =SUM(کاوه!I37+مطهری!I37+سرخس!I37+'لطف آباد'!I37+نیشابور!I37+ماهیرود!I37+دوغارون!I37+بجنورد!I37+بیرجند!I37+باجگیران!I37) -> 166 | J37: =SUM(کاوه!J37+مطهری!J37+سرخس!J37+'لطف آباد'!J37+نیشابور!J37+ماهیرود!J37+دوغارون!J37+بجنورد!J37+بیرجند!J37+باجگیران!J37) -> 95 | K37: =SUM(کاوه!K37+مطهری!K37+سرخس!K37+'لطف آباد'!K37+نیشابور!K37+ماهیرود!K37+دوغارون!K37+بجنورد!K37+بیرجند!K37+باجگیران!K37) -> 258 | ... O37: =SUM(کاوه!O37+مطهری!O37+سرخس!O37+'لطف آباد'!O37+نیشابور!O37+ماهیرود!O37+دوغارون!O37+بجنورد!O37+بیرجند!O37+باجگیران!O37) -> 203 | P37: =O37*100/K37 -> 78.682171 | Q37: =O37*100/G37 -> 107.40741
B38: اداری و عمومی | D38: =SUM(کاوه!D38+مطهری!D38+سرخس!D38+'لطف آباد'!D38+نیشابور!D38+ماهیرود!D38+دوغارون!D38+بجنورد!D38+بیرجند!D38+باجگیران!D38) -> 0 | E38: =SUM(کاوه!E38+مطهری!E38+سرخس!E38+'لطف آباد'!E38+نیشابور!E38+ماهیرود!E38+دوغارون!E38+بجنورد!E38+بیرجند!E38+باجگیران!E38) -> 31 | F38: =SUM(کاوه!F38+مطهری!F38+سرخس!F38+'لطف آباد'!F38+نیشابور!F38+ماهیرود!F38+دوغارون!F38+بجنورد!F38+بیرجند!F38+باجگیران!F38) -> 9 | G38: =SUM(کاوه!G38+مطهری!G38+سرخس!G38+'لطف آباد'!G38+نیشابور!G38+ماهیرود!G38+دوغارون!G38+بجنورد!G38+بیرجند!G38+باجگیران!G38) -> 40 | H38: =SUM(کاوه!H38+مطهری!H38+سرخس!H38+'لطف آباد'!H38+نیشابور!H38+ماهیرود!H38+دوغارون!H38+بجنورد!H38+بیرجند!H38+باجگیران!H38) -> 0 | I38: =SUM(کاوه!I38+مطهری!I38+سرخس!I38+'لطف آباد'!I38+نیشابور!I38+ماهیرود!I38+دوغارون!I38+بجنورد!I38+بیرجند!I38+باجگیران!I38) -> 31 | J38: =SUM(کاوه!J38+مطهری!J38+سرخس!J38+'لطف آباد'!J38+نیشابور!J38+ماهیرود!J38+دوغارون!J38+بجنورد!J38+بیرجند!J38+باجگیران!J38) -> 15 | K38: =SUM(کاوه!K38+مطهری!K38+سرخس!K38+'لطف آباد'!K38+نیشابور!K38+ماهیرود!K38+دوغارون!K38+بجنورد!K38+بیرجند!K38+باجگیران!K38) -> 45 | ... O38: =SUM(کاوه!O38+مطهری!O38+سرخس!O38+'لطف آباد'!O38+نیشابور!O38+ماهیرود!O38+دوغارون!O38+بجنورد!O38+بیرجند!O38+باجگیران!O38) -> 39 | P38: =O38*100/K38 -> 86.666667 | Q38: =O38*100/G38 -> 97.5
B39: جمع | E39: =SUM(E37:E38) -> 197 | F39: =SUM(F37:F38) -> 32 | G39: =SUM(G37:G38) -> 229 | H39: =SUM(H37:H38) -> 0 | I39: =SUM(I37:I38) -> 197 | J39: =SUM(J37:J38) -> 110 | K39: 307 | L39: =SUM(L37:L38) -> 0 | M39: =SUM(M37:M38) -> 193 | N39: =SUM(N37:N38) -> 49 | O39: =SUM(O37:O38) -> 242 | P39: =O39*100/K39 -> 78.827362 | Q39: =O39*100/G39 -> 105.67686

Sheet کاوه
B1: شرکت انبارهای عمومی و خدمات گمرکی ایران / شعبه کاوه
B3: آمار مقایسه ای عملیاتی - 6 ماهه اول | J3: آمار مقایسه ای عملیاتی - 6 ماهه اول
B4: واردات | C4: عملیات (تن) | D4: تناژ | G4: درصد تحقق | H4: درصد تغییرات به عملکرد | J4: صادرات | K4: عملیات (تن) | L4: تناژ | O4: درصد تحقق | P4: درصد تغییرات به عملکرد
D5: عملکرد 1404 | E5: بودجه 1405 | F5: عملکرد 1405 | G5: بودجه | L5: عملکرد 1404 | M5: بودجه 1405 | N5: عملکرد 1405 | O5: بودجه
C6: تخلیه | D6: 10454 | E6: 31858 | F6: 3728 | G6: =F6/E6*100 -> 11.701927 | H6: =IFERROR((F6-D6)*100/D6,"") -> -64.339009 | K6: تخلیه | L6: 43 | M6: 138 | N6: 2 | O6: =N6/M6*100 -> 1.4492754 | P6: =IFERROR((N6-L6)*100/L6,"") -> -95.348837
C7: بارگیری | D7: 11125 | E7: 38497 | F7: 2891 | G7: =F7/E7*100 -> 7.5096761 | H7: =IFERROR((F7-D7)*100/D7,"") -> -74.013483 | K7: بارگیری | L7: 19 | M7: 113 | N7: 1 | O7: =N7/M7*100 -> 0.88495575 | P7: =IFERROR((N7-L7)*100/L7,"") -> -94.736842
C8: حمل یکسره | D8: 3822 | E8: 9716 | F8: 40 | G8: =F8/E8*100 -> 0.41169205 | H8: =IFERROR((F8-D8)*100/D8,"") -> -98.953428 | K8: حمل یکسره | L8: 18 | M8: 26 | N8: 0 | O8: =N8/M8*100 -> 0 | P8: =IFERROR((N8-L8)*100/L8,"") -> -100
C9: ترانشیپ | K9: ترانشیپ | L9: 0 | M9: 0 | N9: 0 | O9: 0
B12: آمار مقایسه ای درآمد واردات - 6 ماهه اول | J12: آمار مقایسه ای درآمد صادرات - 6 ماهه اول
B13: درآمد واردات (میلیون ریال) | D13: عملکرد 1404 | E13: بودجه 1405 | F13: عملکرد 1405 | G13: درصد تحقق بودجه | H13: درصد تغییرات به عملکرد | J13: درآمد صادرات (میلیون ریال) | L13: عملکرد 1404 | M13: بودجه 1405 | N13: عملکرد 1405 | O13: درصد تحقق بودجه | P13: درصد تغییرات به عملکرد
B14: انبارداری | D14: 54657 | E14: 210259 | F14: 33548 | G14: =-IFERROR(F14*100/E14,"") -> -15.95556 | H14: =IFERROR((F14-D14)*100/D14,"") -> -38.620854 | J14: انبارداری | L14: 62 | M14: 553 | N14: 227 | O14: =IFERROR(N14*100/M14,"") -> 41.048825 | P14: =IFERROR((N14-L14)*100/L14,"") -> 266.12903
B15: باربری | D15: 40772 | E15: 138874 | F15: 14688 | G15: =IFERROR(F15*100/E15,"") -> 10.576494 | H15: =IFERROR((F15-D15)*100/D15,"") -> -63.975277 | J15: باربری | L15: 44 | M15: 191 | N15: 5 | O15: =IFERROR(N15*100/M15,"") -> 2.617801 | P15: =IFERROR((N15-L15)*100/L15,"") -> -88.636364
B16: حمل یکسره | D16: 26 | E16: 67 | F16: 26 | G16: =IFERROR(F16*100/E16,"") -> 38.80597 | H16: =IFERROR((F16-D16)*100/D16,"") -> 0 | J16: حمل یکسره | P16: =IFERROR((N16-L16)*100/L16,"")
B17: ترانشیپ | G17: =IFERROR(F17*100/E17,"") | H17: =IFERROR((F17-D17)*100/D17,"") | J17: ترانشیپ | O17: =IFERROR(N17*100/M17,"") | P17: =IFERROR((N17-L17)*100/L17,"")
B18: سایر خدمات باربری | D18: 12286 | E18: 38822 | F18: 3602 | G18: =-IFERROR(F18*100/E18,"") -> -9.2782443 | H18: =IFERROR((F18-D18)*100/D18,"") -> -70.682077 | J18: سایر خدمات باربری | L18: 12 | M18: 46 | N18: 7 | O18: =IFERROR(N18*100/M18,"") -> 15.217391 | P18: =IFERROR((N18-L18)*100/L18,"") -> -41.666667
B19: بیمه | D19: 23994 | E19: 57455 | F19: 17962 | G19: =IFERROR(F19*100/E19,"") -> 31.262727 | H19: =IFERROR((F19-D19)*100/D19,"") -> -25.139618 | J19: بیمه | L19: 71 | M19: 131 | N19: 24 | O19: =IFERROR(N19*100/M19,"") -> 18.320611 | P19: =IFERROR((N19-L19)*100/L19,"") -> -66.197183
B21: سود و زیان مقایسه ای - 6 ماهه اول
B22: شرح (میلیون ریال) | D22: عملکرد 1404 | F22: بودجه 1405 | H22: عملکرد 1405 | J22: درصد تحقق بودجه | K22: درصد تغییرات به عملکرد
B23: درآمد حاصل از ارائه خدمات | D23: 107877 | F23: 388812 | G23: =SUMIFS('[8]جدول فروش خدمات'!$U$25:$FT$25,'[8]جدول فروش خدمات'!$U$1:$FT$1,K21,'[8]جدول فروش خدمات'!$U$26:$FT$26,2) -> 0 | H23: 52103 | I23: =SUMIFS('[8]جدول فروش خدمات'!$U$25:$FT$25,'[8]جدول فروش خدمات'!$U$1:$FT$1,L21,'[8]جدول فروش خدمات'!$U$26:$FT$26,3) -> 0 | J23: =IFERROR(H23*100/F23,"") -> 13.400564 | K23: =IFERROR((H23-D23)*100/ABS(D23),"") -> -51.701475
B24: بهای تمام شده ارائه خدمات | D24: -122962 | F24: -176122 | G24: -176122 | H24: -262637 | I24: -262637 | J24: =IFERROR(H24*100/F24,"") -> 149.1222 | K24: =IFERROR((H24-D24)*100/ABS(D24),"") -> -113.592
B25: سود (زیان) ناخالص | D25: =SUM(D23:D24) -> -15085 | F25: =SUM(F23:F24) -> 212690 | G25: =SUM(G23:G24) -> -176122 | H25: =SUM(H23:H24) -> -210534 | I25: =SUM(I23:I24) -> -262637 | J25: =IFERROR(H25*100/F25,"") -> -98.986318 | K25: =IFERROR((H25-D25)*100/ABS(D25),"") -> -1295.6513
B26: هزینه های اداری و عمومی | D26: -102673 | F26: -151121 | G26: -151121 | H26: -160157 | I26: -160157 | J26: =IFERROR(H26*100/F26,"") -> 105.97931 | K26: =IFERROR((H26-D26)*100/ABS(D26),"") -> -55.987455
B27: سایر درآمدهای عملیاتی | D27: =1678+24065 -> 25743 | F27: 66586 | G27: 66586 | H27: =600+17987 -> 18587 | I27: =600+17987 -> 18587 | J27: =IFERROR(H27*100/F27,"") -> 27.914276 | K27: =IFERROR((H27-D27)*100/ABS(D27),"") -> -27.797848
B28: سایر هزینه های عملیاتی | J28: =IFERROR(H28*100/F28,"") | K28: =IFERROR((H28-D28)*100/ABS(D28),"")
B29: سود ( زیان ) عملیاتی | D29: -92015 | F29: 128155 | H29: -352104 | J29: =IFERROR(H29*100/F29,"") -> -274.74855 | K29: =IFERROR((H29-D29)*100/ABS(D29),"") -> -282.65935
B30: هزینه های مالی | J30: =IFERROR(H30*100/F30,"") | K30: =IFERROR((H30-D30)*100/ABS(D30),"")
B31: سایر درآمد (هزینه) غیر عملیاتی | D31: 1 | F31: 2 | J31: =IFERROR(H31*100/F31,"") -> 0 | K31: =IFERROR((H31-D31)*100/ABS(D31),"") -> -100
B32: سود (زیان) خالص (قبل از مالیات) | D32: -92014 | F32: 128157 | H32: -333517 | J32: =IFERROR(H32*100/F32,"") -> -260.24095 | K32: =IFERROR((H32-D32)*100/ABS(D32),"") -> -262.46332
B34: آمار مقایسه ای منابع انسانی - 6 ماهه اول
B35: نیروی انسانی | D35: عملکرد 1404 | H35: بودجه 1405 | L35: عملکرد 1405 | P35: تحقق بودجه (نفر) | Q35: تغییرات به عملکرد (نفر)
D36: رسمی | E36: قراردادی | F36: پیمانی | G36: جمع | H36: رسمی | I36: قراردادی | J36: پیمانی | K36: جمع | L36: رسمی | M36: قراردادی | N36: پیمانی | O36: جمع | P36: جمع | Q36: جمع
B37: ارائه خدمات | E37: 21 | F37: 1 | G37: =SUM(E37:F37) -> 22 | I37: 21 | J37: 7 | K37: =SUM(I37:J37) -> 28 | M37: 22 | N37: 1 | O37: =SUM(M37:N37) -> 23 | P37: =O37*100/K37 -> 82.142857 | Q37: =O37*100/G37 -> 104.54545
B38: اداری و عمومی | E38: 20 | F38: 5 | G38: =SUM(E38:F38) -> 25 | I38: 20 | J38: 7 | K38: =SUM(I38:J38) -> 27 | M38: 18 | N38: 6 | O38: =SUM(M38:N38) -> 24 | P38: =O38*100/K38 -> 88.888889 | Q38: =O38*100/G38 -> 96
B39: جمع | E39: =SUM(E37:E38) -> 41 | F39: =SUM(F37:F38) -> 6 | G39: =SUM(G37:G38) -> 47 | H39: =SUM(H37:H38) -> 0 | I39: =SUM(I37:I38) -> 41 | J39: =SUM(J37:J38) -> 14 | K39: =SUM(K37:K38) -> 55 | L39: =SUM(L37:L38) -> 0 | ... O39: =SUM(O37:O38) -> 47 | P39: =O39*100/K39 -> 85.454545 | Q39: =O39*100/G39 -> 100

Sheet مطهری
B1: شرکت انبارهای عمومی و خدمات گمرکی ایران / شعبه شهید مطهری
B3: آمار مقایسه ای عملیاتی - 6 ماهه اول | J3: آمار مقایسه ای عملیاتی - 6 ماهه اول
B4: واردات | C4: عملیات (تن) | D4: تناژ | G4: درصد تحقق | H4: درصد تغییرات به عملکرد | J4: صادرات | K4: عملیات (تن) | L4: تناژ | O4: درصد تحقق | P4: درصد تغییرات به عملکرد
D5: عملکرد 1404 | E5: بودجه 1405 | F5: عملکرد 1405 | G5: بودجه | L5: عملکرد 1404 | M5: بودجه 1405 | N5: عملکرد 1405 | O5: بودجه
C6: تخلیه | D6: 11312 | E6: 15241 | F6: 8102 | G6: =F6/E6*100 -> 53.159242 | K6: تخلیه | L6: 16869 | M6: 28802 | N6: 30635 | O6: =N6/M6*100 -> 106.36414
C7: بارگیری | D7: 9899 | E7: 16320 | F7: 6309 | G7: =F7/E7*100 -> 38.658088 | K7: بارگیری | L7: 17690 | M7: 30771 | N7: 29701 | O7: =N7/M7*100 -> 96.5227
C8: حمل یکسره | F8: 493 | K8: حمل یکسره | L8: 0 | M8: 0 | N8: 0 | O8: 0
C9: ترانشیپ | F9: 2207 | K9: ترانشیپ | L9: 351651 | M9: 481483 | N9: 433194 | O9: =N9/M9*100 -> 89.970778
B12: آمار مقایسه ای درآمد واردات - 6 ماهه اول | J12: آمار مقایسه ای درآمد صادرات - 6 ماهه اول
B13: درآمد واردات (میلیون ریال) | D13: عملکرد 1404 | E13: بودجه 1405 | F13: عملکرد 1405 | G13: درصد تحقق بودجه | H13: درصد تغییرات به عملکرد | J13: درآمد صادرات (میلیون ریال) | L13: عملکرد 1404 | M13: بودجه 1405 | N13: عملکرد 1405 | O13: درصد تحقق بودجه | P13: درصد تغییرات به عملکرد
B14: انبارداری | D14: 31072 | E14: 58398 | F14: 39017 | G14: =-IFERROR(F14*100/E14,"") -> -66.81222 | H14: =IFERROR((F14-D14)*100/D14,"") -> 25.569645 | J14: انبارداری | L14: 16279 | M14: 35062 | N14: 28471 | O14: =IFERROR(N14*100/M14,"") -> 81.201871 | P14: =IFERROR((N14-L14)*100/L14,"") -> 74.894035
B15: باربری | D15: 9720 | E15: 16351 | F15: 25516 | G15: =IFERROR(F15*100/E15,"") -> 156.05162 | H15: =IFERROR((F15-D15)*100/D15,"") -> 162.51029 | J15: باربری | L15: 22687 | M15: 45920 | N15: 18524 | O15: =IFERROR(N15*100/M15,"") -> 40.339721 | P15: =IFERROR((N15-L15)*100/L15,"") -> -18.349716
B16: حمل یکسره | F16: 292 | G16: =IFERROR(F16*100/E16,"") | H16: =IFERROR((F16-D16)*100/D16,"") | J16: حمل یکسره | P16: =IFERROR((N16-L16)*100/L16,"")
B17: ترانشیپ | F17: 1557 | G17: =IFERROR(F17*100/E17,"") | H17: =IFERROR((F17-D17)*100/D17,"") | J17: ترانشیپ | L17: 4847 | M17: 8269 | N17: 931556 | O17: =IFERROR(N17*100/M17,"") -> 11265.643 | P17: =IFERROR((N17-L17)*100/L17,"") -> 19119.228
B18: سایر خدمات باربری | D18: 2818 | E18: 3883 | F18: 1448 | G18: =-IFERROR(F18*100/E18,"") -> -37.290755 | H18: =IFERROR((F18-D18)*100/D18,"") -> -48.61604 | J18: سایر خدمات باربری | L18: 10009 | M18: 22293 | N18: 9912 | O18: =IFERROR(N18*100/M18,"") -> 44.462387 | P18: =IFERROR((N18-L18)*100/L18,"") -> -0.96912778
B19: بیمه | D19: 2402 | E19: 4269 | F19: 6902 | G19: =IFERROR(F19*100/E19,"") -> 161.67721 | H19: =IFERROR((F19-D19)*100/D19,"") -> 187.34388 | J19: بیمه | L19: 687 | M19: 1458 | N19: 2180 | O19: =IFERROR(N19*100/M19,"") -> 149.51989 | P19: =IFERROR((N19-L19)*100/L19,"") -> 217.32169
B21: سود و زیان مقایسه ای - 6 ماهه اول
B22: شرح (میلیون ریال) | D22: عملکرد 1404 | F22: بودجه 1405 | H22: عملکرد 1405 | J22: درصد تحقق بودجه | K22: درصد تغییرات به عملکرد
B23: درآمد حاصل از ارائه خدمات | D23: 97432 | E23: =SUMIFS('[8]جدول فروش خدمات'!$U$25:$FT$25,'[8]جدول فروش خدمات'!$U$1:$FT$1,J21,'[8]جدول فروش خدمات'!$U$26:$FT$26,1) -> 0 | F23: 190176 | G23: =SUMIFS('[8]جدول فروش خدمات'!$U$25:$FT$25,'[8]جدول فروش خدمات'!$U$1:$FT$1,K21,'[8]جدول فروش خدمات'!$U$26:$FT$26,2) -> 0 | H23: 1056293 | I23: =SUMIFS('[8]جدول فروش خدمات'!$U$25:$FT$25,'[8]جدول فروش خدمات'!$U$1:$FT$1,L21,'[8]جدول فروش خدمات'!$U$26:$FT$26,3) -> 0 | J23: =IFERROR(H23*100/F23,"") -> 555.42918 | K23: =IFERROR((H23-D23)*100/ABS(D23),"") -> 984.13355
B24: بهای تمام شده ارائه خدمات | D24: -266845 | E24: -266845 | F24: -445118 | G24: -445118 | H24: -1255074 | I24: -1255074 | J24: =IFERROR(H24*100/F24,"") -> 281.96433 | K24: =IFERROR((H24-D24)*100/ABS(D24),"") -> -370.33821
B25: سود (زیان) ناخالص | D25: =SUM(D23:D24) -> -169413 | E25: =SUM(E23:E24) -> -266845 | F25: =SUM(F23:F24) -> -254942 | G25: =SUM(G23:G24) -> -445118 | H25: =SUM(H23:H24) -> -198781 | I25: =SUM(I23:I24) -> -1255074 | J25: =IFERROR(H25*100/F25,"") -> 77.971068 | K25: =IFERROR((H25-D25)*100/ABS(D25),"") -> -17.335151
B26: هزینه های اداری و عمومی | D26: -5805 | E26: -5805 | F26: -7023 | G26: -7023 | H26: -1255 | I26: -1255 | J26: =IFERROR(H26*100/F26,"") -> 17.869856 | K26: =IFERROR((H26-D26)*100/ABS(D26),"") -> 78.380706
B27: سایر درآمدهای عملیاتی | D27: =114672+3089 -> 117761 | E27: =114672+3089 -> 117761 | F27: 260167 | G27: 260167 | H27: =83574+9083 -> 92657 | I27: =83574+9083 -> 92657 | J27: =IFERROR(H27*100/F27,"") -> 35.614432 | K27: =IFERROR((H27-D27)*100/ABS(D27),"") -> -21.317754
B28: سایر هزینه های عملیاتی | J28: =IFERROR(H28*100/F28,"") | K28: =IFERROR((H28-D28)*100/ABS(D28),"")
B29: سود ( زیان ) عملیاتی | D29: -57457 | F29: -1798 | H29: -107379 | J29: =IFERROR(H29*100/F29,"") -> 5972.1357 | K29: =IFERROR((H29-D29)*100/ABS(D29),"") -> -86.885845
B30: هزینه های مالی | J30: =IFERROR(H30*100/F30,"") | K30: =IFERROR((H30-D30)*100/ABS(D30),"")
B31: سایر درآمد (هزینه) غیر عملیاتی | J31: =IFERROR(H31*100/F31,"") | K31: =IFERROR((H31-D31)*100/ABS(D31),"")
B32: سود (زیان) خالص (قبل از مالیات) | D32: -57457 | F32: -1798 | H32: -107379 | J32: =IFERROR(H32*100/F32,"") -> 5972.1357 | K32: =IFERROR((H32-D32)*100/ABS(D32),"") -> -86.885845
B34: آمار مقایسه ای منابع انسانی - 6 ماهه اول
B35: نیروی انسانی | D35: عملکرد 1404 | H35: بودجه 1405 | L35: عملکرد 1405 | P35: تحقق بودجه (نفر) | Q35: تغییرات به عملکرد (نفر)
D36: رسمی | E36: قراردادی | F36: پیمانی | G36: جمع | H36: رسمی | I36: قراردادی | J36: پیمانی | K36: جمع | L36: رسمی | M36: قراردادی | N36: پیمانی | O36: جمع | P36: جمع | Q36: جمع
B37: ارائه خدمات | E37: 27 | F37: 7 | G37: =SUM(E37:F37) -> 34 | I37: 27 | J37: 11 | K37: =SUM(I37:J37) -> 38 | M37: 27 | N37: 10 | O37: =SUM(M37:N37) -> 37 | P37: =O37*100/K37 -> 97.368421 | Q37: =O37*100/G37 -> 108.82353
B38: اداری و عمومی | E38: 1 | F38: 2 | G38: =SUM(E38:F38) -> 3 | I38: 1 | J38: 2 | K38: =SUM(I38:J38) -> 3 | M38: 1 | N38: 2 | O38: =SUM(M38:N38) -> 3 | P38: =O38*100/K38 -> 100 | Q38: =O38*100/G38 -> 100
B39: جمع | E39: =SUM(E37:E38) -> 28 | F39: =SUM(F37:F38) -> 9 | G39: =SUM(G37:G38) -> 37 | H39: =SUM(H37:H38) -> 0 | I39: =SUM(I37:I38) -> 28 | J39: =SUM(J37:J38) -> 13 | K39: =SUM(K37:K38) -> 41 | L39: =SUM(L37:L38) -> 0 | ... O39: =SUM(O37:O38) -> 40 | P39: =O39*100/K39 -> 97.560976 | Q39: =O39*100/G39 -> 108.10811

Sheet سرخس
B1: شرکت انبارهای عمومی و خدمات گمرکی ایران / شعبه سرخس
B3: آمار مقایسه ای عملیاتی - 6 ماهه اول | J3: آمار مقایسه ای عملیاتی - 6 ماهه اول
B4: واردات | C4: عملیات (تن) | D4: تناژ | G4: درصد تحقق | H4: درصد تغییرات به عملکرد | J4: صادرات | K4: عملیات (تن) | L4: تناژ | O4: درصد تحقق | P4: درصد تغییرات به عملکرد
D5: عملکرد 1404 | E5: بودجه 1405 | F5: عملکرد 1405 | G5: بودجه | L5: عملکرد 1404 | M5: بودجه 1405 | N5: عملکرد 1405 | O5: بودجه
C6: تخلیه | D6: 8705 | E6: 9512 | F6: 5924 | G6: =F6/E6*100 -> 62.279226 | K6: تخلیه | L6: 5281 | M6: 2694 | N6: 7067 | O6: =N6/M6*100 -> 262.32368
C7: بارگیری | D7: 7882 | E7: 9272 | F7: 6778 | G7: =F7/E7*100 -> 73.101812 | K7: بارگیری | L7: 5146 | M7: 2959 | N7: 7010 | O7: =N7/M7*100 -> 236.90436
C8: حمل یکسره | G8: 0 | K8: حمل یکسره | L8: 0 | M8: 0 | N8: 0 | O8: 0
C9: ترانشیپ | D9: 29637 | E9: 35362 | F9: 24810 | G9: =F9/E9*100 -> 70.160059 | K9: ترانشیپ | L9: 27099 | M9: 31668 | N9: 34359 | O9: =N9/M9*100 -> 108.49754
B12: آمار مقایسه ای درآمد واردات - 6 ماهه اول | J12: آمار مقایسه ای درآمد صادرات - 6 ماهه اول
B13: درآمد واردات (میلیون ریال) | D13: عملکرد 1404 | E13: بودجه 1405 | F13: عملکرد 1405 | G13: درصد تحقق بودجه | H13: درصد تغییرات به عملکرد | J13: درآمد صادرات (میلیون ریال) | L13: عملکرد 1404 | M13: بودجه 1405 | N13: عملکرد 1405 | O13: درصد تحقق بودجه | P13: درصد تغییرات به عملکرد
B14: انبارداری | D14: 25923 | E14: 45500 | F14: 26869 | G14: =IFERROR(F14*100/E14,"") -> 59.052747 | H14: =IFERROR((F14-D14)*100/D14,"") -> 3.649269 | J14: انبارداری | L14: 1985 | M14: 1882 | N14: 6252 | O14: =IFERROR(N14*100/M14,"") -> 332.19979 | P14: =IFERROR((N14-L14)*100/L14,"") -> 214.96222
B15: باربری | D15: 32643 | E15: 57439 | F15: 43718 | G15: =IFERROR(F15*100/E15,"") -> 76.112049 | H15: =IFERROR((F15-D15)*100/D15,"") -> 33.927641 | J15: باربری | L15: 7581 | M15: 6003 | N15: 13446 | O15: =IFERROR(N15*100/M15,"") -> 223.98801 | P15: =IFERROR((N15-L15)*100/L15,"") -> 77.364464
B16: حمل یکسره | G16: =IFERROR(F16*100/E16,"") | H16: =IFERROR((F16-D16)*100/D16,"") | J16: حمل یکسره | P16: =IFERROR((N16-L16)*100/L16,"")
B17: ترانشیپ | D17: 8883 | E17: 14281 | F17: 7949 | G17: =IFERROR(F17*100/E17,"") -> 55.661368 | H17: =IFERROR((F17-D17)*100/D17,"") -> -10.514466 | J17: ترانشیپ | L17: 775 | M17: 684 | N17: 17566 | O17: =IFERROR(N17*100/M17,"") -> 2568.1287 | P17: =IFERROR((N17-L17)*100/L17,"") -> 2166.5806
B18: سایر خدمات باربری | D18: 6742 | E18: 13533 | F18: 6290 | G18: =IFERROR(F18*100/E18,"") -> 46.478977 | H18: =IFERROR((F18-D18)*100/D18,"") -> -6.7042421 | J18: سایر خدمات باربری | L18: 356 | M18: 294 | N18: 582 | O18: =IFERROR(N18*100/M18,"") -> 197.95918 | P18: =IFERROR((N18-L18)*100/L18,"") -> 63.483146
B19: بیمه | D19: 7033 | E19: 17991 | F19: 13170 | G19: =IFERROR(F19*100/E19,"") -> 73.203268 | H19: =IFERROR((F19-D19)*100/D19,"") -> 87.26006 | J19: بیمه | L19: 508 | M19: 607 | N19: 2121 | O19: =IFERROR(N19*100/M19,"") -> 349.42339 | P19: =IFERROR((N19-L19)*100/L19,"") -> 317.51969
B21: سود و زیان مقایسه ای - 6 ماهه اول
B22: شرح (میلیون ریال) | D22: عملکرد 1404 | F22: بودجه 1405 | H22: عملکرد 1405 | J22: درصد تحقق بودجه | K22: درصد تغییرات به عملکرد
B23: درآمد حاصل از ارائه خدمات | D23: 84888 | E23: =SUMIFS('[8]جدول فروش خدمات'!$U$25:$FT$25,'[8]جدول فروش خدمات'!$U$1:$FT$1,J21,'[8]جدول فروش خدمات'!$U$26:$FT$26,1) -> 0 | F23: 139616 | G23: =SUMIFS('[8]جدول فروش خدمات'!$U$25:$FT$25,'[8]جدول فروش خدمات'!$U$1:$FT$1,K21,'[8]جدول فروش خدمات'!$U$26:$FT$26,2) -> 0 | H23: 122672 | I23: =SUMIFS('[8]جدول فروش خدمات'!$U$25:$FT$25,'[8]جدول فروش خدمات'!$U$1:$FT$1,L21,'[8]جدول فروش خدمات'!$U$26:$FT$26,3) -> 0 | J23: =IFERROR(H23*100/F23,"") -> 87.863855 | K23: =IFERROR((H23-D23)*100/ABS(D23),"") -> 44.510414
B24: بهای تمام شده ارائه خدمات | D24: -131538 | E24: -131538 | F24: -215372 | G24: -215372 | H24: -228781 | I24: -228781 | J24: =IFERROR(H24*100/F24,"") -> 106.22597 | K24: =IFERROR((H24-D24)*100/ABS(D24),"") -> -73.927686
B25: سود (زیان) ناخالص | D25: =SUM(D23:D24) -> -46650 | E25: =SUM(E23:E24) -> -131538 | F25: =SUM(F23:F24) -> -75756 | G25: =SUM(G23:G24) -> -215372 | H25: =SUM(H23:H24) -> -106109 | I25: =SUM(I23:I24) -> -228781 | J25: =IFERROR(H25*100/F25,"") -> 140.06679 | K25: =IFERROR((H25-D25)*100/ABS(D25),"") -> -127.45766
B26: هزینه های اداری و عمومی | D26: -12492 | E26: -12492 | F26: -21204 | G26: -21204 | H26: -22790 | I26: -22790 | J26: =IFERROR(H26*100/F26,"") -> 107.47972 | K26: =IFERROR((H26-D26)*100/ABS(D26),"") -> -82.43676
B27: سایر درآمدهای عملیاتی | D27: =75140+7542 -> 82682 | E27: =75140+7542 -> 82682 | F27: 88672 | G27: 88672 | H27: =110956+15291 -> 126247 | I27: =110956+15291 -> 126247 | J27: =IFERROR(H27*100/F27,"") -> 142.37527 | K27: =IFERROR((H27-D27)*100/ABS(D27),"") -> 52.689824
B28: سایر هزینه های عملیاتی | J28: =IFERROR(H28*100/F28,"") | K28: =IFERROR((H28-D28)*100/ABS(D28),"")
B29: سود ( زیان ) عملیاتی | D29: 23540 | F29: -8288 | H29: -2652 | J29: =IFERROR(H29*100/F29,"") -> 31.998069 | K29: =IFERROR((H29-D29)*100/ABS(D29),"") -> -111.26593
B30: هزینه های مالی | J30: =IFERROR(H30*100/F30,"") | K30: =IFERROR((H30-D30)*100/ABS(D30),"")
B31: سایر درآمد (هزینه) غیر عملیاتی | D31: 2 | H31: 100 | J31: =IFERROR(H31*100/F31,"") | K31: =IFERROR((H31-D31)*100/ABS(D31),"") -> 4900
B32: سود (زیان) خالص (قبل از مالیات) | D32: 23540 | F32: -8288 | H32: -2652 | J32: =IFERROR(H32*100/F32,"") -> 31.998069 | K32: =IFERROR((H32-D32)*100/ABS(D32),"") -> -111.26593
B34: آمار مقایسه ای منابع انسانی - 6 ماهه اول
B35: نیروی انسانی | D35: عملکرد 1404 | H35: بودجه 1405 | L35: عملکرد 1405 | P35: تحقق بودجه (نفر) | Q35: تغییرات به عملکرد (نفر)
D36: رسمی | E36: قراردادی | F36: پیمانی | G36: جمع | H36: رسمی | I36: قراردادی | J36: پیمانی | K36: جمع | L36: رسمی | M36: قراردادی | N36: پیمانی | O36: جمع | P36: جمع | Q36: جمع
B37: ارائه خدمات | E37: 19 | F37: 0 | G37: =SUM(E37:F37) -> 19 | I37: 19 | J37: 3 | K37: =SUM(I37:J37) -> 22 | M37: 19 | N37: 1 | O37: =SUM(M37:N37) -> 20 | P37: =O37*100/K37 -> 90.909091 | Q37: =O37*100/G37 -> 105.26316
B38: اداری و عمومی | E38: 4 | F38: 0 | G38: =SUM(E38:F38) -> 4 | I38: 4 | J38: 1 | K38: =SUM(I38:J38) -> 5 | M38: 3 | N38: 0 | O38: =SUM(M38:N38) -> 3 | P38: =O38*100/K38 -> 60 | Q38: =O38*100/G38 -> 75
B39: جمع | E39: =SUM(E37:E38) -> 23 | F39: =SUM(F37:F38) -> 0 | G39: =SUM(G37:G38) -> 23 | H39: =SUM(H37:H38) -> 0 | I39: =SUM(I37:I38) -> 23 | J39: =SUM(J37:J38) -> 4 | K39: =SUM(K37:K38) -> 27 | L39: =SUM(L37:L38) -> 0 | ... O39: =SUM(O37:O38) -> 23 | P39: =O39*100/K39 -> 85.185185 | Q39: =O39*100/G39 -> 100

Sheet لطف آباد
B1: شرکت انبارهای عمومی و خدمات گمرکی ایران / شعبه لطف آباد
B3: آمار مقایسه ای عملیاتی - 6 ماهه اول | J3: آمار مقایسه ای عملیاتی - 6 ماهه اول
B4: واردات | C4: عملیات (تن) | D4: تناژ | G4: درصد تحقق | H4: درصد تغییرات به عملکرد | J4: صادرات | K4: عملیات (تن) | L4: تناژ | O4: درصد تحقق | P4: درصد تغییرات به عملکرد
D5: عملکرد 1404 | E5: بودجه 1405 | F5: عملکرد 1405 | G5: بودجه | L5: عملکرد 1404 | M5: بودجه 1405 | N5: عملکرد 1405 | O5: بودجه
C6: تخلیه | D6: 42498 | E6: 39629 | F6: 54954 | G6: =F6/E6*100 -> 138.67118 | K6: تخلیه | L6: 1095 | M6: 1301 | N6: 4305 | O6: =N6/M6*100 -> 330.89931
C7: بارگیری | D7: 40280 | E7: 37961 | F7: 62858 | G7: =F7/E7*100 -> 165.58573 | K7: بارگیری | L7: 996 | M7: 1709 | N7: 4561 | O7: =N7/M7*100 -> 266.88122
C8: حمل یکسره | G8: 0 | K8: حمل یکسره | L8: 0 | M8: 0 | O8: =N8/M8*100 -> #DIV/0!
C9: ترانشیپ | D9: 418170 | E9: 401431 | F9: 489014 | G9: =F9/E9*100 -> 121.8177 | K9: ترانشیپ | L9: 0 | M9: 0 | O9: =N9/M9*100 -> #DIV/0!
B12: آمار مقایسه ای درآمد واردات - 6 ماهه اول | J12: آمار مقایسه ای درآمد صادرات - 6 ماهه اول
B13: درآمد واردات (میلیون ریال) | D13: عملکرد 1404 | E13: بودجه 1405 | F13: عملکرد 1405 | G13: درصد تحقق بودجه | H13: درصد تغییرات به عملکرد | J13: درآمد صادرات (میلیون ریال) | L13: عملکرد 1404 | M13: بودجه 1405 | N13: عملکرد 1405 | O13: درصد تحقق بودجه | P13: درصد تغییرات به عملکرد
B14: انبارداری | D14: 32253 | E14: 57420 | F14: 115432 | G14: =IFERROR(F14*100/E14,"") -> 201.031 | H14: =IFERROR((F14-D14)*100/D14,"") -> 257.89539 | J14: انبارداری | L14: 2301 | M14: 3739 | N14: 8632 | O14: =IFERROR(N14*100/M14,"") -> 230.86387 | P14: =IFERROR((N14-L14)*100/L14,"") -> 275.14124
B15: باربری | D15: 311287 | E15: 385608 | F15: 515378 | G15: =IFERROR(F15*100/E15,"") -> 133.65335 | H15: =IFERROR((F15-D15)*100/D15,"") -> 65.563612 | J15: باربری | L15: 1500 | M15: 3746 | N15: 9746 | O15: =IFERROR(N15*100/M15,"") -> 260.17085 | P15: =IFERROR((N15-L15)*100/L15,"") -> 549.73333
B16: حمل یکسره | G16: =IFERROR(F16*100/E16,"") | H16: =IFERROR((F16-D16)*100/D16,"") | J16: حمل یکسره | P16: =IFERROR((N16-L16)*100/L16,"")
B17: ترانشیپ | D17: 75305 | E17: 107863 | F17: 130124 | G17: =IFERROR(F17*100/E17,"") -> 120.63822 | H17: =IFERROR((F17-D17)*100/D17,"") -> 72.795963 | J17: ترانشیپ | O17: =IFERROR(N17*100/M17,"") | P17: =IFERROR((N17-L17)*100/L17,"")
B18: سایر خدمات باربری | D18: 40661 | E18: 56411 | F18: 59733 | G18: =IFERROR(F18*100/E18,"") -> 105.88892 | H18: =IFERROR((F18-D18)*100/D18,"") -> 46.904897 | J18: سایر خدمات باربری | L18: 119 | M18: 241 | N18: 411 | O18: =IFERROR(N18*100/M18,"") -> 170.53942 | P18: =IFERROR((N18-L18)*100/L18,"") -> 245.37815
B19: بیمه | D19: 17704 | E19: 31685 | F19: 31514 | G19: =IFERROR(F19*100/E19,"") -> 99.460312 | H19: =IFERROR((F19-D19)*100/D19,"") -> 78.004971 | J19: بیمه | L19: 651 | M19: 1695 | N19: 3239 | O19: =IFERROR(N19*100/M19,"") -> 191.09145 | P19: =IFERROR((N19-L19)*100/L19,"") -> 397.54224
B21: سود و زیان مقایسه ای - 6 ماهه اول
B22: شرح (میلیون ریال) | D22: عملکرد 1404 | F22: بودجه 1405 | H22: عملکرد 1405 | J22: درصد تحقق بودجه | K22: درصد تغییرات به عملکرد
B23: درآمد حاصل از ارائه خدمات | D23: 463426 | E23: =SUMIFS('[8]جدول فروش خدمات'!$U$25:$FT$25,'[8]جدول فروش خدمات'!$U$1:$FT$1,J21,'[8]جدول فروش خدمات'!$U$26:$FT$26,1) -> 0 | F23: 615028 | G23: =SUMIFS('[8]جدول فروش خدمات'!$U$25:$FT$25,'[8]جدول فروش خدمات'!$U$1:$FT$1,K21,'[8]جدول فروش خدمات'!$U$26:$FT$26,2) -> 0 | H23: 839456 | I23: =SUMIFS('[8]جدول فروش خدمات'!$U$25:$FT$25,'[8]جدول فروش خدمات'!$U$1:$FT$1,L21,'[8]جدول فروش خدمات'!$U$26:$FT$26,3) -> 0 | J23: =IFERROR(H23*100/F23,"") -> 136.4907 | K23: =IFERROR((H23-D23)*100/ABS(D23),"") -> 81.141326
B24: بهای تمام شده ارائه خدمات | D24: -234961 | E24: -234961 | F24: -382929 | G24: -382929 | H24: -368311 | I24: -368311 | J24: =IFERROR(H24*100/F24,"") -> 96.182582 | K24: =IFERROR((H24-D24)*100/ABS(D24),"") -> -56.7541
B25: سود (زیان) ناخالص | D25: =SUM(D23:D24) -> 228465 | E25: =SUM(E23:E24) -> -234961 | F25: =SUM(F23:F24) -> 232099 | G25: =SUM(G23:G24) -> -382929 | H25: =SUM(H23:H24) -> 471145 | I25: =SUM(I23:I24) -> -368311 | J25: =IFERROR(H25*100/F25,"") -> 202.99312 | K25: =IFERROR((H25-D25)*100/ABS(D25),"") -> 106.22196
B26: هزینه های اداری و عمومی | D26: -10136 | E26: -10136 | F26: -19732 | G26: -19732 | H26: -44738 | I26: -44738 | J26: =IFERROR(H26*100/F26,"") -> 226.72816 | K26: =IFERROR((H26-D26)*100/ABS(D26),"") -> -341.37727
B27: سایر درآمدهای عملیاتی | D27: =179348+18355 -> 197703 | E27: =179348+18355 -> 197703 | F27: 196847 | G27: 196847 | H27: =326274+34754 -> 361028 | I27: =326274+34754 -> 361028 | J27: =IFERROR(H27*100/F27,"") -> 183.40539 | K27: =IFERROR((H27-D27)*100/ABS(D27),"") -> 82.611291
B28: سایر هزینه های عملیاتی | J28: =IFERROR(H28*100/F28,"") | K28: =IFERROR((H28-D28)*100/ABS(D28),"")
B29: سود ( زیان ) عملیاتی | D29: 416032 | F29: 409214 | H29: 787435 | J29: =IFERROR(H29*100/F29,"") -> 192.42621 | K29: =IFERROR((H29-D29)*100/ABS(D29),"") -> 89.2727
B30: هزینه های مالی | J30: =IFERROR(H30*100/F30,"") | K30: =IFERROR((H30-D30)*100/ABS(D30),"")
B31: سایر درآمد (هزینه) غیر عملیاتی | D31: 1 | F31: 1 | J31: =IFERROR(H31*100/F31,"") -> 0 | K31: =IFERROR((H31-D31)*100/ABS(D31),"") -> -100
B32: سود (زیان) خالص (قبل از مالیات) | D32: 416032 | F32: 409215 | H32: 787435 | J32: =IFERROR(H32*100/F32,"") -> 192.42574 | K32: =IFERROR((H32-D32)*100/ABS(D32),"") -> 89.2727
B34: آمار مقایسه ای منابع انسانی - 6 ماهه اول
B35: نیروی انسانی | D35: عملکرد 1404 | H35: بودجه 1405 | L35: عملکرد 1405 | P35: تحقق بودجه (نفر) | Q35: تغییرات به عملکرد (نفر)
D36: رسمی | E36: قراردادی | F36: پیمانی | G36: جمع | H36: رسمی | I36: قراردادی | J36: پیمانی | K36: جمع | L36: رسمی | M36: قراردادی | N36: پیمانی | O36: جمع | P36: جمع | Q36: جمع
B37: ارائه خدمات | E37: 24 | F37: 7 | G37: =SUM(E37:F37) -> 31 | I37: 24 | J37: 39 | K37: =SUM(I37:J37) -> 63 | M37: 23 | N37: 13 | O37: =SUM(M37:N37) -> 36 | P37: =O37*100/K37 -> 57.142857 | Q37: =O37*100/G37 -> 116.12903
B38: اداری و عمومی | E38: 2 | F38: 1 | G38: =SUM(E38:F38) -> 3 | I38: 2 | J38: 2 | K38: =SUM(I38:J38) -> 4 | M38: 3 | N38: 1 | O38: =SUM(M38:N38) -> 4 | P38: =O38*100/K38 -> 100 | Q38: =O38*100/G38 -> 133.33333
B39: جمع | E39: =SUM(E37:E38) -> 26 | F39: =SUM(F37:F38) -> 8 | G39: =SUM(G37:G38) -> 34 | H39: =SUM(H37:H38) -> 0 | I39: =SUM(I37:I38) -> 26 | J39: =SUM(J37:J38) -> 41 | K39: =SUM(K37:K38) -> 67 | L39: =SUM(L37:L38) -> 0 | ... O39: =SUM(O37:O38) -> 40 | P39: =O39*100/K39 -> 59.701493 | Q39: =O39*100/G39 -> 117.64706

Sheet نیشابور
B1: شرکت انبارهای عمومی و خدمات گمرکی ایران / شعبه نیشابور
B3: آمار مقایسه ای عملیاتی - 6 ماهه اول | J3: آمار مقایسه ای عملیاتی - 6 ماهه اول
B4: واردات | C4: عملیات (تن) | D4: تناژ | G4: درصد تحقق | H4: درصد تغییرات به عملکرد | J4: صادرات | K4: عملیات (تن) | L4: تناژ | O4: درصد تحقق | P4: درصد تغییرات به عملکرد
D5: عملکرد 1404 | E5: بودجه 1405 | F5: عملکرد 1405 | G5: بودجه | L5: عملکرد 1404 | M5: بودجه 1405 | N5: عملکرد 1405 | O5: بودجه
C6: تخلیه | D6: 4848 | E6: 3225 | F6: 5114 | G6: =F6/E6*100 -> 158.57364 | K6: تخلیه | O6: =N6/M6*100 -> #DIV/0!
C7: بارگیری | D7: 10826 | E7: 5774 | F7: 6401 | G7: =F7/E7*100 -> 110.85902 | K7: بارگیری | O7: =N7/M7*100 -> #DIV/0!
C8: حمل یکسره | D8: 1 | K8: حمل یکسره | O8: =N8/M8*100 -> #DIV/0!
C9: ترانشیپ | K9: ترانشیپ | O9: =N9/M9*100 -> #DIV/0!
B12: آمار مقایسه ای درآمد واردات - 6 ماهه اول | J12: آمار مقایسه ای درآمد صادرات - 6 ماهه اول
B13: درآمد واردات (میلیون ریال) | D13: عملکرد 1404 | E13: بودجه 1405 | F13: عملکرد 1405 | G13: درصد تحقق بودجه | H13: درصد تغییرات به عملکرد | J13: درآمد صادرات (میلیون ریال) | L13: عملکرد 1404 | M13: بودجه 1405 | N13: عملکرد 1405 | O13: درصد تحقق بودجه | P13: درصد تغییرات به عملکرد
B14: انبارداری | D14: 90223 | E14: 78185 | F14: 147424 | G14: =IFERROR(F14*100/E14,"") -> 188.55791 | H14: =IFERROR((F14-D14)*100/D14,"") -> 63.399577 | J14: انبارداری
B15: باربری | D15: 24587 | E15: 18793 | F15: 21518 | G15: =IFERROR(F15*100/E15,"") -> 114.50008 | H15: =IFERROR((F15-D15)*100/D15,"") -> -12.482206 | J15: باربری
B16: حمل یکسره | G16: =IFERROR(F16*100/E16,"") | H16: =IFERROR((F16-D16)*100/D16,"") | J16: حمل یکسره
B17: ترانشیپ | G17: =IFERROR(F17*100/E17,"") | H17: =IFERROR((F17-D17)*100/D17,"") | J17: ترانشیپ
B18: سایر خدمات باربری | D18: 1149 | E18: 1254 | F18: 1948 | G18: =IFERROR(F18*100/E18,"") -> 155.3429 | H18: =IFERROR((F18-D18)*100/D18,"") -> 69.538729 | J18: سایر خدمات باربری
B19: بیمه | D19: 6556 | E19: 9762 | F19: 24779 | G19: =IFERROR(F19*100/E19,"") -> 253.83118 | H19: =IFERROR((F19-D19)*100/D19,"") -> 277.95912 | J19: بیمه
B21: سود و زیان مقایسه ای - 6 ماهه اول
B22: شرح (میلیون ریال) | D22: عملکرد 1404 | F22: بودجه 1405 | H22: عملکرد 1405 | J22: درصد تحقق بودجه | K22: درصد تغییرات به عملکرد
B23: درآمد حاصل از ارائه خدمات | D23: 115959 | E23: =SUMIFS('[8]جدول فروش خدمات'!$U$25:$FT$25,'[8]جدول فروش خدمات'!$U$1:$FT$1,J21,'[8]جدول فروش خدمات'!$U$26:$FT$26,1) -> 0 | F23: 98232 | G23: =SUMIFS('[8]جدول فروش خدمات'!$U$25:$FT$25,'[8]جدول فروش خدمات'!$U$1:$FT$1,K21,'[8]جدول فروش خدمات'!$U$26:$FT$26,2) -> 0 | H23: 170890 | I23: =SUMIFS('[8]جدول فروش خدمات'!$U$25:$FT$25,'[8]جدول فروش خدمات'!$U$1:$FT$1,L21,'[8]جدول فروش خدمات'!$U$26:$FT$26,3) -> 0 | J23: =IFERROR(H23*100/F23,"") -> 173.96571 | K23: =IFERROR((H23-D23)*100/ABS(D23),"") -> 47.371054
B24: بهای تمام شده ارائه خدمات | D24: -110499 | E24: -110499 | F24: -130913 | G24: -130913 | H24: -150415 | I24: -150415 | J24: =IFERROR(H24*100/F24,"") -> 114.89692 | K24: =IFERROR((H24-D24)*100/ABS(D24),"") -> -36.123404
B25: سود (زیان) ناخالص | D25: =SUM(D23:D24) -> 5460 | E25: =SUM(E23:E24) -> -110499 | F25: =SUM(F23:F24) -> -32681 | G25: =SUM(G23:G24) -> -130913 | H25: =SUM(H23:H24) -> 20475 | I25: =SUM(I23:I24) -> -150415 | J25: =IFERROR(H25*100/F25,"") -> -62.651082 | K25: =IFERROR((H25-D25)*100/ABS(D25),"") -> 275
B26: هزینه های اداری و عمومی | D26: -6 | E26: -6 | F26: -86 | G26: -86 | H26: -16 | I26: -16 | J26: =IFERROR(H26*100/F26,"") -> 18.604651 | K26: =IFERROR((H26-D26)*100/ABS(D26),"") -> -166.66667
B27: سایر درآمدهای عملیاتی | D27: =2102+6557 -> 8659 | E27: =2102+6557 -> 8659 | F27: 11231 | G27: 11231 | H27: =3007+24780 -> 27787 | I27: =3007+24780 -> 27787 | J27: =IFERROR(H27*100/F27,"") -> 247.41341 | K27: =IFERROR((H27-D27)*100/ABS(D27),"") -> 220.90311
B28: سایر هزینه های عملیاتی | J28: =IFERROR(H28*100/F28,"") | K28: =IFERROR((H28-D28)*100/ABS(D28),"")
B29: سود ( زیان ) عملیاتی | D29: 14113 | F29: -21536 | H29: 48246 | J29: =IFERROR(H29*100/F29,"") -> -224.02489 | K29: =IFERROR((H29-D29)*100/ABS(D29),"") -> 241.85503
B30: هزینه های مالی | J30: =IFERROR(H30*100/F30,"") | K30: =IFERROR((H30-D30)*100/ABS(D30),"")
B31: سایر درآمد (هزینه) غیر عملیاتی | J31: =IFERROR(H31*100/F31,"") | K31: =IFERROR((H31-D31)*100/ABS(D31),"")
B32: سود (زیان) خالص (قبل از مالیات) | D32: 14113 | F32: -21536 | H32: 48246 | J32: =IFERROR(H32*100/F32,"") -> -224.02489 | K32: =IFERROR((H32-D32)*100/ABS(D32),"") -> 241.85503
B34: آمار مقایسه ای منابع انسانی - 6 ماهه اول
B35: نیروی انسانی | D35: عملکرد 1404 | H35: بودجه 1405 | L35: عملکرد 1405 | P35: تحقق بودجه (نفر) | Q35: تغییرات به عملکرد (نفر)
D36: رسمی | E36: قراردادی | F36: پیمانی | G36: جمع | H36: رسمی | I36: قراردادی | J36: پیمانی | K36: جمع | L36: رسمی | M36: قراردادی | N36: پیمانی | O36: جمع | P36: جمع | Q36: جمع
B37: ارائه خدمات | E37: 2 | G37: =SUM(E37:F37) -> 2 | I37: 2 | J37: 1 | K37: =SUM(I37:J37) -> 3 | M37: 2 | O37: =SUM(M37:N37) -> 2 | P37: =O37*100/K37 -> 66.666667 | Q37: =O37*100/G37 -> 100
B38: اداری و عمومی | G38: =SUM(E38:F38) -> 0 | K38: =SUM(I38:J38) -> 0 | O38: =SUM(M38:N38) -> 0 | P38: =O38*100/K38 -> #DIV/0! | Q38: =O38*100/G38 -> #DIV/0!
B39: جمع | E39: =SUM(E37:E38) -> 2 | F39: =SUM(F37:F38) -> 0 | G39: =SUM(G37:G38) -> 2 | H39: =SUM(H37:H38) -> 0 | I39: =SUM(I37:I38) -> 2 | J39: =SUM(J37:J38) -> 1 | K39: =SUM(K37:K38) -> 3 | L39: =SUM(L37:L38) -> 0 | ... O39: =SUM(O37:O38) -> 2 | P39: =O39*100/K39 -> 66.666667 | Q39: =O39*100/G39 -> 100

Sheet ماهیرود
B1: شرکت انبارهای عمومی و خدمات گمرکی ایران / شعبه ماهیرود
B3: آمار مقایسه ای عملیاتی - 6 ماهه اول | J3: آمار مقایسه ای عملیاتی - 6 ماهه اول
B4: واردات | C4: عملیات (تن) | D4: تناژ | G4: درصد تحقق | H4: درصد تغییرات به عملکرد | J4: صادرات | K4: عملیات (تن) | L4: تناژ | O4: درصد تحقق | P4: درصد تغییرات به عملکرد
D5: عملکرد 1404 | E5: بودجه 1405 | F5: عملکرد 1405 | G5: بودجه | L5: عملکرد 1404 | M5: بودجه 1405 | N5: عملکرد 1405 | O5: بودجه
C6: تخلیه | D6: 17 | E6: 39 | F6: 1704 | G6: =F6/E6*100 -> 4369.2308 | K6: تخلیه | L6: 1271 | M6: 560 | N6: 547 | O6: =N6/M6*100 -> 97.678571
C7: بارگیری | D7: 20 | E7: 33 | F7: 1952 | G7: =F7/E7*100 -> 5915.1515 | K7: بارگیری | L7: 2086 | M7: 896 | N7: 924 | O7: =N7/M7*100 -> 103.125
C8: حمل یکسره | K8: حمل یکسره | L8: 0 | M8: 0 | N8: 0 | O8: 0
C9: ترانشیپ | K9: ترانشیپ | L9: 0 | M9: 0 | N9: 0 | O9: 0
B12: آمار مقایسه ای درآمد واردات - 6 ماهه اول | J12: آمار مقایسه ای درآمد صادرات - 6 ماهه اول
B13: درآمد واردات (میلیون ریال) | D13: عملکرد 1404 | E13: بودجه 1405 | F13: عملکرد 1405 | G13: درصد تحقق بودجه | H13: درصد تغییرات به عملکرد | J13: درآمد صادرات (میلیون ریال) | L13: عملکرد 1404 | M13: بودجه 1405 | N13: عملکرد 1405 | O13: درصد تحقق بودجه | P13: درصد تغییرات به عملکرد
B14: انبارداری | D14: 309 | E14: 465 | F14: 19113 | G14: =IFERROR(F14*100/E14,"") -> 4110.3226 | H14: =IFERROR((F14-D14)*100/D14,"") -> 6085.4369 | J14: انبارداری | L14: 7671 | M14: 4090 | N14: 3539 | O14: =IFERROR(N14*100/M14,"") -> 86.528117 | P14: =IFERROR((N14-L14)*100/L14,"") -> -53.865207
B15: باربری | D15: 53 | E15: 60 | F15: 2362 | G15: =IFERROR(F15*100/E15,"") -> 3936.6667 | H15: =IFERROR((F15-D15)*100/D15,"") -> 4356.6038 | J15: باربری | L15: 1162 | M15: 722 | N15: 879 | O15: =IFERROR(N15*100/M15,"") -> 121.74515 | P15: =IFERROR((N15-L15)*100/L15,"") -> -24.354561
B16: حمل یکسره | G16: =IFERROR(F16*100/E16,"") | H16: =IFERROR((F16-D16)*100/D16,"") | J16: حمل یکسره | P16: =IFERROR((N16-L16)*100/L16,"")
B17: ترانشیپ | G17: =IFERROR(F17*100/E17,"") | H17: =IFERROR((F17-D17)*100/D17,"") | J17: ترانشیپ | O17: =IFERROR(N17*100/M17,"") | P17: =IFERROR((N17-L17)*100/L17,"")
B18: سایر خدمات باربری | D18: 5 | E18: 4 | F18: 61 | G18: =IFERROR(F18*100/E18,"") -> 1525 | H18: =IFERROR((F18-D18)*100/D18,"") -> 1120 | J18: سایر خدمات باربری | L18: 167 | M18: 103 | N18: 51 | O18: =IFERROR(N18*100/M18,"") -> 49.514563 | P18: =IFERROR((N18-L18)*100/L18,"") -> -69.461078
B19: بیمه | D19: 129 | E19: 163 | F19: 4113 | G19: =IFERROR(F19*100/E19,"") -> 2523.3129 | H19: =IFERROR((F19-D19)*100/D19,"") -> 3088.3721 | J19: بیمه | L19: 431 | M19: 607 | N19: 1291 | O19: =IFERROR(N19*100/M19,"") -> 212.68534 | P19: =IFERROR((N19-L19)*100/L19,"") -> 199.53596
B21: سود و زیان مقایسه ای - 6 ماهه اول
B22: شرح (میلیون ریال) | D22: عملکرد 1404 | F22: بودجه 1405 | H22: عملکرد 1405 | J22: درصد تحقق بودجه | K22: درصد تغییرات به عملکرد
B23: درآمد حاصل از ارائه خدمات | D23: 9367 | E23: =SUMIFS('[8]جدول فروش خدمات'!$U$25:$FT$25,'[8]جدول فروش خدمات'!$U$1:$FT$1,J21,'[8]جدول فروش خدمات'!$U$26:$FT$26,1) -> 0 | F23: 5444 | G23: =SUMIFS('[8]جدول فروش خدمات'!$U$25:$FT$25,'[8]جدول فروش خدمات'!$U$1:$FT$1,K21,'[8]جدول فروش خدمات'!$U$26:$FT$26,2) -> 0 | H23: 26005 | I23: =SUMIFS('[8]جدول فروش خدمات'!$U$25:$FT$25,'[8]جدول فروش خدمات'!$U$1:$FT$1,L21,'[8]جدول فروش خدمات'!$U$26:$FT$26,3) -> 0 | J23: =IFERROR(H23*100/F23,"") -> 477.68185 | K23: =IFERROR((H23-D23)*100/ABS(D23),"") -> 177.62357
B24: بهای تمام شده ارائه خدمات | D24: -51997 | E24: -51997 | F24: -69469 | G24: -69469 | H24: -75572 | I24: -75572 | J24: =IFERROR(H24*100/F24,"") -> 108.78521 | K24: =IFERROR((H24-D24)*100/ABS(D24),"") -> -45.339154
B25: سود (زیان) ناخالص | D25: =SUM(D23:D24) -> -42630 | E25: =SUM(E23:E24) -> -51997 | F25: =SUM(F23:F24) -> -64025 | G25: =SUM(G23:G24) -> -69469 | H25: =SUM(H23:H24) -> -49567 | I25: =SUM(I23:I24) -> -75572 | J25: =IFERROR(H25*100/F25,"") -> 77.418196 | K25: =IFERROR((H25-D25)*100/ABS(D25),"") -> -16.272578
B26: هزینه های اداری و عمومی | D26: -771 | E26: -771 | F26: -636 | G26: -636 | H26: -562 | I26: -562 | J26: =IFERROR(H26*100/F26,"") -> 88.36478 | K26: =IFERROR((H26-D26)*100/ABS(D26),"") -> 27.107652
B27: سایر درآمدهای عملیاتی | D27: =25512+560 -> 26072 | E27: =25512+560 -> 26072 | F27: 20855 | G27: 20855 | H27: =61762+5406 -> 67168 | I27: =61762+5406 -> 67168 | J27: =IFERROR(H27*100/F27,"") -> 322.07145 | K27: =IFERROR((H27-D27)*100/ABS(D27),"") -> 157.62504
B28: سایر هزینه های عملیاتی | J28: =IFERROR(H28*100/F28,"") | K28: =IFERROR((H28-D28)*100/ABS(D28),"")
B29: سود ( زیان ) عملیاتی | D29: -17329 | F29: -43806 | H29: 17039 | J29: =IFERROR(H29*100/F29,"") -> -38.896498 | K29: =IFERROR((H29-D29)*100/ABS(D29),"") -> 198.3265
B30: هزینه های مالی | J30: =IFERROR(H30*100/F30,"") | K30: =IFERROR((H30-D30)*100/ABS(D30),"")
B31: سایر درآمد (هزینه) غیر عملیاتی | J31: =IFERROR(H31*100/F31,"") | K31: =IFERROR((H31-D31)*100/ABS(D31),"")
B32: سود (زیان) خالص (قبل از مالیات) | D32: -17329 | F32: -43806 | H32: 17039 | J32: =IFERROR(H32*100/F32,"") -> -38.896498 | K32: =IFERROR((H32-D32)*100/ABS(D32),"") -> 198.3265
B34: آمار مقایسه ای منابع انسانی - 6 ماهه اول
B35: نیروی انسانی | D35: عملکرد 1404 | H35: بودجه 1405 | L35: عملکرد 1405 | P35: تحقق بودجه (نفر) | Q35: تغییرات به عملکرد (نفر)
D36: رسمی | E36: قراردادی | F36: پیمانی | G36: جمع | H36: رسمی | I36: قراردادی | J36: پیمانی | K36: جمع | L36: رسمی | M36: قراردادی | N36: پیمانی | O36: جمع | P36: جمع | Q36: جمع
B37: ارائه خدمات | E37: 10 | F37: 0 | G37: =SUM(E37:F37) -> 10 | I37: 10 | J37: 4 | K37: =SUM(I37:J37) -> 14 | M37: 9 | N37: 0 | O37: =SUM(M37:N37) -> 9 | P37: =O37*100/K37 -> 64.285714 | Q37: =O37*100/G37 -> 90
B38: اداری و عمومی | E38: 0 | F38: 1 | G38: =SUM(E38:F38) -> 1 | I38: 0 | J38: 2 | K38: =SUM(I38:J38) -> 2 | M38: 0 | N38: 0 | O38: =SUM(M38:N38) -> 0 | P38: =O38*100/K38 -> 0 | Q38: =O38*100/G38 -> 0
B39: جمع | E39: =SUM(E37:E38) -> 10 | F39: =SUM(F37:F38) -> 1 | G39: =SUM(G37:G38) -> 11 | H39: =SUM(H37:H38) -> 0 | I39: =SUM(I37:I38) -> 10 | J39: =SUM(J37:J38) -> 6 | K39: =SUM(K37:K38) -> 16 | L39: =SUM(L37:L38) -> 0 | ... O39: =SUM(O37:O38) -> 9 | P39: =O39*100/K39 -> 56.25 | Q39: =O39*100/G39 -> 81.818182

Sheet دوغارون
B1: شرکت انبارهای عمومی و خدمات گمرکی ایران / شعبه دوغارون
B3: آمار مقایسه ای عملیاتی - 6 ماهه اول | J3: آمار مقایسه ای عملیاتی - 6 ماهه اول
B4: واردات | C4: عملیات (تن) | D4: تناژ | G4: درصد تحقق | H4: درصد تغییرات به عملکرد | J4: صادرات | K4: عملیات (تن) | L4: تناژ | O4: درصد تحقق | P4: درصد تغییرات به عملکرد
D5: عملکرد 1404 | E5: بودجه 1405 | F5: عملکرد 1405 | G5: بودجه | L5: عملکرد 1404 | M5: بودجه 1405 | N5: عملکرد 1405 | O5: بودجه
C6: تخلیه | D6: 23951 | E6: 39141 | F6: 52470 | G6: =F6/E6*100 -> 134.05381 | K6: تخلیه | L6: 402 | M6: 158 | N6: 196 | O6: =N6/M6*100 -> 124.05063
C7: بارگیری | D7: 32693 | E7: 37899 | F7: 51694 | G7: =F7/E7*100 -> 136.39938 | K7: بارگیری | L7: 419 | M7: 205 | N7: 311 | O7: =N7/M7*100 -> 151.70732
C8: حمل یکسره | D8: 50 | F8: 86 | G8: 0 | K8: حمل یکسره | L8: 0 | M8: 0 | N8: 0 | O8: 0
C9: ترانشیپ | D9: 50539 | E9: 72639 | F9: 125131 | G9: =F9/E9*100 -> 172.26421 | K9: ترانشیپ | L9: 0 | M9: 0 | N9: 0 | O9: 0
B12: آمار مقایسه ای درآمد واردات - 6 ماهه اول | J12: آمار مقایسه ای درآمد صادرات - 6 ماهه اول
B13: درآمد واردات (میلیون ریال) | D13: عملکرد 1404 | E13: بودجه 1405 | F13: عملکرد 1405 | G13: درصد تحقق بودجه | H13: درصد تغییرات به عملکرد | J13: درآمد صادرات (میلیون ریال) | L13: عملکرد 1404 | M13: بودجه 1405 | N13: عملکرد 1405 | O13: درصد تحقق بودجه | P13: درصد تغییرات به عملکرد
B14: انبارداری | D14: 89889 | E14: 128943 | F14: 131601 | G14: =IFERROR(F14*100/E14,"") -> 102.06138 | H14: =IFERROR((F14-D14)*100/D14,"") -> 46.403898 | J14: انبارداری | L14: 1577 | M14: 1065 | N14: 1514 | O14: =IFERROR(N14*100/M14,"") -> 142.15962 | P14: =IFERROR((N14-L14)*100/L14,"") -> -3.9949271
B15: باربری | D15: 46190 | E15: 69943 | F15: 163436 | G15: =IFERROR(F15*100/E15,"") -> 233.67027 | H15: =IFERROR((F15-D15)*100/D15,"") -> 253.83416 | J15: باربری | L15: 474 | M15: 330 | N15: 627 | O15: =IFERROR(N15*100/M15,"") -> 190 | P15: =IFERROR((N15-L15)*100/L15,"") -> 32.278481
B16: حمل یکسره | D16: 125 | F16: 128 | G16: =IFERROR(F16*100/E16,"") | H16: =IFERROR((F16-D16)*100/D16,"") -> 2.4 | J16: حمل یکسره | P16: =IFERROR((N16-L16)*100/L16,"")
B17: ترانشیپ | D17: 11655 | E17: 24797 | F17: 24789 | G17: =IFERROR(F17*100/E17,"") -> 99.967738 | H17: =IFERROR((F17-D17)*100/D17,"") -> 112.68983 | J17: ترانشیپ | O17: =IFERROR(N17*100/M17,"") | P17: =IFERROR((N17-L17)*100/L17,"")
B18: سایر خدمات باربری | D18: 9573 | E18: 16803 | F18: 43786 | G18: =IFERROR(F18*100/E18,"") -> 260.58442 | H18: =IFERROR((F18-D18)*100/D18,"") -> 357.39058 | J18: سایر خدمات باربری | L18: 44589 | M18: 32269 | N18: 23201 | O18: =IFERROR(N18*100/M18,"") -> 71.898726 | P18: =IFERROR((N18-L18)*100/L18,"") -> -47.966987
B19: بیمه | D19: 15546 | E19: 34765 | F19: 46034 | G19: =IFERROR(F19*100/E19,"") -> 132.41478 | H19: =IFERROR((F19-D19)*100/D19,"") -> 196.11476 | J19: بیمه | L19: 167 | M19: 155 | N19: 169 | O19: =IFERROR(N19*100/M19,"") -> 109.03226 | P19: =IFERROR((N19-L19)*100/L19,"") -> 1.1976048
B21: سود و زیان مقایسه ای - 6 ماهه اول
B22: شرح (میلیون ریال) | D22: عملکرد 1404 | F22: بودجه 1405 | H22: عملکرد 1405 | J22: درصد تحقق بودجه | K22: درصد تغییرات به عملکرد
B23: درآمد حاصل از ارائه خدمات | D23: 204072 | E23: =SUMIFS('[8]جدول فروش خدمات'!$U$25:$FT$25,'[8]جدول فروش خدمات'!$U$1:$FT$1,J21,'[8]جدول فروش خدمات'!$U$26:$FT$26,1) -> 0 | F23: 274150 | G23: =SUMIFS('[8]جدول فروش خدمات'!$U$25:$FT$25,'[8]جدول فروش خدمات'!$U$1:$FT$1,K21,'[8]جدول فروش خدمات'!$U$26:$FT$26,2) -> 0 | H23: 389082 | I23: =SUMIFS('[8]جدول فروش خدمات'!$U$25:$FT$25,'[8]جدول فروش خدمات'!$U$1:$FT$1,L21,'[8]جدول فروش خدمات'!$U$26:$FT$26,3) -> 0 | J23: =IFERROR(H23*100/F23,"") -> 141.92303 | K23: =IFERROR((H23-D23)*100/ABS(D23),"") -> 90.659179
B24: بهای تمام شده ارائه خدمات | D24: -330519 | E24: -330519 | F24: -553424 | G24: -553424 | H24: -541536 | I24: -541536 | J24: =IFERROR(H24*100/F24,"") -> 97.851918 | K24: =IFERROR((H24-D24)*100/ABS(D24),"") -> -63.844136
B25: سود (زیان) ناخالص | D25: =SUM(D23:D24) -> -126447 | E25: =SUM(E23:E24) -> -330519 | F25: =SUM(F23:F24) -> -279274 | G25: =SUM(G23:G24) -> -553424 | H25: =SUM(H23:H24) -> -152454 | I25: =SUM(I23:I24) -> -541536 | J25: =IFERROR(H25*100/F25,"") -> 54.5894 | K25: =IFERROR((H25-D25)*100/ABS(D25),"") -> -20.56751
B26: هزینه های اداری و عمومی | D26: -23770 | E26: -23770 | F26: -37600 | G26: -37600 | H26: -34913 | I26: -34913 | J26: =IFERROR(H26*100/F26,"") -> 92.853723 | K26: =IFERROR((H26-D26)*100/ABS(D26),"") -> -46.878418
B27: سایر درآمدهای عملیاتی | D27: =216647+15713 -> 232360 | E27: =216647+15713 -> 232360 | F27: 274985 | G27: 274985 | H27: =295274+46204 -> 341478 | I27: =295274+46204 -> 341478 | J27: =IFERROR(H27*100/F27,"") -> 124.18059 | K27: =IFERROR((H27-D27)*100/ABS(D27),"") -> 46.960751
B28: سایر هزینه های عملیاتی | J28: =IFERROR(H28*100/F28,"") | K28: =IFERROR((H28-D28)*100/ABS(D28),"")
B29: سود ( زیان ) عملیاتی | D29: 82143 | F29: =SUM(F25:F28) -> -41889 | G29: =SUM(G25:G28) -> -316039 | H29: 154111 | J29: =IFERROR(H29*100/F29,"") -> -367.90327 | K29: =IFERROR((H29-D29)*100/ABS(D29),"") -> 87.613065
B30: هزینه های مالی | J30: =IFERROR(H30*100/F30,"") | K30: =IFERROR((H30-D30)*100/ABS(D30),"")
B31: سایر درآمد (هزینه) غیر عملیاتی | J31: =IFERROR(H31*100/F31,"") | K31: =IFERROR((H31-D31)*100/ABS(D31),"")
B32: سود (زیان) خالص (قبل از مالیات) | D32: 82143 | F32: =SUM(F28:F31) -> -41889 | G32: =SUM(G28:G31) -> -316039 | H32: 154111 | J32: =IFERROR(H32*100/F32,"") -> -367.90327 | K32: =IFERROR((H32-D32)*100/ABS(D32),"") -> 87.613065
B34: آمار مقایسه ای منابع انسانی - 6 ماهه اول
B35: نیروی انسانی | D35: عملکرد 1404 | H35: بودجه 1405 | L35: عملکرد 1405 | P35: تحقق بودجه (نفر) | Q35: تغییرات به عملکرد (نفر)
D36: رسمی | E36: قراردادی | F36: پیمانی | G36: جمع | H36: رسمی | I36: قراردادی | J36: پیمانی | K36: جمع | L36: رسمی | M36: قراردادی | N36: پیمانی | O36: جمع | P36: جمع | Q36: جمع
B37: ارائه خدمات | E37: 59 | F37: 8 | G37: =SUM(E37:F37) -> 67 | I37: 59 | J37: 24 | K37: =SUM(I37:J37) -> 83 | M37: 57 | N37: 11 | O37: =SUM(M37:N37) -> 68 | P37: =O37*100/K37 -> 81.927711 | Q37: =O37*100/G37 -> 101.49254
B38: اداری و عمومی | E38: 3 | F38: 0 | G38: =SUM(E38:F38) -> 3 | I38: 3 | J38: 0 | K38: =SUM(I38:J38) -> 3 | M38: 3 | N38: 0 | O38: =SUM(M38:N38) -> 3 | P38: =O38*100/K38 -> 100 | Q38: =O38*100/G38 -> 100
B39: جمع | E39: =SUM(E37:E38) -> 62 | F39: =SUM(F37:F38) -> 8 | G39: =SUM(G37:G38) -> 70 | H39: =SUM(H37:H38) -> 0 | I39: =SUM(I37:I38) -> 62 | J39: =SUM(J37:J38) -> 24 | K39: =SUM(K37:K38) -> 86 | L39: =SUM(L37:L38) -> 0 | ... O39: =SUM(O37:O38) -> 71 | P39: =O39*100/K39 -> 82.55814 | Q39: =O39*100/G39 -> 101.42857

Sheet بجنورد
B1: شرکت انبارهای عمومی و خدمات گمرکی ایران / شعبه بجنورد
B3: آمار مقایسه ای عملیاتی - 6 ماهه اول | J3: آمار مقایسه ای عملیاتی - 6 ماهه اول
B4: واردات | C4: عملیات (تن) | D4: تناژ | G4: درصد تحقق | H4: درصد تغییرات به عملکرد | J4: صادرات | K4: عملیات (تن) | L4: تناژ | O4: درصد تحقق | P4: درصد تغییرات به عملکرد
D5: عملکرد 1404 | E5: بودجه 1405 | F5: عملکرد 1405 | G5: بودجه | L5: عملکرد 1404 | M5: بودجه 1405 | N5: عملکرد 1405 | O5: بودجه
C6: تخلیه | D6: 227 | E6: 1286 | F6: 235 | G6: =F6/E6*100 -> 18.273717 | K6: تخلیه | O6: =N6/M6*100 -> #DIV/0!
C7: بارگیری | D7: 373 | E7: 3069 | F7: 96 | G7: =F7/E7*100 -> 3.1280547 | K7: بارگیری | O7: =N7/M7*100 -> #DIV/0!
C8: حمل یکسره | D8: 29 | E8: 58 | F8: 38 | G8: =F8/E8*100 -> 65.517241 | K8: حمل یکسره | O8: =N8/M8*100 -> #DIV/0!
C9: ترانشیپ | G9: 0 | K9: ترانشیپ | O9: =N9/M9*100 -> #DIV/0!
B12: آمار مقایسه ای درآمد واردات - 6 ماهه اول | J12: آمار مقایسه ای درآمد صادرات - 6 ماهه اول
B13: درآمد واردات (میلیون ریال) | D13: عملکرد 1404 | E13: بودجه 1405 | F13: عملکرد 1405 | G13: درصد تحقق بودجه | H13: درصد تغییرات به عملکرد | J13: درآمد صادرات (میلیون ریال) | L13: عملکرد 1404 | M13: بودجه 1405 | N13: عملکرد 1405 | O13: درصد تحقق بودجه | P13: درصد تغییرات به عملکرد
B14: انبارداری | D14: 5089 | E14: 26217 | F14: 195 | G14: =IFERROR(F14*100/E14,"") -> 0.7437922 | H14: =IFERROR((F14-D14)*100/D14,"") -> -96.168206 | J14: انبارداری
B15: باربری | D15: 215 | E15: 1417 | F15: 259 | G15: =IFERROR(F15*100/E15,"") -> 18.278052 | H15: =IFERROR((F15-D15)*100/D15,"") -> 20.465116 | J15: باربری
B16: حمل یکسره | F16: 33 | G16: =IFERROR(F16*100/E16,"") | H16: =IFERROR((F16-D16)*100/D16,"") | J16: حمل یکسره
B17: ترانشیپ | G17: =IFERROR(F17*100/E17,"") | H17: =IFERROR((F17-D17)*100/D17,"") | J17: ترانشیپ
B18: سایر خدمات باربری | D18: 168 | E18: 1334 | F18: 325 | G18: =IFERROR(F18*100/E18,"") -> 24.362819 | H18: =IFERROR((F18-D18)*100/D18,"") -> 93.452381 | J18: سایر خدمات باربری
B19: بیمه | D19: 939 | E19: 1635 | F19: 121 | G19: =IFERROR(F19*100/E19,"") -> 7.4006116 | H19: =IFERROR((F19-D19)*100/D19,"") -> -87.113951 | J19: بیمه
B21: سود و زیان مقایسه ای - 6 ماهه اول
B22: شرح (میلیون ریال) | D22: عملکرد 1404 | F22: بودجه 1405 | H22: عملکرد 1405 | J22: درصد تحقق بودجه | K22: درصد تغییرات به عملکرد
B23: درآمد حاصل از ارائه خدمات | D23: 5472 | E23: =SUMIFS('[8]جدول فروش خدمات'!$U$25:$FT$25,'[8]جدول فروش خدمات'!$U$1:$FT$1,J21,'[8]جدول فروش خدمات'!$U$26:$FT$26,1) -> 0 | F23: 28968 | G23: =SUMIFS('[8]جدول فروش خدمات'!$U$25:$FT$25,'[8]جدول فروش خدمات'!$U$1:$FT$1,K21,'[8]جدول فروش خدمات'!$U$26:$FT$26,2) -> 0 | H23: 812 | I23: =SUMIFS('[8]جدول فروش خدمات'!$U$25:$FT$25,'[8]جدول فروش خدمات'!$U$1:$FT$1,L21,'[8]جدول فروش خدمات'!$U$26:$FT$26,3) -> 0 | J23: =IFERROR(H23*100/F23,"") -> 2.8030931 | K23: =IFERROR((H23-D23)*100/ABS(D23),"") -> -85.160819
B24: بهای تمام شده ارائه خدمات | D24: -14919 | E24: -14919 | F24: -22136 | G24: -22136 | H24: -28389 | I24: -28389 | J24: =IFERROR(H24*100/F24,"") -> 128.2481 | K24: =IFERROR((H24-D24)*100/ABS(D24),"") -> -90.287553
B25: سود (زیان) ناخالص | D25: =SUM(D23:D24) -> -9447 | E25: =SUM(E23:E24) -> -14919 | F25: =SUM(F23:F24) -> 6832 | G25: =SUM(G23:G24) -> -22136 | H25: =SUM(H23:H24) -> -27577 | I25: =SUM(I23:I24) -> -28389 | J25: =IFERROR(H25*100/F25,"") -> -403.64461 | K25: =IFERROR((H25-D25)*100/ABS(D25),"") -> -191.91278
B26: هزینه های اداری و عمومی | D26: -2519 | E26: -2519 | F26: -2927 | G26: -2927 | H26: -29 | I26: -29 | J26: =IFERROR(H26*100/F26,"") -> 0.99077554 | K26: =IFERROR((H26-D26)*100/ABS(D26),"") -> 98.84875
B27: سایر درآمدهای عملیاتی | D27: =18+939 -> 957 | E27: =18+939 -> 957 | F27: 2246 | G27: 2246 | H27: =8+121 -> 129 | I27: =8+121 -> 129 | J27: =IFERROR(H27*100/F27,"") -> 5.7435441 | K27: =IFERROR((H27-D27)*100/ABS(D27),"") -> -86.520376
B28: سایر هزینه های عملیاتی | J28: =IFERROR(H28*100/F28,"") | K28: =IFERROR((H28-D28)*100/ABS(D28),"")
B29: سود ( زیان ) عملیاتی | D29: =SUM(D25:D28) -> -11009 | E29: =SUM(E25:E28) -> -16481 | F29: 6151 | H29: =SUM(H25:H28) -> -27477 | I29: =SUM(I25:I28) -> -28289 | J29: =IFERROR(H29*100/F29,"") -> -446.70785 | K29: =IFERROR((H29-D29)*100/ABS(D29),"") -> -149.5867
B30: هزینه های مالی | J30: =IFERROR(H30*100/F30,"") | K30: =IFERROR((H30-D30)*100/ABS(D30),"")
B31: سایر درآمد (هزینه) غیر عملیاتی | J31: =IFERROR(H31*100/F31,"") | K31: =IFERROR((H31-D31)*100/ABS(D31),"")
B32: سود (زیان) خالص (قبل از مالیات) | D32: =SUM(D28:D31) -> -11009 | E32: =SUM(E28:E31) -> -16481 | F32: 6151 | H32: =SUM(H28:H31) -> -27477 | I32: =SUM(I28:I31) -> -28289 | J32: =IFERROR(H32*100/F32,"") -> -446.70785 | K32: =IFERROR((H32-D32)*100/ABS(D32),"") -> -149.5867
B34: آمار مقایسه ای منابع انسانی - 6 ماهه اول
B35: نیروی انسانی | D35: عملکرد 1404 | H35: بودجه 1405 | L35: عملکرد 1405 | P35: تحقق بودجه (نفر) | Q35: تغییرات به عملکرد (نفر)
D36: رسمی | E36: قراردادی | F36: پیمانی | G36: جمع | H36: رسمی | I36: قراردادی | J36: پیمانی | K36: جمع | L36: رسمی | M36: قراردادی | N36: پیمانی | O36: جمع | P36: جمع | Q36: جمع
B37: ارائه خدمات | E37: 4 | F37: 0 | G37: =SUM(E37:F37) -> 4 | I37: 4 | J37: 0 | K37: =SUM(I37:J37) -> 4 | M37: 4 | N37: 0 | O37: =SUM(M37:N37) -> 4 | P37: =O37*100/K37 -> 100 | Q37: =O37*100/G37 -> 100
B38: اداری و عمومی | E38: 0 | F38: 0 | G38: =SUM(E38:F38) -> 0 | I38: 0 | J38: 0 | K38: =SUM(I38:J38) -> 0 | M38: 0 | N38: 0 | O38: =SUM(M38:N38) -> 0 | P38: =O38*100/K38 -> #DIV/0! | Q38: =O38*100/G38 -> #DIV/0!
B39: جمع | E39: =SUM(E37:E38) -> 4 | F39: =SUM(F37:F38) -> 0 | G39: =SUM(G37:G38) -> 4 | H39: =SUM(H37:H38) -> 0 | I39: =SUM(I37:I38) -> 4 | J39: =SUM(J37:J38) -> 0 | K39: =SUM(K37:K38) -> 4 | L39: =SUM(L37:L38) -> 0 | ... O39: =SUM(O37:O38) -> 4 | P39: =O39*100/K39 -> 100 | Q39: =O39*100/G39 -> 100

Sheet بیرجند
B1: شرکت انبارهای عمومی و خدمات گمرکی ایران / شعبه بیرجند
B3: آمار مقایسه ای عملیاتی - 6 ماهه اول | J3: آمار مقایسه ای عملیاتی - 6 ماهه اول
B4: واردات | C4: عملیات (تن) | D4: تناژ | G4: درصد تحقق | H4: درصد تغییرات به عملکرد | J4: صادرات | K4: عملیات (تن) | L4: تناژ | O4: درصد تحقق | P4: درصد تغییرات به عملکرد
D5: عملکرد 1404 | E5: بودجه 1405 | F5: عملکرد 1405 | G5: بودجه | L5: عملکرد 1404 | M5: بودجه 1405 | N5: عملکرد 1405 | O5: بودجه
