Workbook

Sheet تجمیعی
B2: تجمیعی مجتمع خراسان | J2: فرودگاه هاشمی نژاد
B3: ماه | C3: تخلیه | D3: بارگیری | E3: حمل یکسره | F3: ترانشیپمنت | G3: رسوب | H3: جمع عملیاتی | J3: ماه | K3: تخلیه | L3: بارگیری | M3: حمل یکسره | N3: ترانشیپمنت | O3: رسوب | P3: جمع عملیاتی | S3: رسوب محاسبه شده
B4: فروردین | C4: =IF(SUM(K4,C20,K20,C36,K36,C52,K52,C68,K68,C84)=0,"",SUM(K4,C20,K20,C36,K36,C52,K52,C68,K68,C84,K84)) -> 19240 | D4: =IF(SUM(L4,D20,L20,D36,L36,D52,L52,D68,L68,D84)=0,"",SUM(L4,D20,L20,D36,L36,D52,L52,D68,L68,D84,L84)) -> 22149 | E4: =IF(SUM(M4,E20,M20,E36,M36,E52,M52,E68,M68,E84)=0,"",SUM(M4,E20,M20,E36,M36,E52,M52,E68,M68,E84,M84)) -> 407 | F4: =IF(SUM(N4,F20,N20,F36,N36,F52,N52,F68,N68,F84)=0,"",SUM(N4,F20,N20,F36,N36,F52,N52,F68,N68,F84,N84)) -> 126204 | G4: =IF(SUM(O4,G20,O20,G36,O36,G52,O52,G68,O68,G84)=0,"",SUM(O4,G20,O20,G36,O36,G52,O52,G68,O68,G84,O84)) -> 30660 | H4: =SUM(C4:F4) -> 168000 | J4: فروردین | P4: =SUM(K4:N4) -> 0 | S4: =IF(SUM(G4)=0,"",IFERROR(G4,"")) -> 30660 | T4: =IFERROR(S4-G4,"") -> 0 | U4: =IF(SUM(O4)=0,"",IFERROR(O4,"")) | V4: =IFERROR(U4-O4,"")
B5: اردیبهشت | C5: =IF(SUM(K5,C21,K21,C37,K37,C53,K53,C69,K69,C85)=0,"",SUM(K5,C21,K21,C37,K37,C53,K53,C69,K69,C85,K85)) -> 21048 | D5: =IF(SUM(L5,D21,L21,D37,L37,D53,L53,D69,L69,D85)=0,"",SUM(L5,D21,L21,D37,L37,D53,L53,D69,L69,D85,L85)) -> 22533 | E5: =IF(SUM(M5,E21,M21,E37,M37,E53,M53,E69,M69,E85)=0,"",SUM(M5,E21,M21,E37,M37,E53,M53,E69,M69,E85,M85)) -> 657 | F5: =IF(SUM(N5,F21,N21,F37,N37,F53,N53,F69,N69,F85)=0,"",SUM(N5,F21,N21,F37,N37,F53,N53,F69,N69,F85,N85)) -> 138956 | G5: =IF(SUM(O5,G21,O21,G37,O37,G53,O53,G69,O69,G85)=0,"",SUM(O5,G21,O21,G37,O37,G53,O53,G69,O69,G85,O85)) -> 31020 | H5: =SUM(C5:F5) -> 183194 | J5: اردیبهشت | K5: =IFERROR(IF(SUM(واردات!K5,صادرات!K5)=0,"",SUM(واردات!K5,صادرات!K5)),"") | L5: =IFERROR(IF(SUM(واردات!L5,صادرات!L5)=0,"",SUM(واردات!L5,صادرات!L5)),"") | M5: =IFERROR(IF(SUM(واردات!M5,صادرات!M5)=0,"",SUM(واردات!M5,صادرات!M5)),"") | N5: =IFERROR(IF(SUM(واردات!N5,صادرات!N5)=0,"",SUM(واردات!N5,صادرات!N5)),"") | O5: =IFERROR(IF(SUM(واردات!O5,صادرات!O5)=0,"",SUM(واردات!O5,صادرات!O5)),"") | P5: =SUM(K5:N5) -> 0 | S5: =IF(OR(SUM(C5:G5)=0,SUM(G$4:G5)=0),"",IF(SUM(S$4:S4)=0,G5,IFERROR(SUM(S4,C5,-D5),""))) -> 29175 | T5: =IFERROR(S5-G5,"") -> -1845 | U5: =IF(OR(SUM(K5:O5)=0,SUM(O$4:O5)=0),"",IF(SUM(U$4:U4)=0,O5,IFERROR(SUM(U4,K5,-L5),""))) | V5: =IFERROR(U5-O5,"")
B6: خرداد | C6: =IF(SUM(K6,C22,K22,C38,K38,C54,K54,C70,K70,C86)=0,"",SUM(K6,C22,K22,C38,K38,C54,K54,C70,K70,C86,K86)) -> 20077 | D6: =IF(SUM(L6,D22,L22,D38,L38,D54,L54,D70,L70,D86)=0,"",SUM(L6,D22,L22,D38,L38,D54,L54,D70,L70,D86,L86)) -> 18019 | E6: =IF(SUM(M6,E22,M22,E38,M38,E54,M54,E70,M70,E86)=0,"",SUM(M6,E22,M22,E38,M38,E54,M54,E70,M70,E86,M86)) -> 863 | F6: =IF(SUM(N6,F22,N22,F38,N38,F54,N54,F70,N70,F86)=0,"",SUM(N6,F22,N22,F38,N38,F54,N54,F70,N70,F86,N86)) -> 115856 | G6: =IF(SUM(O6,G22,O22,G38,O38,G54,O54,G70,O70,G86)=0,"",SUM(O6,G22,O22,G38,O38,G54,O54,G70,O70,G86,O86)) -> 31543 | H6: =SUM(C6:F6) -> 154815 | J6: خرداد | K6: =IFERROR(IF(SUM(واردات!K6,صادرات!K6)=0,"",SUM(واردات!K6,صادرات!K6)),"") | L6: =IFERROR(IF(SUM(واردات!L6,صادرات!L6)=0,"",SUM(واردات!L6,صادرات!L6)),"") | M6: =IFERROR(IF(SUM(واردات!M6,صادرات!M6)=0,"",SUM(واردات!M6,صادرات!M6)),"") | N6: =IFERROR(IF(SUM(واردات!N6,صادرات!N6)=0,"",SUM(واردات!N6,صادرات!N6)),"") | O6: =IFERROR(IF(SUM(واردات!O6,صادرات!O6)=0,"",SUM(واردات!O6,صادرات!O6)),"") | P6: =SUM(K6:N6) -> 0 | S6: =IF(OR(SUM(C6:G6)=0,SUM(G$4:G6)=0),"",IF(SUM(S$4:S5)=0,G6,IFERROR(SUM(S5,C6,-D6),""))) -> 31233 | T6: =IFERROR(S6-G6,"") -> -310 | U6: =IF(OR(SUM(K6:O6)=0,SUM(O$4:O6)=0),"",IF(SUM(U$4:U5)=0,O6,IFERROR(SUM(U5,K6,-L6),""))) | V6: =IFERROR(U6-O6,"")
B7: تیر | C7: =IF(SUM(K7,C23,K23,C39,K39,C55,K55,C71,K71,C87)=0,"",SUM(K7,C23,K23,C39,K39,C55,K55,C71,K71,C87,K87)) -> 16347 | D7: =IF(SUM(L7,D23,L23,D39,L39,D55,L55,D71,L71,D87)=0,"",SUM(L7,D23,L23,D39,L39,D55,L55,D71,L71,D87,L87)) -> 23311 | E7: =IF(SUM(M7,E23,M23,E39,M39,E55,M55,E71,M71,E87)=0,"",SUM(M7,E23,M23,E39,M39,E55,M55,E71,M71,E87,M87)) -> 293 | F7: =IF(SUM(N7,F23,N23,F39,N39,F55,N55,F71,N71,F87)=0,"",SUM(N7,F23,N23,F39,N39,F55,N55,F71,N71,F87,N87)) -> 158591 | G7: =IF(SUM(O7,G23,O23,G39,O39,G55,O55,G71,O71,G87)=0,"",SUM(O7,G23,O23,G39,O39,G55,O55,G71,O71,G87,O87)) -> 27054 | H7: =SUM(C7:F7) -> 198542 | J7: تیر | K7: =IFERROR(IF(SUM(واردات!K7,صادرات!K7)=0,"",SUM(واردات!K7,صادرات!K7)),"") | L7: =IFERROR(IF(SUM(واردات!L7,صادرات!L7)=0,"",SUM(واردات!L7,صادرات!L7)),"") | M7: =IFERROR(IF(SUM(واردات!M7,صادرات!M7)=0,"",SUM(واردات!M7,صادرات!M7)),"") | N7: =IFERROR(IF(SUM(واردات!N7,صادرات!N7)=0,"",SUM(واردات!N7,صادرات!N7)),"") | O7: =IFERROR(IF(SUM(واردات!O7,صادرات!O7)=0,"",SUM(واردات!O7,صادرات!O7)),"") | P7: =SUM(K7:N7) -> 0 | S7: =IF(OR(SUM(C7:G7)=0,SUM(G$4:G7)=0),"",IF(SUM(S$4:S6)=0,G7,IFERROR(SUM(S6,C7,-D7),""))) -> 24269 | T7: =IFERROR(S7-G7,"") -> -2785 | U7: =IF(OR(SUM(K7:O7)=0,SUM(O$4:O7)=0),"",IF(SUM(U$4:U6)=0,O7,IFERROR(SUM(U6,K7,-L7),""))) | V7: =IFERROR(U7-O7,"")
B8: مرداد | C8: =IF(SUM(K8,C24,K24,C40,K40,C56,K56,C72,K72,C88)=0,"",SUM(K8,C24,K24,C40,K40,C56,K56,C72,K72,C88,K88)) -> 23531 | D8: =IF(SUM(L8,D24,L24,D40,L40,D56,L56,D72,L72,D88)=0,"",SUM(L8,D24,L24,D40,L40,D56,L56,D72,L72,D88,L88)) -> 30208 | E8: =IF(SUM(M8,E24,M24,E40,M40,E56,M56,E72,M72,E88)=0,"",SUM(M8,E24,M24,E40,M40,E56,M56,E72,M72,E88,M88)) -> 1520 | F8: =IF(SUM(N8,F24,N24,F40,N40,F56,N56,F72,N72,F88)=0,"",SUM(N8,F24,N24,F40,N40,F56,N56,F72,N72,F88,N88)) -> 163307 | G8: =IF(SUM(O8,G24,O24,G40,O40,G56,O56,G72,O72,G88)=0,"",SUM(O8,G24,O24,G40,O40,G56,O56,G72,O72,G88,O88)) -> 21674 | H8: =SUM(C8:F8) -> 218566 | J8: مرداد | K8: =IFERROR(IF(SUM(واردات!K8,صادرات!K8)=0,"",SUM(واردات!K8,صادرات!K8)),"") | L8: =IFERROR(IF(SUM(واردات!L8,صادرات!L8)=0,"",SUM(واردات!L8,صادرات!L8)),"") | M8: =IFERROR(IF(SUM(واردات!M8,صادرات!M8)=0,"",SUM(واردات!M8,صادرات!M8)),"") | N8: =IFERROR(IF(SUM(واردات!N8,صادرات!N8)=0,"",SUM(واردات!N8,صادرات!N8)),"") | O8: =IFERROR(IF(SUM(واردات!O8,صادرات!O8)=0,"",SUM(واردات!O8,صادرات!O8)),"") | P8: =SUM(K8:N8) -> 0 | S8: =IF(OR(SUM(C8:G8)=0,SUM(G$4:G8)=0),"",IF(SUM(S$4:S7)=0,G8,IFERROR(SUM(S7,C8,-D8),""))) -> 17592 | T8: =IFERROR(S8-G8,"") -> -4082 | U8: =IF(OR(SUM(K8:O8)=0,SUM(O$4:O8)=0),"",IF(SUM(U$4:U7)=0,O8,IFERROR(SUM(U7,K8,-L8),""))) | V8: =IFERROR(U8-O8,"")
B9: شهریور | C9: =IF(SUM(K9,C25,K25,C41,K41,C57,K57,C73,K73,C89)=0,"",SUM(K9,C25,K25,C41,K41,C57,K57,C73,K73,C89,K89)) -> 27327 | D9: =IF(SUM(L9,D25,L25,D41,L41,D57,L57,D73,L73,D89)=0,"",SUM(L9,D25,L25,D41,L41,D57,L57,D73,L73,D89,L89)) -> 23858 | E9: =IF(SUM(M9,E25,M25,E41,M41,E57,M57,E73,M73,E89)=0,"",SUM(M9,E25,M25,E41,M41,E57,M57,E73,M73,E89,M89)) -> 180 | F9: =IF(SUM(N9,F25,N25,F41,N41,F57,N57,F73,N73,F89)=0,"",SUM(N9,F25,N25,F41,N41,F57,N57,F73,N73,F89,N89)) -> 174182 | G9: =IF(SUM(O9,G25,O25,G41,O41,G57,O57,G73,O73,G89)=0,"",SUM(O9,G25,O25,G41,O41,G57,O57,G73,O73,G89,O89)) -> 24373 | H9: =SUM(C9:F9) -> 225547 | J9: شهریور | K9: =IFERROR(IF(SUM(واردات!K9,صادرات!K9)=0,"",SUM(واردات!K9,صادرات!K9)),"") | L9: =IFERROR(IF(SUM(واردات!L9,صادرات!L9)=0,"",SUM(واردات!L9,صادرات!L9)),"") | M9: =IFERROR(IF(SUM(واردات!M9,صادرات!M9)=0,"",SUM(واردات!M9,صادرات!M9)),"") | N9: =IFERROR(IF(SUM(واردات!N9,صادرات!N9)=0,"",SUM(واردات!N9,صادرات!N9)),"") | O9: =IFERROR(IF(SUM(واردات!O9,صادرات!O9)=0,"",SUM(واردات!O9,صادرات!O9)),"") | P9: =SUM(K9:N9) -> 0 | S9: =IF(OR(SUM(C9:G9)=0,SUM(G$4:G9)=0),"",IF(SUM(S$4:S8)=0,G9,IFERROR(SUM(S8,C9,-D9),""))) -> 21061 | T9: =IFERROR(S9-G9,"") -> -3312 | U9: =IF(OR(SUM(K9:O9)=0,SUM(O$4:O9)=0),"",IF(SUM(U$4:U8)=0,O9,IFERROR(SUM(U8,K9,-L9),""))) | V9: =IFERROR(U9-O9,"")
B10: مهر | C10: =IF(SUM(K10,C26,K26,C42,K42,C58,K58,C74,K74,C90)=0,"",SUM(K10,C26,K26,C42,K42,C58,K58,C74,K74,C90,K90)) -> 24847 | D10: =IF(SUM(L10,D26,L26,D42,L42,D58,L58,D74,L74,D90)=0,"",SUM(L10,D26,L26,D42,L42,D58,L58,D74,L74,D90,L90)) -> 24761 | E10: =IF(SUM(M10,E26,M26,E42,M42,E58,M58,E74,M74,E90)=0,"",SUM(M10,E26,M26,E42,M42,E58,M58,E74,M74,E90,M90)) | F10: =IF(SUM(N10,F26,N26,F42,N42,F58,N58,F74,N74,F90)=0,"",SUM(N10,F26,N26,F42,N42,F58,N58,F74,N74,F90,N90)) -> 182744 | G10: =IF(SUM(O10,G26,O26,G42,O42,G58,O58,G74,O74,G90)=0,"",SUM(O10,G26,O26,G42,O42,G58,O58,G74,O74,G90,O90)) -> 24529 | H10: =SUM(C10:F10) -> 232352 | J10: مهر | K10: =IFERROR(IF(SUM(واردات!K10,صادرات!K10)=0,"",SUM(واردات!K10,صادرات!K10)),"") | L10: =IFERROR(IF(SUM(واردات!L10,صادرات!L10)=0,"",SUM(واردات!L10,صادرات!L10)),"") | M10: =IFERROR(IF(SUM(واردات!M10,صادرات!M10)=0,"",SUM(واردات!M10,صادرات!M10)),"") | N10: =IFERROR(IF(SUM(واردات!N10,صادرات!N10)=0,"",SUM(واردات!N10,صادرات!N10)),"") | O10: =IFERROR(IF(SUM(واردات!O10,صادرات!O10)=0,"",SUM(واردات!O10,صادرات!O10)),"") | P10: =SUM(K10:N10) -> 0 | S10: =IF(OR(SUM(C10:G10)=0,SUM(G$4:G10)=0),"",IF(SUM(S$4:S9)=0,G10,IFERROR(SUM(S9,C10,-D10),""))) -> 21147 | T10: =IFERROR(S10-G10,"") -> -3382 | U10: =IF(OR(SUM(K10:O10)=0,SUM(O$4:O10)=0),"",IF(SUM(U$4:U9)=0,O10,IFERROR(SUM(U9,K10,-L10),""))) | V10: =IFERROR(U10-O10,"")
B11: آبان | C11: =IF(SUM(K11,C27,K27,C43,K43,C59,K59,C75,K75,C91)=0,"",SUM(K11,C27,K27,C43,K43,C59,K59,C75,K75,C91,K91)) -> 40962 | D11: =IF(SUM(L11,D27,L27,D43,L43,D59,L59,D75,L75,D91)=0,"",SUM(L11,D27,L27,D43,L43,D59,L59,D75,L75,D91,L91)) -> 28144 | E11: =IF(SUM(M11,E27,M27,E43,M43,E59,M59,E75,M75,E91)=0,"",SUM(M11,E27,M27,E43,M43,E59,M59,E75,M75,E91,M91)) | F11: =IF(SUM(N11,F27,N27,F43,N43,F59,N59,F75,N75,F91)=0,"",SUM(N11,F27,N27,F43,N43,F59,N59,F75,N75,F91,N91)) -> 179945 | G11: =IF(SUM(O11,G27,O27,G43,O43,G59,O59,G75,O75,G91)=0,"",SUM(O11,G27,O27,G43,O43,G59,O59,G75,O75,G91,O91)) -> 36606 | H11: =SUM(C11:F11) -> 249051 | J11: آبان | K11: =IFERROR(IF(SUM(واردات!K11,صادرات!K11)=0,"",SUM(واردات!K11,صادرات!K11)),"") | L11: =IFERROR(IF(SUM(واردات!L11,صادرات!L11)=0,"",SUM(واردات!L11,صادرات!L11)),"") | M11: =IFERROR(IF(SUM(واردات!M11,صادرات!M11)=0,"",SUM(واردات!M11,صادرات!M11)),"") | N11: =IFERROR(IF(SUM(واردات!N11,صادرات!N11)=0,"",SUM(واردات!N11,صادرات!N11)),"") | O11: =IFERROR(IF(SUM(واردات!O11,صادرات!O11)=0,"",SUM(واردات!O11,صادرات!O11)),"") | P11: =SUM(K11:N11) -> 0 | S11: =IF(OR(SUM(C11:G11)=0,SUM(G$4:G11)=0),"",IF(SUM(S$4:S10)=0,G11,IFERROR(SUM(S10,C11,-D11),""))) -> 33965 | T11: =IFERROR(S11-G11,"") -> -2641 | U11: =IF(OR(SUM(K11:O11)=0,SUM(O$4:O11)=0),"",IF(SUM(U$4:U10)=0,O11,IFERROR(SUM(U10,K11,-L11),""))) | V11: =IFERROR(U11-O11,"")
B12: آذر | C12: =IF(SUM(K12,C28,K28,C44,K44,C60,K60,C76,K76,C92)=0,"",SUM(K12,C28,K28,C44,K44,C60,K60,C76,K76,C92,K92)) -> 31087 | D12: =IF(SUM(L12,D28,L28,D44,L44,D60,L60,D76,L76,D92)=0,"",SUM(L12,D28,L28,D44,L44,D60,L60,D76,L76,D92,L92)) -> 28457 | E12: =IF(SUM(M12,E28,M28,E44,M44,E60,M60,E76,M76,E92)=0,"",SUM(M12,E28,M28,E44,M44,E60,M60,E76,M76,E92,M92)) -> 4 | F12: =IF(SUM(N12,F28,N28,F44,N44,F60,N60,F76,N76,F92)=0,"",SUM(N12,F28,N28,F44,N44,F60,N60,F76,N76,F92,N92)) -> 167136 | G12: =IF(SUM(O12,G28,O28,G44,O44,G60,O60,G76,O76,G92)=0,"",SUM(O12,G28,O28,G44,O44,G60,O60,G76,O76,G92,O92)) -> 38854 | H12: =SUM(C12:F12) -> 226684 | J12: آذر | K12: =IFERROR(IF(SUM(واردات!K12,صادرات!K12)=0,"",SUM(واردات!K12,صادرات!K12)),"") | L12: =IFERROR(IF(SUM(واردات!L12,صادرات!L12)=0,"",SUM(واردات!L12,صادرات!L12)),"") | M12: =IFERROR(IF(SUM(واردات!M12,صادرات!M12)=0,"",SUM(واردات!M12,صادرات!M12)),"") | N12: =IFERROR(IF(SUM(واردات!N12,صادرات!N12)=0,"",SUM(واردات!N12,صادرات!N12)),"") | O12: =IFERROR(IF(SUM(واردات!O12,صادرات!O12)=0,"",SUM(واردات!O12,صادرات!O12)),"") | P12: =SUM(K12:N12) -> 0 | S12: =IF(OR(SUM(C12:G12)=0,SUM(G$4:G12)=0),"",IF(SUM(S$4:S11)=0,G12,IFERROR(SUM(S11,C12,-D12),""))) -> 36595 | T12: =IFERROR(S12-G12,"") -> -2259 | U12: =IF(OR(SUM(K12:O12)=0,SUM(O$4:O12)=0),"",IF(SUM(U$4:U11)=0,O12,IFERROR(SUM(U11,K12,-L12),""))) | V12: =IFERROR(U12-O12,"")
B13: دی | C13: =IF(SUM(K13,C29,K29,C45,K45,C61,K61,C77,K77,C93)=0,"",SUM(K13,C29,K29,C45,K45,C61,K61,C77,K77,C93,K93)) -> 20475 | D13: =IF(SUM(L13,D29,L29,D45,L45,D61,L61,D77,L77,D93)=0,"",SUM(L13,D29,L29,D45,L45,D61,L61,D77,L77,D93,L93)) -> 29848 | E13: =IF(SUM(M13,E29,M29,E45,M45,E61,M61,E77,M77,E93)=0,"",SUM(M13,E29,M29,E45,M45,E61,M61,E77,M77,E93,M93)) -> 20 | F13: =IF(SUM(N13,F29,N29,F45,N45,F61,N61,F77,N77,F93)=0,"",SUM(N13,F29,N29,F45,N45,F61,N61,F77,N77,F93,N93)) -> 152328 | G13: =IF(SUM(O13,G29,O29,G45,O45,G61,O61,G77,O77,G93)=0,"",SUM(O13,G29,O29,G45,O45,G61,O61,G77,O77,G93,O93)) -> 30796 | H13: =SUM(C13:F13) -> 202671 | J13: دی | K13: =IFERROR(IF(SUM(واردات!K13,صادرات!K13)=0,"",SUM(واردات!K13,صادرات!K13)),"") | L13: =IFERROR(IF(SUM(واردات!L13,صادرات!L13)=0,"",SUM(واردات!L13,صادرات!L13)),"") | M13: =IFERROR(IF(SUM(واردات!M13,صادرات!M13)=0,"",SUM(واردات!M13,صادرات!M13)),"") | N13: =IFERROR(IF(SUM(واردات!N13,صادرات!N13)=0,"",SUM(واردات!N13,صادرات!N13)),"") | O13: =IFERROR(IF(SUM(واردات!O13,صادرات!O13)=0,"",SUM(واردات!O13,صادرات!O13)),"") | P13: =SUM(K13:N13) -> 0 | S13: =IF(OR(SUM(C13:G13)=0,SUM(G$4:G13)=0),"",IF(SUM(S$4:S12)=0,G13,IFERROR(SUM(S12,C13,-D13),""))) -> 27222 | T13: =IFERROR(S13-G13,"") -> -3574 | U13: =IF(OR(SUM(K13:O13)=0,SUM(O$4:O13)=0),"",IF(SUM(U$4:U12)=0,O13,IFERROR(SUM(U12,K13,-L13),""))) | V13: =IFERROR(U13-O13,"")
B14: بهمن | C14: =IF(SUM(K14,C30,K30,C46,K46,C62,K62,C78,K78,C94)=0,"",SUM(K14,C30,K30,C46,K46,C62,K62,C78,K78,C94,K94)) -> 26021.758 | D14: =IF(SUM(L14,D30,L30,D46,L46,D62,L62,D78,L78,D94)=0,"",SUM(L14,D30,L30,D46,L46,D62,L62,D78,L78,D94,L94)) -> 29296.137 | E14: =IF(SUM(M14,E30,M30,E46,M46,E62,M62,E78,M78,E94)=0,"",SUM(M14,E30,M30,E46,M46,E62,M62,E78,M78,E94,M94)) | F14: =IF(SUM(N14,F30,N30,F46,N46,F62,N62,F78,N78,F94)=0,"",SUM(N14,F30,N30,F46,N46,F62,N62,F78,N78,F94,N94)) -> 186756 | G14: =IF(SUM(O14,G30,O30,G46,O46,G62,O62,G78,O78,G94)=0,"",SUM(O14,G30,O30,G46,O46,G62,O62,G78,O78,G94,O94)) -> 30204.621 | H14: =SUM(C14:F14) -> 242073.9 | J14: بهمن | K14: =IFERROR(IF(SUM(واردات!K14,صادرات!K14)=0,"",SUM(واردات!K14,صادرات!K14)),"") | L14: =IFERROR(IF(SUM(واردات!L14,صادرات!L14)=0,"",SUM(واردات!L14,صادرات!L14)),"") | M14: =IFERROR(IF(SUM(واردات!M14,صادرات!M14)=0,"",SUM(واردات!M14,صادرات!M14)),"") | N14: =IFERROR(IF(SUM(واردات!N14,صادرات!N14)=0,"",SUM(واردات!N14,صادرات!N14)),"") | O14: =IFERROR(IF(SUM(واردات!O14,صادرات!O14)=0,"",SUM(واردات!O14,صادرات!O14)),"") | P14: =SUM(K14:N14) -> 0 | S14: =IF(OR(SUM(C14:G14)=0,SUM(G$4:G14)=0),"",IF(SUM(S$4:S13)=0,G14,IFERROR(SUM(S13,C14,-D14),""))) -> 23947.621 | T14: =IFERROR(S14-G14,"") -> -6257 | U14: =IF(OR(SUM(K14:O14)=0,SUM(O$4:O14)=0),"",IF(SUM(U$4:U13)=0,O14,IFERROR(SUM(U13,K14,-L14),""))) | V14: =IFERROR(U14-O14,"")
B15: اسفند | C15: =IF(SUM(K15,C31,K31,C47,K47,C63,K63,C79,K79,C95)=0,"",SUM(K15,C31,K31,C47,K47,C63,K63,C79,K79,C95,K95)) -> 26757 | D15: =IF(SUM(L15,D31,L31,D47,L47,D63,L63,D79,L79,D95)=0,"",SUM(L15,D31,L31,D47,L47,D63,L63,D79,L79,D95,L95)) -> 26932 | E15: =IF(SUM(M15,E31,M31,E47,M47,E63,M63,E79,M79,E95)=0,"",SUM(M15,E31,M31,E47,M47,E63,M63,E79,M79,E95,M95)) | F15: =IF(SUM(N15,F31,N31,F47,N47,F63,N63,F79,N79,F95)=0,"",SUM(N15,F31,N31,F47,N47,F63,N63,F79,N79,F95,N95)) -> 174665 | G15: =IF(SUM(O15,G31,O31,G47,O47,G63,O63,G79,O79,G95)=0,"",SUM(O15,G31,O31,G47,O47,G63,O63,G79,O79,G95,O95)) -> 26366 | H15: =SUM(C15:F15) -> 228354 | J15: اسفند | K15: =IFERROR(IF(SUM(واردات!K15,صادرات!K15)=0,"",SUM(واردات!K15,صادرات!K15)),"") | L15: =IFERROR(IF(SUM(واردات!L15,صادرات!L15)=0,"",SUM(واردات!L15,صادرات!L15)),"") | M15: =IFERROR(IF(SUM(واردات!M15,صادرات!M15)=0,"",SUM(واردات!M15,صادرات!M15)),"") | N15: =IFERROR(IF(SUM(واردات!N15,صادرات!N15)=0,"",SUM(واردات!N15,صادرات!N15)),"") | O15: =IFERROR(IF(SUM(واردات!O15,صادرات!O15)=0,"",SUM(واردات!O15,صادرات!O15)),"") | P15: =SUM(K15:N15) -> 0 | S15: =IF(OR(SUM(C15:G15)=0,SUM(G$4:G15)=0),"",IF(SUM(S$4:S14)=0,G15,IFERROR(SUM(S14,C15,-D15),""))) -> 23772.621 | T15: =IFERROR(S15-G15,"") -> -2593.379 | U15: =IF(OR(SUM(K15:O15)=0,SUM(O$4:O15)=0),"",IF(SUM(U$4:U14)=0,O15,IFERROR(SUM(U14,K15,-L15),""))) | V15: =IFERROR(U15-O15,"")
B16: جمع | C16: =SUM(C4:C15) -> 297719.76 | D16: =SUM(D4:D15) -> 307516.14 | E16: =SUM(E4:E15) -> 3944 | F16: =SUM(F4:F15) -> 1920670 | G16: =IF(G15<>"",G15,IF(G14<>"",G14,IF(G13<>"",G13,IF(G12<>"",G12,IF(G11<>"",G11,IF(G10<>"",G10,IF(G9<>"",G9,IF(G8<>"",G8,IF(G7<>"",G7,IF(G6<>"",G6,IF(G5<>"",G5,IF(G4<>"",G4,"")))))))))))) -> 26366 | H16: =SUM(C16:F16) -> 2529849.9 | J16: جمع | K16: =SUM(K4:K15) -> 0 | L16: =SUM(L4:L15) -> 0 | M16: =SUM(M4:M15) -> 0 | N16: =SUM(N4:N15) -> 0 | O16: =IF(O15<>"",O15,IF(O14<>"",O14,IF(O13<>"",O13,IF(O12<>"",O12,IF(O11<>"",O11,IF(O10<>"",O10,IF(O9<>"",O9,IF(O8<>"",O8,IF(O7<>"",O7,IF(O6<>"",O6,IF(O5<>"",O5,IF(O4<>"",O4,"")))))))))))) | P16: =SUM(K16:N16) -> 0
B18: شهید کاوه | J18: مطهری
B19: ماه | C19: تخلیه | D19: بارگیری | E19: حمل یکسره | F19: ترانشیپمنت | G19: رسوب | H19: جمع عملیاتی | J19: ماه | K19: تخلیه | L19: بارگیری | M19: حمل یکسره | N19: ترانشیپمنت | O19: رسوب | P19: جمع عملیاتی
B20: فروردین | C20: =IFERROR(IF(SUM(واردات!C20,صادرات!C20)=0,"",SUM(واردات!C20,صادرات!C20)),"") -> 1297 | D20: =IFERROR(IF(SUM(واردات!D20,صادرات!D20)=0,"",SUM(واردات!D20,صادرات!D20)),"") -> 1101 | E20: =IFERROR(IF(SUM(واردات!E20,صادرات!E20)=0,"",SUM(واردات!E20,صادرات!E20)),"") -> 407 | F20: =IFERROR(IF(SUM(واردات!F20,صادرات!F20)=0,"",SUM(واردات!F20,صادرات!F20)),"") | G20: =IFERROR(IF(SUM(واردات!G20,صادرات!G20)=0,"",SUM(واردات!G20,صادرات!G20)),"") -> 3019 | H20: =SUM(C20:F20) -> 2805 | J20: فروردین | K20: =IFERROR(IF(SUM(واردات!K20,صادرات!K20)=0,"",SUM(واردات!K20,صادرات!K20)),"") -> 3435 | L20: =IFERROR(IF(SUM(واردات!L20,صادرات!L20)=0,"",SUM(واردات!L20,صادرات!L20)),"") -> 4224 | M20: =IFERROR(IF(SUM(واردات!M20,صادرات!M20)=0,"",SUM(واردات!M20,صادرات!M20)),"") | N20: =IFERROR(IF(SUM(واردات!N20,صادرات!N20)=0,"",SUM(واردات!N20,صادرات!N20)),"") -> 34498 | O20: =IFERROR(IF(SUM(واردات!O20,صادرات!O20)=0,"",SUM(واردات!O20,صادرات!O20)),"") -> 6494 | P20: =SUM(K20:N20) -> 42157 | S20: =IF(SUM(G20)=0,"",IFERROR(G20,"")) -> 3019 | T20: =IFERROR(S20-G20,"") -> 0 | U20: =IF(SUM(O20)=0,"",IFERROR(O20,"")) -> 6494 | V20: =IFERROR(U20-O20,"") -> 0
B21: اردیبهشت | C21: =IFERROR(IF(SUM(واردات!C21,صادرات!C21)=0,"",SUM(واردات!C21,صادرات!C21)),"") -> 2608 | D21: =IFERROR(IF(SUM(واردات!D21,صادرات!D21)=0,"",SUM(واردات!D21,صادرات!D21)),"") -> 1650 | E21: =IFERROR(IF(SUM(واردات!E21,صادرات!E21)=0,"",SUM(واردات!E21,صادرات!E21)),"") -> 578 | F21: =IFERROR(IF(SUM(واردات!F21,صادرات!F21)=0,"",SUM(واردات!F21,صادرات!F21)),"") | G21: =IFERROR(IF(SUM(واردات!G21,صادرات!G21)=0,"",SUM(واردات!G21,صادرات!G21)),"") -> 4165 | H21: =SUM(C21:F21) -> 4836 | J21: اردیبهشت | K21: =IFERROR(IF(SUM(واردات!K21,صادرات!K21)=0,"",SUM(واردات!K21,صادرات!K21)),"") -> 3480 | L21: =IFERROR(IF(SUM(واردات!L21,صادرات!L21)=0,"",SUM(واردات!L21,صادرات!L21)),"") -> 4724 | M21: =IFERROR(IF(SUM(واردات!M21,صادرات!M21)=0,"",SUM(واردات!M21,صادرات!M21)),"") | N21: =IFERROR(IF(SUM(واردات!N21,صادرات!N21)=0,"",SUM(واردات!N21,صادرات!N21)),"") -> 50468 | O21: =IFERROR(IF(SUM(واردات!O21,صادرات!O21)=0,"",SUM(واردات!O21,صادرات!O21)),"") -> 5103 | P21: =SUM(K21:N21) -> 58672 | S21: =IF(OR(SUM(C21:G21)=0,SUM(G$20:G21)=0),"",IF(SUM(S$20:S20)=0,G21,IFERROR(SUM(S20,C21,-D21),""))) -> 3977 | T21: =IFERROR(S21-G21,"") -> -188 | U21: =IF(OR(SUM(K21:O21)=0,SUM(O$20:O21)=0),"",IF(SUM(U$20:U20)=0,O21,IFERROR(SUM(U20,K21,-L21),""))) -> 5250 | V21: =IFERROR(U21-O21,"") -> 147
B22: خرداد | C22: =IFERROR(IF(SUM(واردات!C22,صادرات!C22)=0,"",SUM(واردات!C22,صادرات!C22)),"") -> 1558 | D22: =IFERROR(IF(SUM(واردات!D22,صادرات!D22)=0,"",SUM(واردات!D22,صادرات!D22)),"") -> 2007 | E22: =IFERROR(IF(SUM(واردات!E22,صادرات!E22)=0,"",SUM(واردات!E22,صادرات!E22)),"") -> 863 | F22: =IFERROR(IF(SUM(واردات!F22,صادرات!F22)=0,"",SUM(واردات!F22,صادرات!F22)),"") | G22: =IFERROR(IF(SUM(واردات!G22,صادرات!G22)=0,"",SUM(واردات!G22,صادرات!G22)),"") -> 3669 | H22: =SUM(C22:F22) -> 4428 | J22: خرداد | K22: =IFERROR(IF(SUM(واردات!K22,صادرات!K22)=0,"",SUM(واردات!K22,صادرات!K22)),"") -> 4745 | L22: =IFERROR(IF(SUM(واردات!L22,صادرات!L22)=0,"",SUM(واردات!L22,صادرات!L22)),"") -> 3614 | M22: =IFERROR(IF(SUM(واردات!M22,صادرات!M22)=0,"",SUM(واردات!M22,صادرات!M22)),"") | N22: =IFERROR(IF(SUM(واردات!N22,صادرات!N22)=0,"",SUM(واردات!N22,صادرات!N22)),"") -> 42125 | O22: =IFERROR(IF(SUM(واردات!O22,صادرات!O22)=0,"",SUM(واردات!O22,صادرات!O22)),"") -> 4826 | P22: =SUM(K22:N22) -> 50484 | S22: =IF(OR(SUM(C22:G22)=0,SUM(G$20:G22)=0),"",IF(SUM(S$20:S21)=0,G22,IFERROR(SUM(S21,C22,-D22),""))) -> 3528 | T22: =IFERROR(S22-G22,"") -> -141 | U22: =IF(OR(SUM(K22:O22)=0,SUM(O$20:O22)=0),"",IF(SUM(U$20:U21)=0,O22,IFERROR(SUM(U21,K22,-L22),""))) -> 6381 | V22: =IFERROR(U22-O22,"") -> 1555
B23: تیر | C23: =IFERROR(IF(SUM(واردات!C23,صادرات!C23)=0,"",SUM(واردات!C23,صادرات!C23)),"") -> 1861 | D23: =IFERROR(IF(SUM(واردات!D23,صادرات!D23)=0,"",SUM(واردات!D23,صادرات!D23)),"") -> 2131 | E23: =IFERROR(IF(SUM(واردات!E23,صادرات!E23)=0,"",SUM(واردات!E23,صادرات!E23)),"") -> 293 | F23: =IFERROR(IF(SUM(واردات!F23,صادرات!F23)=0,"",SUM(واردات!F23,صادرات!F23)),"") | G23: =IFERROR(IF(SUM(واردات!G23,صادرات!G23)=0,"",SUM(واردات!G23,صادرات!G23)),"") -> 3537 | H23: =SUM(C23:F23) -> 4285 | J23: تیر | K23: =IFERROR(IF(SUM(واردات!K23,صادرات!K23)=0,"",SUM(واردات!K23,صادرات!K23)),"") -> 2796 | L23: =IFERROR(IF(SUM(واردات!L23,صادرات!L23)=0,"",SUM(واردات!L23,صادرات!L23)),"") -> 4653 | M23: =IFERROR(IF(SUM(واردات!M23,صادرات!M23)=0,"",SUM(واردات!M23,صادرات!M23)),"") | N23: =IFERROR(IF(SUM(واردات!N23,صادرات!N23)=0,"",SUM(واردات!N23,صادرات!N23)),"") -> 80132 | O23: =IFERROR(IF(SUM(واردات!O23,صادرات!O23)=0,"",SUM(واردات!O23,صادرات!O23)),"") -> 4283 | P23: =SUM(K23:N23) -> 87581 | S23: =IF(OR(SUM(C23:G23)=0,SUM(G$20:G23)=0),"",IF(SUM(S$20:S22)=0,G23,IFERROR(SUM(S22,C23,-D23),""))) -> 3258 | T23: =IFERROR(S23-G23,"") -> -279 | U23: =IF(OR(SUM(K23:O23)=0,SUM(O$20:O23)=0),"",IF(SUM(U$20:U22)=0,O23,IFERROR(SUM(U22,K23,-L23),""))) -> 4524 | V23: =IFERROR(U23-O23,"") -> 241
B24: مرداد | C24: =IFERROR(IF(SUM(واردات!C24,صادرات!C24)=0,"",SUM(واردات!C24,صادرات!C24)),"") -> 1873 | D24: =IFERROR(IF(SUM(واردات!D24,صادرات!D24)=0,"",SUM(واردات!D24,صادرات!D24)),"") -> 2661 | E24: =IFERROR(IF(SUM(واردات!E24,صادرات!E24)=0,"",SUM(واردات!E24,صادرات!E24)),"") -> 1519 | F24: =IFERROR(IF(SUM(واردات!F24,صادرات!F24)=0,"",SUM(واردات!F24,صادرات!F24)),"") | G24: =IFERROR(IF(SUM(واردات!G24,صادرات!G24)=0,"",SUM(واردات!G24,صادرات!G24)),"") -> 2772 | H24: =SUM(C24:F24) -> 6053 | J24: مرداد | K24: =IFERROR(IF(SUM(واردات!K24,صادرات!K24)=0,"",SUM(واردات!K24,صادرات!K24)),"") -> 4913 | L24: =IFERROR(IF(SUM(واردات!L24,صادرات!L24)=0,"",SUM(واردات!L24,صادرات!L24)),"") -> 4653 | M24: =IFERROR(IF(SUM(واردات!M24,صادرات!M24)=0,"",SUM(واردات!M24,صادرات!M24)),"") | N24: =IFERROR(IF(SUM(واردات!N24,صادرات!N24)=0,"",SUM(واردات!N24,صادرات!N24)),"") -> 72070 | O24: =IFERROR(IF(SUM(واردات!O24,صادرات!O24)=0,"",SUM(واردات!O24,صادرات!O24)),"") -> 4550 | P24: =SUM(K24:N24) -> 81636 | S24: =IF(OR(SUM(C24:G24)=0,SUM(G$20:G24)=0),"",IF(SUM(S$20:S23)=0,G24,IFERROR(SUM(S23,C24,-D24),""))) -> 2470 | T24: =IFERROR(S24-G24,"") -> -302 | U24: =IF(OR(SUM(K24:O24)=0,SUM(O$20:O24)=0),"",IF(SUM(U$20:U23)=0,O24,IFERROR(SUM(U23,K24,-L24),""))) -> 4784 | V24: =IFERROR(U24-O24,"") -> 234
B25: شهریور | C25: =IFERROR(IF(SUM(واردات!C25,صادرات!C25)=0,"",SUM(واردات!C25,صادرات!C25)),"") -> 1300 | D25: =IFERROR(IF(SUM(واردات!D25,صادرات!D25)=0,"",SUM(واردات!D25,صادرات!D25)),"") -> 1594 | E25: =IFERROR(IF(SUM(واردات!E25,صادرات!E25)=0,"",SUM(واردات!E25,صادرات!E25)),"") -> 180 | F25: =IFERROR(IF(SUM(واردات!F25,صادرات!F25)=0,"",SUM(واردات!F25,صادرات!F25)),"") | G25: =IFERROR(IF(SUM(واردات!G25,صادرات!G25)=0,"",SUM(واردات!G25,صادرات!G25)),"") -> 2671 | H25: =SUM(C25:F25) -> 3074 | J25: شهریور | K25: =IFERROR(IF(SUM(واردات!K25,صادرات!K25)=0,"",SUM(واردات!K25,صادرات!K25)),"") -> 8812 | L25: =IFERROR(IF(SUM(واردات!L25,صادرات!L25)=0,"",SUM(واردات!L25,صادرات!L25)),"") -> 5719 | M25: =IFERROR(IF(SUM(واردات!M25,صادرات!M25)=0,"",SUM(واردات!M25,صادرات!M25)),"") | N25: =IFERROR(IF(SUM(واردات!N25,صادرات!N25)=0,"",SUM(واردات!N25,صادرات!N25)),"") -> 72358 | O25: =IFERROR(IF(SUM(واردات!O25,صادرات!O25)=0,"",SUM(واردات!O25,صادرات!O25)),"") -> 7528 | P25: =SUM(K25:N25) -> 86889 | S25: =IF(OR(SUM(C25:G25)=0,SUM(G$20:G25)=0),"",IF(SUM(S$20:S24)=0,G25,IFERROR(SUM(S24,C25,-D25),""))) -> 2176 | T25: =IFERROR(S25-G25,"") -> -495 | U25: =IF(OR(SUM(K25:O25)=0,SUM(O$20:O25)=0),"",IF(SUM(U$20:U24)=0,O25,IFERROR(SUM(U24,K25,-L25),""))) -> 7877 | V25: =IFERROR(U25-O25,"") -> 349
B26: مهر | C26: =IFERROR(IF(SUM(واردات!C26,صادرات!C26)=0,"",SUM(واردات!C26,صادرات!C26)),"") -> 1603 | D26: =IFERROR(IF(SUM(واردات!D26,صادرات!D26)=0,"",SUM(واردات!D26,صادرات!D26)),"") -> 1763 | E26: =IFERROR(IF(SUM(واردات!E26,صادرات!E26)=0,"",SUM(واردات!E26,صادرات!E26)),"") | F26: =IFERROR(IF(SUM(واردات!F26,صادرات!F26)=0,"",SUM(واردات!F26,صادرات!F26)),"") | G26: =IFERROR(IF(SUM(واردات!G26,صادرات!G26)=0,"",SUM(واردات!G26,صادرات!G26)),"") -> 2529 | H26: =SUM(C26:F26) -> 3366 | J26: مهر | K26: =IFERROR(IF(SUM(واردات!K26,صادرات!K26)=0,"",SUM(واردات!K26,صادرات!K26)),"") -> 5049 | L26: =IFERROR(IF(SUM(واردات!L26,صادرات!L26)=0,"",SUM(واردات!L26,صادرات!L26)),"") -> 6537 | M26: =IFERROR(IF(SUM(واردات!M26,صادرات!M26)=0,"",SUM(واردات!M26,صادرات!M26)),"") | N26: =IFERROR(IF(SUM(واردات!N26,صادرات!N26)=0,"",SUM(واردات!N26,صادرات!N26)),"") -> 73749 | O26: =IFERROR(IF(SUM(واردات!O26,صادرات!O26)=0,"",SUM(واردات!O26,صادرات!O26)),"") -> 6153 | P26: =SUM(K26:N26) -> 85335 | S26: =IF(OR(SUM(C26:G26)=0,SUM(G$20:G26)=0),"",IF(SUM(S$20:S25)=0,G26,IFERROR(SUM(S25,C26,-D26),""))) -> 2016 | T26: =IFERROR(S26-G26,"") -> -513 | U26: =IF(OR(SUM(K26:O26)=0,SUM(O$20:O26)=0),"",IF(SUM(U$20:U25)=0,O26,IFERROR(SUM(U25,K26,-L26),""))) -> 6389 | V26: =IFERROR(U26-O26,"") -> 236
B27: آبان | C27: =IFERROR(IF(SUM(واردات!C27,صادرات!C27)=0,"",SUM(واردات!C27,صادرات!C27)),"") -> 1252 | D27: =IFERROR(IF(SUM(واردات!D27,صادرات!D27)=0,"",SUM(واردات!D27,صادرات!D27)),"") -> 1578 | E27: =IFERROR(IF(SUM(واردات!E27,صادرات!E27)=0,"",SUM(واردات!E27,صادرات!E27)),"") | F27: =IFERROR(IF(SUM(واردات!F27,صادرات!F27)=0,"",SUM(واردات!F27,صادرات!F27)),"") | G27: =IFERROR(IF(SUM(واردات!G27,صادرات!G27)=0,"",SUM(واردات!G27,صادرات!G27)),"") -> 2543 | H27: =SUM(C27:F27) -> 2830 | J27: آبان | K27: =IFERROR(IF(SUM(واردات!K27,صادرات!K27)=0,"",SUM(واردات!K27,صادرات!K27)),"") -> 2656 | L27: =IFERROR(IF(SUM(واردات!L27,صادرات!L27)=0,"",SUM(واردات!L27,صادرات!L27)),"") -> 4453 | M27: =IFERROR(IF(SUM(واردات!M27,صادرات!M27)=0,"",SUM(واردات!M27,صادرات!M27)),"") | N27: =IFERROR(IF(SUM(واردات!N27,صادرات!N27)=0,"",SUM(واردات!N27,صادرات!N27)),"") -> 69673 | O27: =IFERROR(IF(SUM(واردات!O27,صادرات!O27)=0,"",SUM(واردات!O27,صادرات!O27)),"") -> 4348 | P27: =SUM(K27:N27) -> 76782 | S27: =IF(OR(SUM(C27:G27)=0,SUM(G$20:G27)=0),"",IF(SUM(S$20:S26)=0,G27,IFERROR(SUM(S26,C27,-D27),""))) -> 1690 | T27: =IFERROR(S27-G27,"") -> -853 | U27: =IF(OR(SUM(K27:O27)=0,SUM(O$20:O27)=0),"",IF(SUM(U$20:U26)=0,O27,IFERROR(SUM(U26,K27,-L27),""))) -> 4592 | V27: =IFERROR(U27-O27,"") -> 244
B28: آذر | C28: =IFERROR(IF(SUM(واردات!C28,صادرات!C28)=0,"",SUM(واردات!C28,صادرات!C28)),"") -> 1289 | D28: =IFERROR(IF(SUM(واردات!D28,صادرات!D28)=0,"",SUM(واردات!D28,صادرات!D28)),"") -> 1006 | E28: =IFERROR(IF(SUM(واردات!E28,صادرات!E28)=0,"",SUM(واردات!E28,صادرات!E28)),"") -> 4 | F28: =IFERROR(IF(SUM(واردات!F28,صادرات!F28)=0,"",SUM(واردات!F28,صادرات!F28)),"") | G28: =IFERROR(IF(SUM(واردات!G28,صادرات!G28)=0,"",SUM(واردات!G28,صادرات!G28)),"") -> 2476 | H28: =SUM(C28:F28) -> 2299 | J28: آذر | K28: =IFERROR(IF(SUM(واردات!K28,صادرات!K28)=0,"",SUM(واردات!K28,صادرات!K28)),"") -> 4671 | L28: =IFERROR(IF(SUM(واردات!L28,صادرات!L28)=0,"",SUM(واردات!L28,صادرات!L28)),"") -> 2940 | M28: =IFERROR(IF(SUM(واردات!M28,صادرات!M28)=0,"",SUM(واردات!M28,صادرات!M28)),"") | N28: =IFERROR(IF(SUM(واردات!N28,صادرات!N28)=0,"",SUM(واردات!N28,صادرات!N28)),"") -> 47213 | O28: =IFERROR(IF(SUM(واردات!O28,صادرات!O28)=0,"",SUM(واردات!O28,صادرات!O28)),"") -> 6079 | P28: =SUM(K28:N28) -> 54824 | S28: =IF(OR(SUM(C28:G28)=0,SUM(G$20:G28)=0),"",IF(SUM(S$20:S27)=0,G28,IFERROR(SUM(S27,C28,-D28),""))) -> 1973 | T28: =IFERROR(S28-G28,"") -> -503 | U28: =IF(OR(SUM(K28:O28)=0,SUM(O$20:O28)=0),"",IF(SUM(U$20:U27)=0,O28,IFERROR(SUM(U27,K28,-L28),""))) -> 6323 | V28: =IFERROR(U28-O28,"") -> 244
B29: دی | C29: =IFERROR(IF(SUM(واردات!C29,صادرات!C29)=0,"",SUM(واردات!C29,صادرات!C29)),"") -> 683 | D29: =IFERROR(IF(SUM(واردات!D29,صادرات!D29)=0,"",SUM(واردات!D29,صادرات!D29)),"") -> 1363 | E29: =IFERROR(IF(SUM(واردات!E29,صادرات!E29)=0,"",SUM(واردات!E29,صادرات!E29)),"") -> 20 | F29: =IFERROR(IF(SUM(واردات!F29,صادرات!F29)=0,"",SUM(واردات!F29,صادرات!F29)),"") | G29: =IFERROR(IF(SUM(واردات!G29,صادرات!G29)=0,"",SUM(واردات!G29,صادرات!G29)),"") -> 1981 | H29: =SUM(C29:F29) -> 2066 | J29: دی | K29: =IFERROR(IF(SUM(واردات!K29,صادرات!K29)=0,"",SUM(واردات!K29,صادرات!K29)),"") -> 2940 | L29: =IFERROR(IF(SUM(واردات!L29,صادرات!L29)=0,"",SUM(واردات!L29,صادرات!L29)),"") -> 3130 | M29: =IFERROR(IF(SUM(واردات!M29,صادرات!M29)=0,"",SUM(واردات!M29,صادرات!M29)),"") | N29: =IFERROR(IF(SUM(واردات!N29,صادرات!N29)=0,"",SUM(واردات!N29,صادرات!N29)),"") -> 39588 | O29: =IFERROR(IF(SUM(واردات!O29,صادرات!O29)=0,"",SUM(واردات!O29,صادرات!O29)),"") -> 5940 | P29: =SUM(K29:N29) -> 45658 | S29: =IF(OR(SUM(C29:G29)=0,SUM(G$20:G29)=0),"",IF(SUM(S$20:S28)=0,G29,IFERROR(SUM(S28,C29,-D29),""))) -> 1293 | T29: =IFERROR(S29-G29,"") -> -688 | U29: =IF(OR(SUM(K29:O29)=0,SUM(O$20:O29)=0),"",IF(SUM(U$20:U28)=0,O29,IFERROR(SUM(U28,K29,-L29),""))) -> 6133 | V29: =IFERROR(U29-O29,"") -> 193
B30: بهمن | C30: =IFERROR(IF(SUM(واردات!C30,صادرات!C30)=0,"",SUM(واردات!C30,صادرات!C30)),"") -> 155 | D30: =IFERROR(IF(SUM(واردات!D30,صادرات!D30)=0,"",SUM(واردات!D30,صادرات!D30)),"") -> 626 | E30: =IFERROR(IF(SUM(واردات!E30,صادرات!E30)=0,"",SUM(واردات!E30,صادرات!E30)),"") | F30: =IFERROR(IF(SUM(واردات!F30,صادرات!F30)=0,"",SUM(واردات!F30,صادرات!F30)),"") | G30: =IFERROR(IF(SUM(واردات!G30,صادرات!G30)=0,"",SUM(واردات!G30,صادرات!G30)),"") -> 1510 | H30: =SUM(C30:F30) -> 781 | J30: بهمن | K30: =IFERROR(IF(SUM(واردات!K30,صادرات!K30)=0,"",SUM(واردات!K30,صادرات!K30)),"") -> 1976 | L30: =IFERROR(IF(SUM(واردات!L30,صادرات!L30)=0,"",SUM(واردات!L30,صادرات!L30)),"") -> 3633 | M30: =IFERROR(IF(SUM(واردات!M30,صادرات!M30)=0,"",SUM(واردات!M30,صادرات!M30)),"") | N30: =IFERROR(IF(SUM(واردات!N30,صادرات!N30)=0,"",SUM(واردات!N30,صادرات!N30)),"") -> 64157 | O30: =IFERROR(IF(SUM(واردات!O30,صادرات!O30)=0,"",SUM(واردات!O30,صادرات!O30)),"") -> 4284 | P30: =SUM(K30:N30) -> 69766 | S30: =IF(OR(SUM(C30:G30)=0,SUM(G$20:G30)=0),"",IF(SUM(S$20:S29)=0,G30,IFERROR(SUM(S29,C30,-D30),""))) -> 822 | T30: =IFERROR(S30-G30,"") -> -688 | U30: =IF(OR(SUM(K30:O30)=0,SUM(O$20:O30)=0),"",IF(SUM(U$20:U29)=0,O30,IFERROR(SUM(U29,K30,-L30),""))) -> 4476 | V30: =IFERROR(U30-O30,"") -> 192
B31: اسفند | C31: =IFERROR(IF(SUM(واردات!C31,صادرات!C31)=0,"",SUM(واردات!C31,صادرات!C31)),"") -> 104 | D31: =IFERROR(IF(SUM(واردات!D31,صادرات!D31)=0,"",SUM(واردات!D31,صادرات!D31)),"") -> 912 | E31: =IFERROR(IF(SUM(واردات!E31,صادرات!E31)=0,"",SUM(واردات!E31,صادرات!E31)),"") | F31: =IFERROR(IF(SUM(واردات!F31,صادرات!F31)=0,"",SUM(واردات!F31,صادرات!F31)),"") | G31: =IFERROR(IF(SUM(واردات!G31,صادرات!G31)=0,"",SUM(واردات!G31,صادرات!G31)),"") -> 703 | H31: =SUM(C31:F31) -> 1016 | J31: اسفند | K31: =IFERROR(IF(SUM(واردات!K31,صادرات!K31)=0,"",SUM(واردات!K31,صادرات!K31)),"") -> 3320 | L31: =IFERROR(IF(SUM(واردات!L31,صادرات!L31)=0,"",SUM(واردات!L31,صادرات!L31)),"") -> 3155 | M31: =IFERROR(IF(SUM(واردات!M31,صادرات!M31)=0,"",SUM(واردات!M31,صادرات!M31)),"") | N31: =IFERROR(IF(SUM(واردات!N31,صادرات!N31)=0,"",SUM(واردات!N31,صادرات!N31)),"") -> 47203 | O31: =IFERROR(IF(SUM(واردات!O31,صادرات!O31)=0,"",SUM(واردات!O31,صادرات!O31)),"") -> 4573 | P31: =SUM(K31:N31) -> 53678 | S31: =IF(OR(SUM(C31:G31)=0,SUM(G$20:G31)=0),"",IF(SUM(S$20:S30)=0,G31,IFERROR(SUM(S30,C31,-D31),""))) -> 14 | T31: =IFERROR(S31-G31,"") -> -689 | U31: =IF(OR(SUM(K31:O31)=0,SUM(O$20:O31)=0),"",IF(SUM(U$20:U30)=0,O31,IFERROR(SUM(U30,K31,-L31),""))) -> 4641 | V31: =IFERROR(U31-O31,"") -> 68
B32: جمع | C32: =SUM(C20:C31) -> 15583 | D32: =SUM(D20:D31) -> 18392 | E32: =SUM(E20:E31) -> 3864 | F32: =SUM(F20:F31) -> 0 | G32: =IF(G31<>"",G31,IF(G30<>"",G30,IF(G29<>"",G29,IF(G28<>"",G28,IF(G27<>"",G27,IF(G26<>"",G26,IF(G25<>"",G25,IF(G24<>"",G24,IF(G23<>"",G23,IF(G22<>"",G22,IF(G21<>"",G21,IF(G20<>"",G20,"")))))))))))) -> 703 | H32: =SUM(C32:F32) -> 37839 | J32: جمع | K32: =SUM(K20:K31) -> 48793 | L32: =SUM(L20:L31) -> 51435 | M32: =SUM(M20:M31) -> 0 | N32: =SUM(N20:N31) -> 693234 | O32: =IF(O31<>"",O31,IF(O30<>"",O30,IF(O29<>"",O29,IF(O28<>"",O28,IF(O27<>"",O27,IF(O26<>"",O26,IF(O25<>"",O25,IF(O24<>"",O24,IF(O23<>"",O23,IF(O22<>"",O22,IF(O21<>"",O21,IF(O20<>"",O20,"")))))))))))) -> 4573 | P32: =SUM(K32:N32) -> 793462
B34: سرخس | J34: لطف آباد
B35: ماه | C35: تخلیه | D35: بارگیری | E35: حمل یکسره | F35: ترانشیپمنت | G35: رسوب | H35: جمع عملیاتی | J35: ماه | K35: تخلیه | L35: بارگیری | M35: حمل یکسره | N35: ترانشیپمنت | O35: رسوب | P35: جمع عملیاتی
B36: فروردین | C36: =IFERROR(IF(SUM(واردات!C36,صادرات!C36)=0,"",SUM(واردات!C36,صادرات!C36)),"") -> 1869 | D36: =IFERROR(IF(SUM(واردات!D36,صادرات!D36)=0,"",SUM(واردات!D36,صادرات!D36)),"") -> 1026 | E36: =IFERROR(IF(SUM(واردات!E36,صادرات!E36)=0,"",SUM(واردات!E36,صادرات!E36)),"") | F36: =IFERROR(IF(SUM(واردات!F36,صادرات!F36)=0,"",SUM(واردات!F36,صادرات!F36)),"") -> 4981 | G36: =IFERROR(IF(SUM(واردات!G36,صادرات!G36)=0,"",SUM(واردات!G36,صادرات!G36)),"") -> 1971 | H36: =SUM(C36:F36) -> 7876 | J36: فروردین | K36: =IFERROR(IF(SUM(واردات!K36,صادرات!K36)=0,"",SUM(واردات!K36,صادرات!K36)),"") -> 4129 | L36: =IFERROR(IF(SUM(واردات!L36,صادرات!L36)=0,"",SUM(واردات!L36,صادرات!L36)),"") -> 6007 | M36: =IFERROR(IF(SUM(واردات!M36,صادرات!M36)=0,"",SUM(واردات!M36,صادرات!M36)),"") | N36: =IFERROR(IF(SUM(واردات!N36,صادرات!N36)=0,"",SUM(واردات!N36,صادرات!N36)),"") -> 81641 | O36: =IFERROR(IF(SUM(واردات!O36,صادرات!O36)=0,"",SUM(واردات!O36,صادرات!O36)),"") -> 1311 | P36: =SUM(K36:N36) -> 91777 | S36: =IF(SUM(G36)=0,"",IFERROR(G36,"")) -> 1971 | T36: =IFERROR(S36-G36,"") -> 0 | U36: =IF(SUM(O36)=0,"",IFERROR(O36,"")) -> 1311 | V36: =IFERROR(U36-O36,"") -> 0
B37: اردیبهشت | C37: =IFERROR(IF(SUM(واردات!C37,صادرات!C37)=0,"",SUM(واردات!C37,صادرات!C37)),"") -> 2531 | D37: =IFERROR(IF(SUM(واردات!D37,صادرات!D37)=0,"",SUM(واردات!D37,صادرات!D37)),"") -> 2584 | E37: =IFERROR(IF(SUM(واردات!E37,صادرات!E37)=0,"",SUM(واردات!E37,صادرات!E37)),"") | F37: =IFERROR(IF(SUM(واردات!F37,صادرات!F37)=0,"",SUM(واردات!F37,صادرات!F37)),"") -> 8515 | G37: =IFERROR(IF(SUM(واردات!G37,صادرات!G37)=0,"",SUM(واردات!G37,صادرات!G37)),"") -> 1918 | H37: =SUM(C37:F37) -> 13630 | J37: اردیبهشت | K37: =IFERROR(IF(SUM(واردات!K37,صادرات!K37)=0,"",SUM(واردات!K37,صادرات!K37)),"") -> 6930 | L37: =IFERROR(IF(SUM(واردات!L37,صادرات!L37)=0,"",SUM(واردات!L37,صادرات!L37)),"") -> 6645 | M37: =IFERROR(IF(SUM(واردات!M37,صادرات!M37)=0,"",SUM(واردات!M37,صادرات!M37)),"") | N37: =IFERROR(IF(SUM(واردات!N37,صادرات!N37)=0,"",SUM(واردات!N37,صادرات!N37)),"") -> 72167 | O37: =IFERROR(IF(SUM(واردات!O37,صادرات!O37)=0,"",SUM(واردات!O37,صادرات!O37)),"") -> 1627 | P37: =SUM(K37:N37) -> 85742 | S37: =IF(OR(SUM(C37:G37)=0,SUM(G$36:G37)=0),"",IF(SUM(S$36:S36)=0,G37,IFERROR(SUM(S36,C37,-D37),""))) -> 1918 | T37: =IFERROR(S37-G37,"") -> 0 | U37: =IF(OR(SUM(K37:O37)=0,SUM(O$36:O37)=0),"",IF(SUM(U$36:U36)=0,O37,IFERROR(SUM(U36,K37,-L37),""))) -> 1596 | V37: =IFERROR(U37-O37,"") -> -31
B38: خرداد | C38: =IFERROR(IF(SUM(واردات!C38,صادرات!C38)=0,"",SUM(واردات!C38,صادرات!C38)),"") -> 1484 | D38: =IFERROR(IF(SUM(واردات!D38,صادرات!D38)=0,"",SUM(واردات!D38,صادرات!D38)),"") -> 1871 | E38: =IFERROR(IF(SUM(واردات!E38,صادرات!E38)=0,"",SUM(واردات!E38,صادرات!E38)),"") | F38: =IFERROR(IF(SUM(واردات!F38,صادرات!F38)=0,"",SUM(واردات!F38,صادرات!F38)),"") -> 8339 | G38: =IFERROR(IF(SUM(واردات!G38,صادرات!G38)=0,"",SUM(واردات!G38,صادرات!G38)),"") -> 1547 | H38: =SUM(C38:F38) -> 11694 | J38: خرداد | K38: =IFERROR(IF(SUM(واردات!K38,صادرات!K38)=0,"",SUM(واردات!K38,صادرات!K38)),"") -> 8823 | L38: =IFERROR(IF(SUM(واردات!L38,صادرات!L38)=0,"",SUM(واردات!L38,صادرات!L38)),"") -> 6130 | M38: =IFERROR(IF(SUM(واردات!M38,صادرات!M38)=0,"",SUM(واردات!M38,صادرات!M38)),"") | N38: =IFERROR(IF(SUM(واردات!N38,صادرات!N38)=0,"",SUM(واردات!N38,صادرات!N38)),"") -> 60319 | O38: =IFERROR(IF(SUM(واردات!O38,صادرات!O38)=0,"",SUM(واردات!O38,صادرات!O38)),"") -> 4320 | P38: =SUM(K38:N38) -> 75272 | S38: =IF(OR(SUM(C38:G38)=0,SUM(G$36:G38)=0),"",IF(SUM(S$36:S37)=0,G38,IFERROR(SUM(S37,C38,-D38),""))) -> 1531 | T38: =IFERROR(S38-G38,"") -> -16 | U38: =IF(OR(SUM(K38:O38)=0,SUM(O$36:O38)=0),"",IF(SUM(U$36:U37)=0,O38,IFERROR(SUM(U37,K38,-L38),""))) -> 4289 | V38: =IFERROR(U38-O38,"") -> -31
B39: تیر | C39: =IFERROR(IF(SUM(واردات!C39,صادرات!C39)=0,"",SUM(واردات!C39,صادرات!C39)),"") -> 1396 | D39: =IFERROR(IF(SUM(واردات!D39,صادرات!D39)=0,"",SUM(واردات!D39,صادرات!D39)),"") -> 2028 | E39: =IFERROR(IF(SUM(واردات!E39,صادرات!E39)=0,"",SUM(واردات!E39,صادرات!E39)),"") | F39: =IFERROR(IF(SUM(واردات!F39,صادرات!F39)=0,"",SUM(واردات!F39,صادرات!F39)),"") -> 8352 | G39: =IFERROR(IF(SUM(واردات!G39,صادرات!G39)=0,"",SUM(واردات!G39,صادرات!G39)),"") -> 1220 | H39: =SUM(C39:F39) -> 11776 | J39: تیر | K39: =IFERROR(IF(SUM(واردات!K39,صادرات!K39)=0,"",SUM(واردات!K39,صادرات!K39)),"") -> 5564 | L39: =IFERROR(IF(SUM(واردات!L39,صادرات!L39)=0,"",SUM(واردات!L39,صادرات!L39)),"") -> 7048 | M39: =IFERROR(IF(SUM(واردات!M39,صادرات!M39)=0,"",SUM(واردات!M39,صادرات!M39)),"") | N39: =IFERROR(IF(SUM(واردات!N39,صادرات!N39)=0,"",SUM(واردات!N39,صادرات!N39)),"") -> 60422 | O39: =IFERROR(IF(SUM(واردات!O39,صادرات!O39)=0,"",SUM(واردات!O39,صادرات!O39)),"") -> 2858 | P39: =SUM(K39:N39) -> 73034 | S39: =IF(OR(SUM(C39:G39)=0,SUM(G$36:G39)=0),"",IF(SUM(S$36:S38)=0,G39,IFERROR(SUM(S38,C39,-D39),""))) -> 899 | T39: =IFERROR(S39-G39,"") -> -321 | U39: =IF(OR(SUM(K39:O39)=0,SUM(O$36:O39)=0),"",IF(SUM(U$36:U38)=0,O39,IFERROR(SUM(U38,K39,-L39),""))) -> 2805 | V39: =IFERROR(U39-O39,"") -> -53
B40: مرداد | C40: =IFERROR(IF(SUM(واردات!C40,صادرات!C40)=0,"",SUM(واردات!C40,صادرات!C40)),"") -> 4003 | D40: =IFERROR(IF(SUM(واردات!D40,صادرات!D40)=0,"",SUM(واردات!D40,صادرات!D40)),"") -> 2096 | E40: =IFERROR(IF(SUM(واردات!E40,صادرات!E40)=0,"",SUM(واردات!E40,صادرات!E40)),"") | F40: =IFERROR(IF(SUM(واردات!F40,صادرات!F40)=0,"",SUM(واردات!F40,صادرات!F40)),"") -> 11957 | G40: =IFERROR(IF(SUM(واردات!G40,صادرات!G40)=0,"",SUM(واردات!G40,صادرات!G40)),"") -> 4847 | H40: =SUM(C40:F40) -> 18056 | J40: مرداد | K40: =IFERROR(IF(SUM(واردات!K40,صادرات!K40)=0,"",SUM(واردات!K40,صادرات!K40)),"") -> 8594 | L40: =IFERROR(IF(SUM(واردات!L40,صادرات!L40)=0,"",SUM(واردات!L40,صادرات!L40)),"") -> 7428 | M40: =IFERROR(IF(SUM(واردات!M40,صادرات!M40)=0,"",SUM(واردات!M40,صادرات!M40)),"") | N40: =IFERROR(IF(SUM(واردات!N40,صادرات!N40)=0,"",SUM(واردات!N40,صادرات!N40)),"") -> 69420 | O40: =IFERROR(IF(SUM(واردات!O40,صادرات!O40)=0,"",SUM(واردات!O40,صادرات!O40)),"") -> 4039 | P40: =SUM(K40:N40) -> 85442 | S40: =IF(OR(SUM(C40:G40)=0,SUM(G$36:G40)=0),"",IF(SUM(S$36:S39)=0,G40,IFERROR(SUM(S39,C40,-D40),""))) -> 2806 | T40: =IFERROR(S40-G40,"") -> -2041 | U40: =IF(OR(SUM(K40:O40)=0,SUM(O$36:O40)=0),"",IF(SUM(U$36:U39)=0,O40,IFERROR(SUM(U39,K40,-L40),""))) -> 3971 | V40: =IFERROR(U40-O40,"") -> -68
B41: شهریور | C41: =IFERROR(IF(SUM(واردات!C41,صادرات!C41)=0,"",SUM(واردات!C41,صادرات!C41)),"") -> 2703 | D41: =IFERROR(IF(SUM(واردات!D41,صادرات!D41)=0,"",SUM(واردات!D41,صادرات!D41)),"") -> 3423 | E41: =IFERROR(IF(SUM(واردات!E41,صادرات!E41)=0,"",SUM(واردات!E41,صادرات!E41)),"") | F41: =IFERROR(IF(SUM(واردات!F41,صادرات!F41)=0,"",SUM(واردات!F41,صادرات!F41)),"") -> 14592 | G41: =IFERROR(IF(SUM(واردات!G41,صادرات!G41)=0,"",SUM(واردات!G41,صادرات!G41)),"") -> 2373 | H41: =SUM(C41:F41) -> 20718 | J41: شهریور | K41: =IFERROR(IF(SUM(واردات!K41,صادرات!K41)=0,"",SUM(واردات!K41,صادرات!K41)),"") -> 9553 | L41: =IFERROR(IF(SUM(واردات!L41,صادرات!L41)=0,"",SUM(واردات!L41,صادرات!L41)),"") -> 8018 | M41: =IFERROR(IF(SUM(واردات!M41,صادرات!M41)=0,"",SUM(واردات!M41,صادرات!M41)),"") | N41: =IFERROR(IF(SUM(واردات!N41,صادرات!N41)=0,"",SUM(واردات!N41,صادرات!N41)),"") -> 74201 | O41: =IFERROR(IF(SUM(واردات!O41,صادرات!O41)=0,"",SUM(واردات!O41,صادرات!O41)),"") -> 5608 | P41: =SUM(K41:N41) -> 91772 | S41: =IF(OR(SUM(C41:G41)=0,SUM(G$36:G41)=0),"",IF(SUM(S$36:S40)=0,G41,IFERROR(SUM(S40,C41,-D41),""))) -> 2086 | T41: =IFERROR(S41-G41,"") -> -287 | U41: =IF(OR(SUM(K41:O41)=0,SUM(O$36:O41)=0),"",IF(SUM(U$36:U40)=0,O41,IFERROR(SUM(U40,K41,-L41),""))) -> 5506 | V41: =IFERROR(U41-O41,"") -> -102
B42: مهر | C42: =IFERROR(IF(SUM(واردات!C42,صادرات!C42)=0,"",SUM(واردات!C42,صادرات!C42)),"") -> 3183 | D42: =IFERROR(IF(SUM(واردات!D42,صادرات!D42)=0,"",SUM(واردات!D42,صادرات!D42)),"") -> 2946 | E42: =IFERROR(IF(SUM(واردات!E42,صادرات!E42)=0,"",SUM(واردات!E42,صادرات!E42)),"") | F42: =IFERROR(IF(SUM(واردات!F42,صادرات!F42)=0,"",SUM(واردات!F42,صادرات!F42)),"") -> 14671 | G42: =IFERROR(IF(SUM(واردات!G42,صادرات!G42)=0,"",SUM(واردات!G42,صادرات!G42)),"") -> 2713 | H42: =SUM(C42:F42) -> 20800 | J42: مهر | K42: =IFERROR(IF(SUM(واردات!K42,صادرات!K42)=0,"",SUM(واردات!K42,صادرات!K42)),"") -> 8905 | L42: =IFERROR(IF(SUM(واردات!L42,صادرات!L42)=0,"",SUM(واردات!L42,صادرات!L42)),"") -> 8229 | M42: =IFERROR(IF(SUM(واردات!M42,صادرات!M42)=0,"",SUM(واردات!M42,صادرات!M42)),"") | N42: =IFERROR(IF(SUM(واردات!N42,صادرات!N42)=0,"",SUM(واردات!N42,صادرات!N42)),"") -> 72407 | O42: =IFERROR(IF(SUM(واردات!O42,صادرات!O42)=0,"",SUM(واردات!O42,صادرات!O42)),"") -> 6314 | P42: =SUM(K42:N42) -> 89541 | S42: =IF(OR(SUM(C42:G42)=0,SUM(G$36:G42)=0),"",IF(SUM(S$36:S41)=0,G42,IFERROR(SUM(S41,C42,-D42),""))) -> 2323 | T42: =IFERROR(S42-G42,"") -> -390 | U42: =IF(OR(SUM(K42:O42)=0,SUM(O$36:O42)=0),"",IF(SUM(U$36:U41)=0,O42,IFERROR(SUM(U41,K42,-L42),""))) -> 6182 | V42: =IFERROR(U42-O42,"") -> -132
B43: آبان | C43: =IFERROR(IF(SUM(واردات!C43,صادرات!C43)=0,"",SUM(واردات!C43,صادرات!C43)),"") -> 4223 | D43: =IFERROR(IF(SUM(واردات!D43,صادرات!D43)=0,"",SUM(واردات!D43,صادرات!D43)),"") -> 3815 | E43: =IFERROR(IF(SUM(واردات!E43,صادرات!E43)=0,"",SUM(واردات!E43,صادرات!E43)),"") | F43: =IFERROR(IF(SUM(واردات!F43,صادرات!F43)=0,"",SUM(واردات!F43,صادرات!F43)),"") -> 14098 | G43: =IFERROR(IF(SUM(واردات!G43,صادرات!G43)=0,"",SUM(واردات!G43,صادرات!G43)),"") -> 2773 | H43: =SUM(C43:F43) -> 22136 | J43: آبان | K43: =IFERROR(IF(SUM(واردات!K43,صادرات!K43)=0,"",SUM(واردات!K43,صادرات!K43)),"") -> 7460 | L43: =IFERROR(IF(SUM(واردات!L43,صادرات!L43)=0,"",SUM(واردات!L43,صادرات!L43)),"") -> 9283 | M43: =IFERROR(IF(SUM(واردات!M43,صادرات!M43)=0,"",SUM(واردات!M43,صادرات!M43)),"") | N43: =IFERROR(IF(SUM(واردات!N43,صادرات!N43)=0,"",SUM(واردات!N43,صادرات!N43)),"") -> 81270 | O43: =IFERROR(IF(SUM(واردات!O43,صادرات!O43)=0,"",SUM(واردات!O43,صادرات!O43)),"") -> 4585 | P43: =SUM(K43:N43) -> 98013 | S43: =IF(OR(SUM(C43:G43)=0,SUM(G$36:G43)=0),"",IF(SUM(S$36:S42)=0,G43,IFERROR(SUM(S42,C43,-D43),""))) -> 2731 | T43: =IFERROR(S43-G43,"") -> -42 | U43: =IF(OR(SUM(K43:O43)=0,SUM(O$36:O43)=0),"",IF(SUM(U$36:U42)=0,O43,IFERROR(SUM(U42,K43,-L43),""))) -> 4359 | V43: =IFERROR(U43-O43,"") -> -226
...

Sheet واردات
B2: واردات مجتمع خراسان | J2: فرودگاه هاشمی نژاد
B3: ماه | C3: تخلیه | D3: بارگیری | E3: حمل یکسره | F3: ترانشیپمنت | G3: رسوب | H3: جمع عملیاتی | J3: ماه | K3: تخلیه | L3: بارگیری | M3: حمل یکسره | N3: ترانشیپمنت | O3: رسوب | P3: جمع عملیاتی | S3: رسوب محاسبه شده
A4: =B2 -> واردات مجتمع خراسان | B4: فروردین | C4: =IF(SUM(K4,C20,K20,C36,K36,C52,K52,C68,K68,C84)=0,"",SUM(K4,C20,K20,C36,K36,C52,K52,C68,K68,C84,K84)) -> 16718 | D4: =IF(SUM(L4,D20,L20,D36,L36,D52,L52,D68,L68,D84)=0,"",SUM(L4,D20,L20,D36,L36,D52,L52,D68,L68,D84,L84)) -> 19111 | E4: =IF(SUM(M4,E20,M20,E36,M36,E52,M52,E68,M68,E84)=0,"",SUM(M4,E20,M20,E36,M36,E52,M52,E68,M68,E84,M84)) -> 407 | F4: =IF(SUM(N4,F20,N20,F36,N36,F52,N52,F68,N68,F84)=0,"",SUM(N4,F20,N20,F36,N36,F52,N52,F68,N68,F84,N84)) -> 90473 | G4: =IF(SUM(O4,G20,O20,G36,O36,G52,O52,G68,O68,G84)=0,"",SUM(O4,G20,O20,G36,O36,G52,O52,G68,O68,G84,O84)) -> 26939 | H4: =SUM(C4:F4) -> 126709 | I4: =J2 -> فرودگاه هاشمی نژاد | J4: فروردین | P4: =SUM(K4:N4) -> 0 | S4: =IF(SUM(G4)=0,"",IFERROR(G4,"")) -> 26939 | T4: =IFERROR(S4-G4,"") -> 0 | U4: =IF(SUM(O4)=0,"",IFERROR(O4,"")) | V4: =IFERROR(U4-O4,"")
A5: =B2 -> واردات مجتمع خراسان | B5: اردیبهشت | C5: =IF(SUM(K5,C21,K21,C37,K37,C53,K53,C69,K69,C85)=0,"",SUM(K5,C21,K21,C37,K37,C53,K53,C69,K69,C85,K85)) -> 17719 | D5: =IF(SUM(L5,D21,L21,D37,L37,D53,L53,D69,L69,D85)=0,"",SUM(L5,D21,L21,D37,L37,D53,L53,D69,L69,D85,L85)) -> 17949 | E5: =IF(SUM(M5,E21,M21,E37,M37,E53,M53,E69,M69,E85)=0,"",SUM(M5,E21,M21,E37,M37,E53,M53,E69,M69,E85,M85)) -> 657 | F5: =IF(SUM(N5,F21,N21,F37,N37,F53,N53,F69,N69,F85)=0,"",SUM(N5,F21,N21,F37,N37,F53,N53,F69,N69,F85,N85)) -> 84907 | G5: =IF(SUM(O5,G21,O21,G37,O37,G53,O53,G69,O69,G85)=0,"",SUM(O5,G21,O21,G37,O37,G53,O53,G69,O69,G85,O85)) -> 27081 | H5: =SUM(C5:F5) -> 121232 | I5: =J2 -> فرودگاه هاشمی نژاد | J5: اردیبهشت | P5: =SUM(K5:N5) -> 0 | S5: =IF(OR(SUM(C5:G5)=0,SUM(G$4:G5)=0),"",IF(SUM(S$4:S4)=0,G5,IFERROR(SUM(S4,C5,-D5),""))) -> 26709 | T5: =IFERROR(S5-G5,"") -> -372 | U5: =IF(OR(SUM(K5:O5)=0,SUM(O$4:O5)=0),"",IF(SUM(U$4:U4)=0,O5,IFERROR(SUM(U4,K5,-L5),""))) | V5: =IFERROR(U5-O5,"")
A6: =B2 -> واردات مجتمع خراسان | B6: خرداد | C6: =IF(SUM(K6,C22,K22,C38,K38,C54,K54,C70,K70,C86)=0,"",SUM(K6,C22,K22,C38,K38,C54,K54,C70,K70,C86,K86)) -> 17760 | D6: =IF(SUM(L6,D22,L22,D38,L38,D54,L54,D70,L70,D86)=0,"",SUM(L6,D22,L22,D38,L38,D54,L54,D70,L70,D86,L86)) -> 15467 | E6: =IF(SUM(M6,E22,M22,E38,M38,E54,M54,E70,M70,E86)=0,"",SUM(M6,E22,M22,E38,M38,E54,M54,E70,M70,E86,M86)) -> 863 | F6: =IF(SUM(N6,F22,N22,F38,N38,F54,N54,F70,N70,F86)=0,"",SUM(N6,F22,N22,F38,N38,F54,N54,F70,N70,F86,N86)) -> 70721 | G6: =IF(SUM(O6,G22,O22,G38,O38,G54,O54,G70,O70,G86)=0,"",SUM(O6,G22,O22,G38,O38,G54,O54,G70,O70,G86,O86)) -> 27823 | H6: =SUM(C6:F6) -> 104811 | I6: =J2 -> فرودگاه هاشمی نژاد | J6: خرداد | P6: =SUM(K6:N6) -> 0 | S6: =IF(OR(SUM(C6:G6)=0,SUM(G$4:G6)=0),"",IF(SUM(S$4:S5)=0,G6,IFERROR(SUM(S5,C6,-D6),""))) -> 29002 | T6: =IFERROR(S6-G6,"") -> 1179 | U6: =IF(OR(SUM(K6:O6)=0,SUM(O$4:O6)=0),"",IF(SUM(U$4:U5)=0,O6,IFERROR(SUM(U5,K6,-L6),""))) | V6: =IFERROR(U6-O6,"")
A7: =B2 -> واردات مجتمع خراسان | B7: تیر | C7: =IF(SUM(K7,C23,K23,C39,K39,C55,K55,C71,K71,C87)=0,"",SUM(K7,C23,K23,C39,K39,C55,K55,C71,K71,C87,K87)) -> 13439 | D7: =IF(SUM(L7,D23,L23,D39,L39,D55,L55,D71,L71,D87)=0,"",SUM(L7,D23,L23,D39,L39,D55,L55,D71,L71,D87,L87)) -> 19960 | E7: =IF(SUM(M7,E23,M23,E39,M39,E55,M55,E71,M71,E87)=0,"",SUM(M7,E23,M23,E39,M39,E55,M55,E71,M71,E87,M87)) -> 293 | F7: =IF(SUM(N7,F23,N23,F39,N39,F55,N55,F71,N71,F87)=0,"",SUM(N7,F23,N23,F39,N39,F55,N55,F71,N71,F87,N87)) -> 74800 | G7: =IF(SUM(O7,G23,O23,G39,O39,G55,O55,G71,O71,G87)=0,"",SUM(O7,G23,O23,G39,O39,G55,O55,G71,O71,G87,O87)) -> 23545 | H7: =SUM(C7:F7) -> 108492 | I7: =J2 -> فرودگاه هاشمی نژاد | J7: تیر | P7: =SUM(K7:N7) -> 0 | S7: =IF(OR(SUM(C7:G7)=0,SUM(G$4:G7)=0),"",IF(SUM(S$4:S6)=0,G7,IFERROR(SUM(S6,C7,-D7),""))) -> 22481 | T7: =IFERROR(S7-G7,"") -> -1064 | U7: =IF(OR(SUM(K7:O7)=0,SUM(O$4:O7)=0),"",IF(SUM(U$4:U6)=0,O7,IFERROR(SUM(U6,K7,-L7),""))) | V7: =IFERROR(U7-O7,"")
A8: =B2 -> واردات مجتمع خراسان | B8: مرداد | C8: =IF(SUM(K8,C24,K24,C40,K40,C56,K56,C72,K72,C88)=0,"",SUM(K8,C24,K24,C40,K40,C56,K56,C72,K72,C88,K88)) -> 16219 | D8: =IF(SUM(L8,D24,L24,D40,L40,D56,L56,D72,L72,D88)=0,"",SUM(L8,D24,L24,D40,L40,D56,L56,D72,L72,D88,L88)) -> 25347 | E8: =IF(SUM(M8,E24,M24,E40,M40,E56,M56,E72,M72,E88)=0,"",SUM(M8,E24,M24,E40,M40,E56,M56,E72,M72,E88,M88)) -> 1520 | F8: =IF(SUM(N8,F24,N24,F40,N40,F56,N56,F72,N72,F88)=0,"",SUM(N8,F24,N24,F40,N40,F56,N56,F72,N72,F88,N88)) -> 84582 | G8: =IF(SUM(O8,G24,O24,G40,O40,G56,O56,G72,O72,G88)=0,"",SUM(O8,G24,O24,G40,O40,G56,O56,G72,O72,G88,O88)) -> 14494 | H8: =SUM(C8:F8) -> 127668 | I8: =J2 -> فرودگاه هاشمی نژاد | J8: مرداد | P8: =SUM(K8:N8) -> 0 | S8: =IF(OR(SUM(C8:G8)=0,SUM(G$4:G8)=0),"",IF(SUM(S$4:S7)=0,G8,IFERROR(SUM(S7,C8,-D8),""))) -> 13353 | T8: =IFERROR(S8-G8,"") -> -1141 | U8: =IF(OR(SUM(K8:O8)=0,SUM(O$4:O8)=0),"",IF(SUM(U$4:U7)=0,O8,IFERROR(SUM(U7,K8,-L8),""))) | V8: =IFERROR(U8-O8,"")
A9: =B2 -> واردات مجتمع خراسان | B9: شهریور | C9: =IF(SUM(K9,C25,K25,C41,K41,C57,K57,C73,K73,C89)=0,"",SUM(K9,C25,K25,C41,K41,C57,K57,C73,K73,C89,K89)) -> 20754 | D9: =IF(SUM(L9,D25,L25,D41,L41,D57,L57,D73,L73,D89)=0,"",SUM(L9,D25,L25,D41,L41,D57,L57,D73,L73,D89,L89)) -> 15888 | E9: =IF(SUM(M9,E25,M25,E41,M41,E57,M57,E73,M73,E89)=0,"",SUM(M9,E25,M25,E41,M41,E57,M57,E73,M73,E89,M89)) -> 162 | F9: =IF(SUM(N9,F25,N25,F41,N41,F57,N57,F73,N73,F89)=0,"",SUM(N9,F25,N25,F41,N41,F57,N57,F73,N73,F89,N89)) -> 92863 | G9: =IF(SUM(O9,G25,O25,G41,O41,G57,O57,G73,O73,G89)=0,"",SUM(O9,G25,O25,G41,O41,G57,O57,G73,O73,G89,O89)) -> 19729 | H9: =SUM(C9:F9) -> 129667 | I9: =J2 -> فرودگاه هاشمی نژاد | J9: شهریور | P9: =SUM(K9:N9) -> 0 | S9: =IF(OR(SUM(C9:G9)=0,SUM(G$4:G9)=0),"",IF(SUM(S$4:S8)=0,G9,IFERROR(SUM(S8,C9,-D9),""))) -> 18219 | T9: =IFERROR(S9-G9,"") -> -1510 | U9: =IF(OR(SUM(K9:O9)=0,SUM(O$4:O9)=0),"",IF(SUM(U$4:U8)=0,O9,IFERROR(SUM(U8,K9,-L9),""))) | V9: =IFERROR(U9-O9,"")
A10: =B2 -> واردات مجتمع خراسان | B10: مهر | C10: =IF(SUM(K10,C26,K26,C42,K42,C58,K58,C74,K74,C90)=0,"",SUM(K10,C26,K26,C42,K42,C58,K58,C74,K74,C90,K90)) -> 18829 | D10: =IF(SUM(L10,D26,L26,D42,L42,D58,L58,D74,L74,D90)=0,"",SUM(L10,D26,L26,D42,L42,D58,L58,D74,L74,D90,L90)) -> 19819 | E10: =IF(SUM(M10,E26,M26,E42,M42,E58,M58,E74,M74,E90)=0,"",SUM(M10,E26,M26,E42,M42,E58,M58,E74,M74,E90,M90)) | F10: =IF(SUM(N10,F26,N26,F42,N42,F58,N58,F74,N74,F90)=0,"",SUM(N10,F26,N26,F42,N42,F58,N58,F74,N74,F90,N90)) -> 100787 | G10: =IF(SUM(O10,G26,O26,G42,O42,G58,O58,G74,O74,G90)=0,"",SUM(O10,G26,O26,G42,O42,G58,O58,G74,O74,G90,O90)) -> 18886 | H10: =SUM(C10:F10) -> 139435 | I10: =J2 -> فرودگاه هاشمی نژاد | J10: مهر | P10: =SUM(K10:N10) -> 0 | S10: =IF(OR(SUM(C10:G10)=0,SUM(G$4:G10)=0),"",IF(SUM(S$4:S9)=0,G10,IFERROR(SUM(S9,C10,-D10),""))) -> 17229 | T10: =IFERROR(S10-G10,"") -> -1657 | U10: =IF(OR(SUM(K10:O10)=0,SUM(O$4:O10)=0),"",IF(SUM(U$4:U9)=0,O10,IFERROR(SUM(U9,K10,-L10),""))) | V10: =IFERROR(U10-O10,"")
A11: =B2 -> واردات مجتمع خراسان | B11: آبان | C11: =IF(SUM(K11,C27,K27,C43,K43,C59,K59,C75,K75,C91)=0,"",SUM(K11,C27,K27,C43,K43,C59,K59,C75,K75,C91,K91)) -> 35741 | D11: =IF(SUM(L11,D27,L27,D43,L43,D59,L59,D75,L75,D91)=0,"",SUM(L11,D27,L27,D43,L43,D59,L59,D75,L75,D91,L91)) -> 21498 | E11: =IF(SUM(M11,E27,M27,E43,M43,E59,M59,E75,M75,E91)=0,"",SUM(M11,E27,M27,E43,M43,E59,M59,E75,M75,E91,M91)) | F11: =IF(SUM(N11,F27,N27,F43,N43,F59,N59,F75,N75,F91)=0,"",SUM(N11,F27,N27,F43,N43,F59,N59,F75,N75,F91,N91)) -> 102708 | G11: =IF(SUM(O11,G27,O27,G43,O43,G59,O59,G75,O75,G91)=0,"",SUM(O11,G27,O27,G43,O43,G59,O59,G75,O75,G91,O91)) -> 33236 | H11: =SUM(C11:F11) -> 159947 | I11: =J2 -> فرودگاه هاشمی نژاد | J11: آبان | P11: =SUM(K11:N11) -> 0 | S11: =IF(OR(SUM(C11:G11)=0,SUM(G$4:G11)=0),"",IF(SUM(S$4:S10)=0,G11,IFERROR(SUM(S10,C11,-D11),""))) -> 31472 | T11: =IFERROR(S11-G11,"") -> -1764 | U11: =IF(OR(SUM(K11:O11)=0,SUM(O$4:O11)=0),"",IF(SUM(U$4:U10)=0,O11,IFERROR(SUM(U10,K11,-L11),""))) | V11: =IFERROR(U11-O11,"")
A12: =B2 -> واردات مجتمع خراسان | B12: آذر | C12: =IF(SUM(K12,C28,K28,C44,K44,C60,K60,C76,K76,C92)=0,"",SUM(K12,C28,K28,C44,K44,C60,K60,C76,K76,C92,K92)) -> 26777 | D12: =IF(SUM(L12,D28,L28,D44,L44,D60,L60,D76,L76,D92)=0,"",SUM(L12,D28,L28,D44,L44,D60,L60,D76,L76,D92,L92)) -> 24206 | E12: =IF(SUM(M12,E28,M28,E44,M44,E60,M60,E76,M76,E92)=0,"",SUM(M12,E28,M28,E44,M44,E60,M60,E76,M76,E92,M92)) -> 4 | F12: =IF(SUM(N12,F28,N28,F44,N44,F60,N60,F76,N76,F92)=0,"",SUM(N12,F28,N28,F44,N44,F60,N60,F76,N76,F92,N92)) -> 112833 | G12: =IF(SUM(O12,G28,O28,G44,O44,G60,O60,G76,O76,G92)=0,"",SUM(O12,G28,O28,G44,O44,G60,O60,G76,O76,G92,O92)) -> 35617 | H12: =SUM(C12:F12) -> 163820 | I12: =J2 -> فرودگاه هاشمی نژاد | J12: آذر | P12: =SUM(K12:N12) -> 0 | S12: =IF(OR(SUM(C12:G12)=0,SUM(G$4:G12)=0),"",IF(SUM(S$4:S11)=0,G12,IFERROR(SUM(S11,C12,-D12),""))) -> 34043 | T12: =IFERROR(S12-G12,"") -> -1574 | U12: =IF(OR(SUM(K12:O12)=0,SUM(O$4:O12)=0),"",IF(SUM(U$4:U11)=0,O12,IFERROR(SUM(U11,K12,-L12),""))) | V12: =IFERROR(U12-O12,"")
A13: =B2 -> واردات مجتمع خراسان | B13: دی | C13: =IF(SUM(K13,C29,K29,C45,K45,C61,K61,C77,K77,C93)=0,"",SUM(K13,C29,K29,C45,K45,C61,K61,C77,K77,C93,K93)) -> 17385 | D13: =IF(SUM(L13,D29,L29,D45,L45,D61,L61,D77,L77,D93)=0,"",SUM(L13,D29,L29,D45,L45,D61,L61,D77,L77,D93,L93)) -> 26844 | E13: =IF(SUM(M13,E29,M29,E45,M45,E61,M61,E77,M77,E93)=0,"",SUM(M13,E29,M29,E45,M45,E61,M61,E77,M77,E93,M93)) -> 20 | F13: =IF(SUM(N13,F29,N29,F45,N45,F61,N61,F77,N77,F93)=0,"",SUM(N13,F29,N29,F45,N45,F61,N61,F77,N77,F93,N93)) -> 107111 | G13: =IF(SUM(O13,G29,O29,G45,O45,G61,O61,G77,O77,G93)=0,"",SUM(O13,G29,O29,G45,O45,G61,O61,G77,O77,G93,O93)) -> 27229 | H13: =SUM(C13:F13) -> 151360 | I13: =J2 -> فرودگاه هاشمی نژاد | J13: دی | P13: =SUM(K13:N13) -> 0 | S13: =IF(OR(SUM(C13:G13)=0,SUM(G$4:G13)=0),"",IF(SUM(S$4:S12)=0,G13,IFERROR(SUM(S12,C13,-D13),""))) -> 24584 | T13: =IFERROR(S13-G13,"") -> -2645 | U13: =IF(OR(SUM(K13:O13)=0,SUM(O$4:O13)=0),"",IF(SUM(U$4:U12)=0,O13,IFERROR(SUM(U12,K13,-L13),""))) | V13: =IFERROR(U13-O13,"")
A14: =B2 -> واردات مجتمع خراسان | B14: بهمن | C14: =IF(SUM(K14,C30,K30,C46,K46,C62,K62,C78,K78,C94)=0,"",SUM(K14,C30,K30,C46,K46,C62,K62,C78,K78,C94,K94)) -> 23040 | D14: =IF(SUM(L14,D30,L30,D46,L46,D62,L62,D78,L78,D94)=0,"",SUM(L14,D30,L30,D46,L46,D62,L62,D78,L78,D94,L94)) -> 25455 | E14: =IF(SUM(M14,E30,M30,E46,M46,E62,M62,E78,M78,E94)=0,"",SUM(M14,E30,M30,E46,M46,E62,M62,E78,M78,E94,M94)) | F14: =IF(SUM(N14,F30,N30,F46,N46,F62,N62,F78,N78,F94)=0,"",SUM(N14,F30,N30,F46,N46,F62,N62,F78,N78,F94,N94)) -> 116832 | G14: =IF(SUM(O14,G30,O30,G46,O46,G62,O62,G78,O78,G94)=0,"",SUM(O14,G30,O30,G46,O46,G62,O62,G78,O78,G94,O94)) -> 27407 | H14: =SUM(C14:F14) -> 165327 | I14: =J2 -> فرودگاه هاشمی نژاد | J14: بهمن | P14: =SUM(K14:N14) -> 0 | S14: =IF(OR(SUM(C14:G14)=0,SUM(G$4:G14)=0),"",IF(SUM(S$4:S13)=0,G14,IFERROR(SUM(S13,C14,-D14),""))) -> 22169 | T14: =IFERROR(S14-G14,"") -> -5238 | U14: =IF(OR(SUM(K14:O14)=0,SUM(O$4:O14)=0),"",IF(SUM(U$4:U13)=0,O14,IFERROR(SUM(U13,K14,-L14),""))) | V14: =IFERROR(U14-O14,"")
A15: =B2 -> واردات مجتمع خراسان | B15: اسفند | C15: =IF(SUM(K15,C31,K31,C47,K47,C63,K63,C79,K79,C95)=0,"",SUM(K15,C31,K31,C47,K47,C63,K63,C79,K79,C95,K95)) -> 23502 | D15: =IF(SUM(L15,D31,L31,D47,L47,D63,L63,D79,L79,D95)=0,"",SUM(L15,D31,L31,D47,L47,D63,L63,D79,L79,D95,L95)) -> 23751 | E15: =IF(SUM(M15,E31,M31,E47,M47,E63,M63,E79,M79,E95)=0,"",SUM(M15,E31,M31,E47,M47,E63,M63,E79,M79,E95,M95)) | F15: =IF(SUM(N15,F31,N31,F47,N47,F63,N63,F79,N79,F95)=0,"",SUM(N15,F31,N31,F47,N47,F63,N63,F79,N79,F95,N95)) -> 124202 | G15: =IF(SUM(O15,G31,O31,G47,O47,G63,O63,G79,O79,G95)=0,"",SUM(O15,G31,O31,G47,O47,G63,O63,G79,O79,G95,O95)) -> 23032 | H15: =SUM(C15:F15) -> 171455 | I15: =J2 -> فرودگاه هاشمی نژاد | J15: اسفند | P15: =SUM(K15:N15) -> 0 | S15: =IF(OR(SUM(C15:G15)=0,SUM(G$4:G15)=0),"",IF(SUM(S$4:S14)=0,G15,IFERROR(SUM(S14,C15,-D15),""))) -> 21920 | T15: =IFERROR(S15-G15,"") -> -1112 | U15: =IF(OR(SUM(K15:O15)=0,SUM(O$4:O15)=0),"",IF(SUM(U$4:U14)=0,O15,IFERROR(SUM(U14,K15,-L15),""))) | V15: =IFERROR(U15-O15,"")
B16: جمع | C16: =SUM(C4:C15) -> 247883 | D16: =SUM(D4:D15) -> 255295 | E16: =SUM(E4:E15) -> 3926 | F16: =SUM(F4:F15) -> 1162819 | G16: =IF(G15<>"",G15,IF(G14<>"",G14,IF(G13<>"",G13,IF(G12<>"",G12,IF(G11<>"",G11,IF(G10<>"",G10,IF(G9<>"",G9,IF(G8<>"",G8,IF(G7<>"",G7,IF(G6<>"",G6,IF(G5<>"",G5,IF(G4<>"",G4,"")))))))))))) -> 23032 | H16: =SUM(C16:F16) -> 1669923 | J16: جمع | K16: =SUM(K4:K15) -> 0 | L16: =SUM(L4:L15) -> 0 | M16: =SUM(M4:M15) -> 0 | N16: =SUM(N4:N15) -> 0 | O16: =IF(O15<>"",O15,IF(O14<>"",O14,IF(O13<>"",O13,IF(O12<>"",O12,IF(O11<>"",O11,IF(O10<>"",O10,IF(O9<>"",O9,IF(O8<>"",O8,IF(O7<>"",O7,IF(O6<>"",O6,IF(O5<>"",O5,IF(O4<>"",O4,"")))))))))))) | P16: =SUM(K16:N16) -> 0
B18: شهید کاوه | J18: مطهری
B19: ماه | C19: تخلیه | D19: بارگیری | E19: حمل یکسره | F19: ترانشیپمنت | G19: رسوب | H19: جمع عملیاتی | J19: ماه | K19: تخلیه | L19: بارگیری | M19: حمل یکسره | N19: ترانشیپمنت | O19: رسوب | P19: جمع عملیاتی
A20: =B18 -> شهید کاوه | B20: فروردین | C20: 1297 | D20: 1101 | E20: 407 | F20: 0 | G20: 3019 | H20: =SUM(C20:G20) -> 5824 | I20: =J18 -> مطهری | J20: فروردین | K20: 2075 | L20: 1854 | M20: 0 | N20: 0 | O20: 3898 | P20: =SUM(K20:O20) -> 7827 | S20: =IF(SUM(G20)=0,"",IFERROR(G20,"")) -> 3019 | T20: =IFERROR(S20-G20,"") -> 0 | U20: =IF(SUM(O20)=0,"",IFERROR(O20,"")) -> 3898 | V20: =IFERROR(U20-O20,"") -> 0
A21: =B18 -> شهید کاوه | B21: اردیبهشت | C21: 2604 | D21: 1646 | E21: 578 | F21: 0 | G21: 4162 | H21: =SUM(C21:G21) -> 8990 | I21: =J18 -> مطهری | J21: اردیبهشت | K21: 1269 | L21: 1823 | M21: 0 | N21: 0 | O21: 3370 | P21: =SUM(K21:O21) -> 6462 | S21: =IF(OR(SUM(C21:G21)=0,SUM(G$20:G21)=0),"",IF(SUM(S$20:S20)=0,G21,IFERROR(SUM(S20,C21,-D21),""))) -> 3977 | T21: =IFERROR(S21-G21,"") -> -185 | U21: =IF(OR(SUM(K21:O21)=0,SUM(O$20:O21)=0),"",IF(SUM(U$20:U20)=0,O21,IFERROR(SUM(U20,K21,-L21),""))) -> 3344 | V21: =IFERROR(U21-O21,"") -> -26
A22: =B18 -> شهید کاوه | B22: خرداد | C22: 1549 | D22: 2007 | E22: 863 | F22: 0 | G22: 3658 | H22: =SUM(C22:G22) -> 8077 | I22: =J18 -> مطهری | J22: خرداد | K22: 3001 | L22: 1593 | M22: 0 | N22: 0 | O22: 3370 | P22: =SUM(K22:O22) -> 7964 | S22: =IF(OR(SUM(C22:G22)=0,SUM(G$20:G22)=0),"",IF(SUM(S$20:S21)=0,G22,IFERROR(SUM(S21,C22,-D22),""))) -> 3519 | T22: =IFERROR(S22-G22,"") -> -139 | U22: =IF(OR(SUM(K22:O22)=0,SUM(O$20:O22)=0),"",IF(SUM(U$20:U21)=0,O22,IFERROR(SUM(U21,K22,-L22),""))) -> 4752 | V22: =IFERROR(U22-O22,"") -> 1382
A23: =B18 -> شهید کاوه | B23: تیر | C23: 1858 | D23: 2119 | E23: 293 | F23: 0 | G23: 3534 | H23: =SUM(C23:G23) -> 7804 | I23: =J18 -> مطهری | J23: تیر | K23: 465 | L23: 2319 | M23: 0 | N23: 0 | O23: 2922 | P23: =SUM(K23:O23) -> 5706 | S23: =IF(OR(SUM(C23:G23)=0,SUM(G$20:G23)=0),"",IF(SUM(S$20:S22)=0,G23,IFERROR(SUM(S22,C23,-D23),""))) -> 3258 | T23: =IFERROR(S23-G23,"") -> -276 | U23: =IF(OR(SUM(K23:O23)=0,SUM(O$20:O23)=0),"",IF(SUM(U$20:U22)=0,O23,IFERROR(SUM(U22,K23,-L23),""))) -> 2898 | V23: =IFERROR(U23-O23,"") -> -24
A24: =B18 -> شهید کاوه | B24: مرداد | C24: 1871 | D24: 2661 | E24: 1519 | F24: 0 | G24: 2768 | H24: =SUM(C24:G24) -> 8819 | I24: =J18 -> مطهری | J24: مرداد | K24: 561 | L24: 1394 | M24: 0 | N24: 0 | O24: 2089 | P24: =SUM(K24:O24) -> 4044 | S24: =IF(OR(SUM(C24:G24)=0,SUM(G$20:G24)=0),"",IF(SUM(S$20:S23)=0,G24,IFERROR(SUM(S23,C24,-D24),""))) -> 2468 | T24: =IFERROR(S24-G24,"") -> -300 | U24: =IF(OR(SUM(K24:O24)=0,SUM(O$20:O24)=0),"",IF(SUM(U$20:U23)=0,O24,IFERROR(SUM(U23,K24,-L24),""))) -> 2065 | V24: =IFERROR(U24-O24,"") -> -24
A25: =B18 -> شهید کاوه | B25: شهریور | C25: 1275 | D25: 1591 | E25: 162 | F25: 0 | G25: 2644 | H25: =SUM(C25:G25) -> 5672 | I25: =J18 -> مطهری | J25: شهریور | K25: 3941 | L25: 914 | M25: 0 | N25: 0 | O25: 5003 | P25: =SUM(K25:O25) -> 9858 | S25: =IF(OR(SUM(C25:G25)=0,SUM(G$20:G25)=0),"",IF(SUM(S$20:S24)=0,G25,IFERROR(SUM(S24,C25,-D25),""))) -> 2152 | T25: =IFERROR(S25-G25,"") -> -492 | U25: =IF(OR(SUM(K25:O25)=0,SUM(O$20:O25)=0),"",IF(SUM(U$20:U24)=0,O25,IFERROR(SUM(U24,K25,-L25),""))) -> 5092 | V25: =IFERROR(U25-O25,"") -> 89
A26: =B18 -> شهید کاوه | B26: مهر | C26: 1603 | D26: 1732 | E26: 0 | F26: 0 | G26: 2528 | H26: =SUM(C26:G26) -> 5863 | I26: =J18 -> مطهری | J26: مهر | K26: 1217 | L26: 3021 | M26: 0 | N26: 0 | O26: 3312 | P26: =SUM(K26:O26) -> 7550 | S26: =IF(OR(SUM(C26:G26)=0,SUM(G$20:G26)=0),"",IF(SUM(S$20:S25)=0,G26,IFERROR(SUM(S25,C26,-D26),""))) -> 2023 | T26: =IFERROR(S26-G26,"") -> -505 | U26: =IF(OR(SUM(K26:O26)=0,SUM(O$20:O26)=0),"",IF(SUM(U$20:U25)=0,O26,IFERROR(SUM(U25,K26,-L26),""))) -> 3288 | V26: =IFERROR(U26-O26,"") -> -24
